Workbook
Name lista: OFFSET([1]DinamicValidation!$B$4,0,0,COUNTA([1]DinamicValidation!$B$4:$B$1048576),1)

Sheet OpeningPage

Sheet Admin
C9: Applied Business Valuation
C12: Date | D12: 45280
C13: Student name | D13: Sam Sample | I13: Master in Finance
C14: Neptun code | D14: ABCD1234 | I14: Master in Accounting
C16: Study program | D16: Master in Finance
C17: Instructor | D17: Péter Juhász, PhD, CFA
C20: Total points achieved | D20: =+'Bonus Task'!C9+'Task 4'!C9+'Task 5'!C9+'Task 1'!C9+'Task 2'!C9+'Task 3'!C9 -> 0

Sheet Task 1
B2: =+Admin!C12 -> Date | C2: =+Admin!D12 -> 45280
B3: =+Admin!C13 -> Student name | C3: =+Admin!D13 -> Sam Sample
B4: =+Admin!C14 -> Neptun code | C4: =+Admin!D14 -> ABCD1234
B6: =+Admin!C16 -> Study program | C6: =+Admin!D16 -> Master in Finance
B7: =+Admin!C17 -> Instructor | C7: =+Admin!D17 -> Péter Juhász, PhD, CFA
B9: Points achived:
D23: Firm A | E23: Firm B | F23: Together
C24: FCFF | D24: 500 | F24: 600
C25: FCFE | E25: 70
C26: g | D26: 0.03 | E26: 0.04 | F26: 0.033
C27: rA | D27: 0.1 | E27: 0.1 | F27: 0.1
C28: D/V | D28: 0.25 | E28: 0.3 | F28: 0.25
C29: rD | D29: 0.05 | E29: 0.06 | F29: 0.05
C30: t | D30: 0.15 | E30: 0.15 | F30: 0.15
C31: # of shares | D31: 1000000 | E31: 2000000
C33: rE | D33: =(D27-D29*D28)/(1-D28) -> 0.11666667 | E33: =(E27-E29*E28)/(1-E28) -> 0.11714286 | F33: =(F27-F29*F28)/(1-F28) -> 0.11666667
C35: WACC | D35: =D27-D28*D29*D30 -> 0.098125 | E35: =E27-E28*E29*E30 -> 0.0973 | F35: =F27-F28*F29*F30 -> 0.098125 | H35: Synergy
C36: V boy | D36: =D24/(D35-D26) -> 7339.4495 | E36: =E37*1/(1-E28) -> 1296.2963 | F36: =F24/(F35-F26) -> 9213.0518 | H36: =F36-E36-D36 -> 577.30599
C37: E boy | D37: =D39 -> 5504.5872 | E37: =E25/(E33-E26) -> 907.40741 | F37: =F39 -> 6909.7889
C38: D boy | D38: =D36*D28 -> 1834.8624 | E38: =E36-E37 -> 388.88889 | F38: =F36*F28 -> 2303.263
C39: E* | D39: =D36-D38 -> 5504.5872 | E39: =E37 -> 907.40741 | F39: =F36-F38 -> 6909.7889
C43: min price | D43: =E39 -> 907.40741
C44: max price | D44: =D43+H36 -> 1484.7134
C47: 30% transfer | D47: =D43+H36*30% -> 1080.5992
C48: 40% cash | D48: =D47*40% -> 432.23968
C49: Ownership pased over to B | D49: =E39+H36*30%-D48 -> 648.35952
C50: Ownership stake for B | D50: =D49/F39 -> 0.093832031
C52: Number of initial shares | D52: =D31+E31 -> 3000000
C53: Ownership stake for A | D53: =1-D50 -> 0.90616797
C55: Number of shares to be issued for B | D55: =D52/D53*D50 -> 310644.5
C56: Total number of shares post merger | D56: =D52/D53 -> 3310644.5
C58: Exchange rate | D58: =D56/D52 -> 1.1035482

Sheet Task 2
B2: =+Admin!C12 -> Date | C2: =+Admin!D12 -> 45280
B3: =+Admin!C13 -> Student name | C3: =+Admin!D13 -> Sam Sample
B4: =+Admin!C14 -> Neptun code | C4: =+Admin!D14 -> ABCD1234
B6: =+Admin!C16 -> Study program | C6: =+Admin!D16 -> Master in Finance
B7: =+Admin!C17 -> Instructor | C7: =+Admin!D17 -> Péter Juhász, PhD, CFA
B9: Points achived:
D24: 2023 | E24: =+D24+1 -> 2024 | F24: =+E24+1 -> 2025 | G24: =+F24+1 -> 2026 | H24: =+G24+1 -> 2027 | I24: TV1 | J24: TV2
C25: IC boy | D25: 750000 | E25: =D25+D26 -> 810000 | F25: =E25+E26 -> 860000 | G25: =F25+F26 -> 903000 | H25: =G25+G26 -> 936927 | I25: =H25+H26 -> 966302.13 | J25: =I25+I26 -> 1050617.7
C26: dIC | D26: 60000 | E26: 50000 | F26: =F29*F51 -> 43000 | G26: =G29*G51 -> 33927 | H26: =H29*H51 -> 29375.127 | I26: =I29*I51 -> 84315.559 | J26: =J29*J51 -> 89374.493
C27: ROIC | D27: 0.11 | E27: 0.12 | F27: 0.125
C28: RONIC | G28: 0.13 | H28: 0.13 | I28: =I41 -> 0.0854 | J28: =J41 -> 0.0854
C29: K | F29: 0.4 | G29: 0.3 | H29: 0.25 | I29: =J30/J28 -> 0.70257611 | J29: =I29 -> 0.70257611
C30: g TV period | J30: 0.06
C31: D/V boy | D31: =D45/D74 -> 0 | E31: =E45/E74 -> 0.13903886 | F31: =F45/F74 -> 0.20508613 | G31: 0.3 | H31: 0.3 | I31: 0.3 | J31: 0.3
C32: D/IC boy | D32: 0 | E32: 0.2 | F32: 0.3
C33: t | D33: 0.2 | E33: 0.2 | F33: 0.2 | G33: 0.2 | H33: 0.2 | I33: 0.2 | J33: 0.2
C34: rf | D34: 0.1 | E34: 0.08 | F34: 0.07 | G34: 0.06 | H34: 0.05 | I34: 0.05 | J34: 0.05
C35: rMarket portfolio | D35: 0.16 | E35: 0.14 | F35: 0.13 | G35: 0.12 | H35: 0.11 | I35: 0.11 | J35: 0.11
C36: b unlevered (industry) | D36: 0.8 | E36: 0.8 | F36: 0.8 | G36: 0.8 | H36: 0.8 | I36: 0.8 | J36: 0.8
C37: Debt risk premium | D37: 0 | E37: 0.01 | F37: 0.015 | G37: 0.02 | H37: 0.02 | I37: 0.02 | J37: 0.02
C38: rD | D38: =D37+D34 -> 0.1 | E38: =E37+E34 -> 0.09 | F38: =F37+F34 -> 0.085 | G38: =G37+G34 -> 0.08 | H38: =H37+H34 -> 0.07 | I38: =I37+I34 -> 0.07 | J38: =J37+J34 -> 0.07
C39: rE | D39: =D34+D36*(D35-D34) -> 0.148 | E39: =E34+E36*(E35-E34) -> 0.128 | F39: =F34+F36*(F35-F34) -> 0.118 | G39: =G34+G36*(G35-G34) -> 0.108 | H39: =H34+H36*(H35-H34) -> 0.098 | I39: =I34+I36*(I35-I34) -> 0.098 | J39: =J34+J36*(J35-J34) -> 0.098
C40: rA | D40: =D31*D38+(1-D31)*D39 -> 0.148 | E40: =E31*E38+(1-E31)*E39 -> 0.12271652 | F40: =F31*F38+(1-F31)*F39 -> 0.11123216 | G40: =G31*G38+(1-G31)*G39 -> 0.0996 | H40: =H31*H38+(1-H31)*H39 -> 0.0896 | I40: =I31*I38+(1-I31)*I39 -> 0.0896 | J40: =J31*J38+(1-J31)*J39 -> 0.0896
C41: WACC | D41: =D40-D38*D31*D33 -> 0.148 | E41: =E40-E38*E31*E33 -> 0.12021382 | F41: =F40-F38*F31*F33 -> 0.10774569 | G41: =G40-G38*G31*G33 -> 0.0948 | H41: =H40-H38*H31*H33 -> 0.0854 | I41: =I40-I38*I31*I33 -> 0.0854 | J41: =J40-J38*J31*J33 -> 0.0854 | XFD41: =XFD40-XFD38*XFD31*XFD33 -> 0
C44: IC BOY | D44: =D25 -> 750000 | E44: =E25 -> 810000 | F44: =F25 -> 860000 | G44: =G25 -> 903000 | H44: =H25 -> 936927 | I44: =I25 -> 966302.13 | J44: =J25 -> 1050617.7 | XFD44: =XFD25 -> 0
C45: DEBT BOY | D45: =D32*D44 -> 0 | E45: =E32*E44 -> 162000 | F45: =F32*F44 -> 258000 | G45: =G31*G68 -> 398715.89 | H45: =H31*H68 -> 412765.26 | I45: =I31*I68 -> 421577.8 | J45: =J31*J68 -> 446872.46 | K45: =J45*(1+J30) -> 473684.81 | XFD45: =XFD31*XFD42 -> 0
C46: EQUITY BOY | D46: =D44-D45 -> 750000 | E46: =E44-E45 -> 648000 | F46: =F44-F45 -> 602000 | G46: =G44-G45 -> 504284.11 | H46: =H44-H45 -> 524161.74 | I46: =I44-I45 -> 544724.33 | J46: =J44-J45 -> 603745.22
C51: NOPLAT | D51: =D25*D27 -> 82500 | E51: =E25*E27 -> 97200 | F51: =F25*F27 -> 107500 | G51: =F51+F52*G28 -> 113090 | H51: =G51+G52*H28 -> 117500.51 | I51: =H51+H52*I28 -> 120009.15 | J51: =I51+I52*J28 -> 127209.69
C52: dIC | D52: =D26 -> 60000 | E52: =E26 -> 50000 | F52: =F26 -> 43000 | G52: =G26 -> 33927 | H52: =H26 -> 29375.127 | I52: =I26 -> 84315.559 | J52: =J26 -> 89374.493
C53: FCFF | D53: =D51-D52 -> 22500 | E53: =E51-E52 -> 47200 | F53: =F51-F52 -> 64500 | G53: =G51-G52 -> 79163 | H53: =H51-H52 -> 88125.382 | I53: =I51-I52 -> 35693.587 | J53: =J51-J52 -> 37835.202
C54: interest payment | D54: =D45*D38 -> 0 | E54: =E45*E38 -> 14580 | F54: =F45*F38 -> 21930 | G54: =G45*G38 -> 31897.271 | H54: =H45*H38 -> 28893.568 | I54: =I45*I38 -> 29510.446 | J54: =J45*J38 -> 31281.072
C55: tax shield | D55: =D54*D33 -> 0 | E55: =E54*E33 -> 2916 | F55: =F54*F33 -> 4386 | G55: =G54*G33 -> 6379.4543 | H55: =H54*H33 -> 5778.7136 | I55: =I54*I33 -> 5902.0891 | J55: =J54*J33 -> 6256.2145
C56: dDebt | D56: =E45-D45 -> 162000 | E56: =F45-E45 -> 96000 | F56: =G45-F45 -> 140715.89 | G56: =H45-G45 -> 14049.366 | H56: =I45-H45 -> 8812.5382 | I56: =J45-I45 -> 25294.668 | J56: =K45-J45 -> 26812.348
C57: FCFE | D57: =D53-D54+D55+D56 -> 184500 | E57: =E53-E54+E55+E56 -> 131536 | F57: =F53-F54+F55+F56 -> 187671.89 | G57: =G53-G54+G55+G56 -> 67694.549 | H57: =H53-H54+H55+H56 -> 73823.066 | I57: =I53-I54+I55+I56 -> 37379.898 | J57: =J53-J54+J55+J56 -> 39622.692
A62: 1 | B62: FCFF+TS | C62: FCFF+TS | D62: =D53+D55 -> 22500 | E62: =E53+E55 -> 50116 | F62: =F53+F55 -> 68886 | G62: =G53+G55 -> 85542.454 | H62: =H53+H55 -> 93904.096 | I62: =I53+I55 -> 41595.676 | J62: =J53+J55 -> 44091.416
C63: rA | D63: =D40 -> 0.148 | E63: =E40 -> 0.12271652 | F63: =F40 -> 0.11123216 | G63: =G40 -> 0.0996 | H63: =H40 -> 0.0896 | I63: =I40 -> 0.0896 | J63: =J40 -> 0.0896
C64: Vboy | D64: =(D62+E64)/(1+D63) -> 1034531.2 | E64: =(E62+F64)/(1+E63) -> 1165141.9 | F64: =(F62+G64)/(1+F63) -> 1258008 | G64: =(G62+H64)/(1+G63) -> 1329053 | H64: =(H62+I64)/(1+H63) -> 1375884.2 | I64: =I62/(I63-J30) -> 1405259.3 | J64: =J62/(J63-J30) -> 1489574.9
A66: 2 | B66: FCFF | C66: FCFF | D66: =D53 -> 22500 | E66: =E53 -> 47200 | F66: =F53 -> 64500 | G66: =G53 -> 79163 | H66: =H53 -> 88125.382 | I66: =I53 -> 35693.587 | J66: =J53 -> 37835.202
C67: WACC | D67: =D41 -> 0.148 | E67: =E41 -> 0.12021382 | F67: =F41 -> 0.10774569 | G67: =G41 -> 0.0948 | H67: =H41 -> 0.0854 | I67: =I41 -> 0.0854 | J67: =J41 -> 0.0854 | XFD67: =XFD41 -> 0
C68: V boy | D68: =(D66+E68)/(1+D67) -> 1034531.2 | E68: =(E66+F68)/(1+E67) -> 1165141.9 | F68: =(F66+G68)/(1+F67) -> 1258008 | G68: =(G66+H68)/(1+G67) -> 1329053 | H68: =(H66+I68)/(1+H67) -> 1375884.2 | I68: =I66/(I67-$J$30) -> 1405259.3 | J68: =J66/(J67-$J$30) -> 1489574.9
...

Sheet Task 3
B2: =+Admin!C12 -> Date | C2: =+Admin!D12 -> 45280
B3: =+Admin!C13 -> Student name | C3: =+Admin!D13 -> Sam Sample
B4: =+Admin!C14 -> Neptun code | C4: =+Admin!D14 -> ABCD1234
B6: =+Admin!C16 -> Study program | C6: =+Admin!D16 -> Master in Finance
B7: =+Admin!C17 -> Instructor | C7: =+Admin!D17 -> Péter Juhász, PhD, CFA
B9: Points achived:
B26: P/E | C26: =C53/C60 -> 22.222222
B27: EV/EBIT | C27: =(C58-C44)/C35 -> 14.6875
B28: P/BV | C28: =C56/C46 -> 3.5087719
B29: EV/BV | C29: =(C58-C44)/C61 -> 2.1559633
B30: EV/S | C30: =(C58-C44)/C33 -> 1.1190476
B32: P/L
B33: Sales Revenue | C33: 10500000
B34: D&A | C34: 700000
B35: Operational profit | C35: 800000
B36: Profit before tax | C36: 700000
B37: Tax | C37: 250000
B38: After tax profit | C38: =+C36-C37 -> 450000
B40: Balance sheet
B41: PP&E | C41: 4000000
B42: Inventory | C42: 500000
B43: Receivables | C43: 700000
B44: Cash | C44: 250000
B46: Equity | C46: =SUM(C41:C44)-C49-C48-C47 -> 2850000
B47: Variable rate bank loans | C47: 1100000
B48: Outstanding face value of bonds | C48: 1000000
B49: Payables | C49: 500000
B51: Closing price of bonds | C51: 9
B52: Number of bonds | C52: 100000
B53: Closing price of shares | C53: 5
B54: Number of shares | C54: 2000000
B56: Equity Market Value | C56: =C53*C54 -> 10000000
B57: Debt Market Value | C57: =C47+C51*C52 -> 2000000
B58: Enterprise Value | C58: =C56+C57 -> 12000000
B60: E | C60: =C38/C54 -> 0.225
B61: IC | C61: =SUM(C46:C49) -> 5450000

Sheet Task 4
B2: =+Admin!C12 -> Date | C2: =+Admin!D12 -> 45280
B3: =+Admin!C13 -> Student name | C3: =+Admin!D13 -> Sam Sample
B4: =+Admin!C14 -> Neptun code | C4: =+Admin!D14 -> ABCD1234
B6: =+Admin!C16 -> Study program | C6: =+Admin!D16 -> Master in Finance
B7: =+Admin!C17 -> Instructor | C7: =+Admin!D17 -> Péter Juhász, PhD, CFA
B9: Points achived:
C35: RiskIt Co.
C37: rFinancing | D37: 0.2
C41: rReinvestment | D41: 0.05
C51: GreatIdea Ltd
G52: Post money value | H52: =M56/(1+D69)^5 -> 1319.219
D53: Today | H53: In 2 years | M53: In 7 years
C54: Equity | D54: 200 | G54: Capital increase 2 | H54: 500 | L54: Sales price | M54: 6000
C55: Pre money vlaue | D55: =D58-D56 -> 146.95754 | G55: Pre money value | H55: =H52-D57 -> 819.21899 | L55: D | M55: 0
C56: Capital increase 1 | D56: 300 | G56: Bank loan | H56: 0 | L56: E | M56: =M54-M55 -> 6000
C57: Total investment (IC) | D57: =D54+D56 -> 500 | G57: PE Stake (y=2) | H57: =H54/H52 -> 0.37901213 | I57: % of ownwrr who invested in the first year
C58: Post monay vslue | D58: =H55/(1+D69)^2 -> 446.95754 | G58: 1-PE | H58: =1-H57 -> 0.62098787 | L58: PE Stake (y=2) | M58: =H57 -> 0.37901213
E59: 0.25 | G59: PE stake (inc Year 1) | H59: =H58*D60 -> 0.41681 | I59: % of ownwrr who invested in the 0 year | L59: PE stake (inc Year 1) | M59: =H59 -> 0.41681
C60: PE stake(guess) | D60: 0.67120474 | G60: Founders stake | H60: =D63*H58 -> 0.20417786 | I60: % of founders | L60: Founders stake | M60: =H60 -> 0.20417786
C61: PE stake (guess)- market based | D61: =D56/D58 -> 0.6712047
C62: diff | D62: =D61-D60 -> -4.4908568e-08 | E62: 0.75 | L62: Total Value | M62: =H63*(1+D41)^5 -> 893.39709
B63: Q2 Answer | C63: Founders stake | D63: =1-D60 -> 0.32879526 | E63: years | G63: Liquidation | H63: 700 | L63: PE Value | M63: =H64*(1+D41)^5 -> 599.65237
G64: Inflow for PE | H64: =H63*D60 -> 469.84332 | L64: PE Value | M64: =M62*D60 -> 599.65237
C65: Investment horizon | D65: 7
C66: Chance of failure | D66: 0.75 | L66: Founders cash inflow | M66: =M56*M60 -> 1225.0672 | N66: after selling in 6 years
C67: Yearly return for failure | D67: =(M63/D56)^(1/7)-1 -> 0.10399811 | L67: Founders yearly return | M67: =(M66/D55)^(1/7)-1 -> 0.35383851
C68: Chance of success | D68: 0.25
B69: Q1 Answer | C69: Yearly return on success | D69: =(((1+D37)^D65-D66*(1+D67)^D65)/D68)^(1/D65)-1 -> 0.35383853 | E69: (1+rfin)^t=Prob fail *(1+r fail)^t+Prob success*(1+rsuccess)^t

Sheet Task 5
B2: =+Admin!C12 -> Date | C2: =+Admin!D12 -> 45280
B3: =+Admin!C13 -> Student name | C3: =+Admin!D13 -> Sam Sample
B4: =+Admin!C14 -> Neptun code | C4: =+Admin!D14 -> ABCD1234
B6: =+Admin!C16 -> Study program | C6: =+Admin!D16 -> Master in Finance
B7: =+Admin!C17 -> Instructor | C7: =+Admin!D17 -> Péter Juhász, PhD, CFA
B9: Points achived:

Sheet Bonus Task
B2: =+Admin!C12 -> Date | C2: =+Admin!D12 -> 45280
B3: =+Admin!C13 -> Student name | C3: =+Admin!D13 -> Sam Sample
B4: =+Admin!C14 -> Neptun code | C4: =+Admin!D14 -> ABCD1234
B6: =+Admin!C16 -> Study program | C6: =+Admin!D16 -> Master in Finance
B7: =+Admin!C17 -> Instructor | C7: =+Admin!D17 -> Péter Juhász, PhD, CFA
B9: Points achived:
B24: General data | C24: 2024 | D24: =+C24+1 -> 2025 | E24: =+D24+1 -> 2026 | F24: =+E24+1 -> 2027 | G24: =+F24+1 -> 2028 | H24: TV1 | I24: TV2
B25: IC boy | C25: 20000
B26: g TV | I26: 0.04
B27: rA | C27: 0.09 | D27: 0.09 | E27: 0.09 | F27: 0.09 | G27: 0.09 | H27: 0.09 | I27: 0.09
B28: D/V boy | H28: 0.35 | I28: 0.35
B29: rD | H29: 0.05 | I29: 0.05
B30: t | C30: 0.2 | D30: 0.2 | E30: 0.2 | F30: 0.2 | G30: 0.2 | H30: 0.2 | I30: 0.2
B32: Option A | K32: Option B
B33: ROIC | C33: 0.1 | D33: 0.1 | E33: 0.1 | F33: 0.1 | G33: 0.1 | K33: Additional IC boy | L33: 1000
B34: D/V | C34: 0.35 | D34: 0.35 | E34: 0.35 | F34: 0.35 | G34: 0.35 | K34: ROIC | L34: 0.09
B35: rD | C35: 0.05 | D35: 0.05 | E35: 0.05 | F35: 0.05 | G35: 0.05 | K35: RONIC | M35: 0.13 | N35: 0.12 | O35: 0.11 | P35: 0.1
B36: g | D36: 0.04 | E36: 0.04 | F36: 0.04 | G36: 0.04 | H36: 0.04 | K36: D/IC | L36: 0.5 | M36: 0.5 | N36: 0.5 | O36: 0.5 | P36: 0.5
K37: rD | L37: 0.07 | M37: 0.07 | N37: 0.07 | O37: 0.07 | P37: 0.07
K38: dIC | L38: 2000 | M38: 1900 | N38: 1800 | O38: 1700 | P38: 1600
B39: IC boy | C39: =C25 -> 20000
B40: Debt
B41: Equity | C41: =C39-C40 -> 20000
B43: NOPLAT | C43: =C39*C33 -> 2000
B44: dIC
B45: FCFF
