Workbook
Name lista: OFFSET([1]DinamicValidation!$B$4,0,0,COUNTA([1]DinamicValidation!$B$4:$B$1048576),1)

Sheet OpeningPage

Sheet Admin
C9: Applied Business Valuation
C12: Date | D12: 45280
C13: Student name | I13: Master in Finance
C14: Neptun code | I14: Master in Accounting
C16: Study program | D16: Master in Finance
C17: Instructor | D17: Péter Juhász, PhD, CFA
C20: Total points achieved | D20: =+'Bonus Task DCF compare'!C9+PE!C9+Theory!C9+'M&A'!C9+DCF!C9+'Task 3'!C9 -> 0

Sheet M&A
B2: =+Admin!C12 -> Date | C2: =+Admin!D12 -> 45280
B3: =+Admin!C13 -> Student name | C3: =+Admin!D13 -> 0
B4: =+Admin!C14 -> Neptun code | C4: =+Admin!D14 -> 0
B6: =+Admin!C16 -> Study program | C6: =+Admin!D16 -> Master in Finance
B7: =+Admin!C17 -> Instructor | C7: =+Admin!D17 -> Péter Juhász, PhD, CFA
B9: Points achived:
D23: Firm A | E23: Firm B | F23: Together
C24: FCFF | D24: 500 | F24: 600 | H24: Trick is to know how to get the FCFF
C25: FCFE | E25: 70
C26: g | D26: 0.03 | E26: 0.04 | F26: 0.033
C27: rA | D27: 0.1 | E27: 0.1 | F27: 0.1
C28: D/V | D28: 0.25 | E28: 0.3 | F28: 0.25
C29: rD | D29: 0.05 | E29: 0.06 | F29: 0.05
C30: t | D30: 0.15 | E30: 0.15 | F30: 0.15
C31: # of shares | D31: 1000000 | E31: 2000000
C33: rE | D33: =(D27-D29*D28)/(1-D28) -> 0.11666667 | E33: =(E27-E29*E28)/(1-E28) -> 0.11714286 | F33: =(F27-F29*F28)/(1-F28) -> 0.11666667
C36: WACC | D36: =D27-D29*D28*D30 -> 0.098125 | E36: =E27-E29*E28*E30 -> 0.0973 | F36: =F27-F29*F28*F30 -> 0.098125
C37: k | D37: =D26/D36 -> 0.30573248 | E37: =E26/E36 -> 0.41109969 | F37: =F26/F36 -> 0.33630573
C38: NOPLAT | D38: =D24/(1-D37) -> 720.18349 | E38: =E24/(1-E37) -> 0 | F38: =F24/(1-F37) -> 904.03071
C40: V | D40: =D24/(D36-D26) -> 7339.4495 | E40: =E42/(1-E28) -> 1296.2963 | F40: =F24/(F36-F26) -> 9213.0518
C41: D | D41: =D40*D28 -> 1834.8624 | E41: =E40-E42 -> 388.88889 | F41: =F40*F28 -> 2303.263
C42: E | D42: =D40-D41 -> 5504.5872 | E42: =E25/(E33-E26) -> 907.40741 | F42: =F40-F41 -> 6909.7889
C43: Synergy | F43: =F40-D40-E40 -> 577.30599 | G43: this we got from substracting together value - Firm A - Firm B
D44: Base
C45: Min | D45: =E42 -> 907.40741 | F45: this is the minimum that you need to pay for the Equity of the company you want to acquire
C46: Max | D46: =D45+F43 -> 1484.7134
C48: Price | D48: =D45+(0.3*F43) -> 1080.5992
C49: Cash | D49: =D48*40% -> 432.23968
C50: Shares worth | D50: =D48-D49 -> 648.35952
C51: B hold % | D51: =D50/F40 -> 0.070374023
C53: Initial Shared held by A | D53: 1000000
C54: % of shared held by A | D54: =(1-D51) -> 0.92962598
C56: Number of Shared B hold | D56: =D53*D51 -> 70374.023

Sheet DCF
B2: =+Admin!C12 -> Date | C2: =+Admin!D12 -> 45280
B3: =+Admin!C13 -> Student name | C3: =+Admin!D13 -> 0
B4: =+Admin!C14 -> Neptun code | C4: =+Admin!D14 -> 0
B6: =+Admin!C16 -> Study program | C6: =+Admin!D16 -> Master in Finance
B7: =+Admin!C17 -> Instructor | C7: =+Admin!D17 -> Péter Juhász, PhD, CFA
B9: Points achived:
D24: 2023 | E24: =+D24+1 -> 2024 | F24: =+E24+1 -> 2025 | G24: =+F24+1 -> 2026 | H24: =+G24+1 -> 2027 | I24: TV1 | J24: TV2 | M24: 2023 | N24: =+M24+1 -> 2024 | O24: =+N24+1 -> 2025 | P24: =+O24+1 -> 2026 | Q24: =+P24+1 -> 2027 | R24: TV1 | S24: TV2
C25: IC boy | D25: 750000 | E25: =D25+D26 -> 810000 | F25: =E25+E26 -> 860000 | G25: =F25+F26 -> 903000 | H25: =G25+G26 -> 936927 | I25: =H25+H26 -> 966302.13 | J25: =I25+I26 -> 1050617.7 | L25: IC boy | M25: 750000
C26: dIC | D26: 60000 | E26: 50000 | F26: =F49*F29 -> 43000 | G26: =G49*G29 -> 33927 | H26: =H49*H29 -> 29375.127 | I26: =I29*I49 -> 84315.559 | J26: =J29*J49 -> 89374.493 | L26: dIC | M26: 60000 | N26: 50000
C27: ROIC | D27: 0.11 | E27: 0.12 | F27: 0.125 | L27: ROIC | M27: 0.11 | N27: 0.12 | O27: 0.125
C28: RONIC | G28: 0.13 | H28: 0.13 | I28: =I42 -> 0.0854 | J28: =J42 -> 0.0854 | L28: RONIC | P28: 0.13 | Q28: 0.13 | R28: =R42 -> 0.0854 | S28: =S42 -> 0.0854
C29: K | F29: 0.4 | G29: 0.3 | H29: 0.25 | I29: =J30/J28 -> 0.70257611 | J29: 0.70257611 | L29: K | O29: 0.4 | P29: 0.3 | Q29: 0.25 | R29: =S30/S28 -> 0.70257611 | S29: =R29 -> 0.70257611
C30: g TV period | I30: 0.06 | J30: 0.06 | L30: g TV period | R30: 0.06 | S30: 0.06
C31: D/V boy | D31: =D45/D71 -> 0 | E31: =E45/E71 -> 0.17346937 | F31: =F45/F71 -> 0.2572336 | G31: 0.3 | H31: 0.3 | I31: 0.3 | J31: 0.3 | L31: D/V boy | M31: =M44/M71 -> 0 | N31: =N44/N71 -> 0.13903886 | O31: =O44/O71 -> 0.20508613 | P31: 0.3 | Q31: 0.3 | R31: 0.3 | S31: 0.3
C32: D/IC boy | D32: 0 | E32: 0.2 | F32: 0.3 | L32: D/IC boy | M32: 0 | N32: 0.2 | O32: 0.3
C33: t | D33: 0.2 | E33: 0.2 | F33: 0.2 | G33: 0.2 | H33: 0.2 | I33: 0.2 | J33: 0.2 | L33: t | M33: 0.2 | N33: 0.2 | O33: 0.2 | P33: 0.2 | Q33: 0.2 | R33: 0.2 | S33: 0.2
C34: rf | D34: 0.1 | E34: 0.08 | F34: 0.07 | G34: 0.06 | H34: 0.05 | I34: 0.05 | J34: 0.05 | L34: rf | M34: 0.1 | N34: 0.08 | O34: 0.07 | P34: 0.06 | Q34: 0.05 | R34: 0.05 | S34: 0.05
C35: rMarket portfolio | D35: 0.16 | E35: 0.14 | F35: 0.13 | G35: 0.12 | H35: 0.11 | I35: 0.11 | J35: 0.11 | L35: rMarket portfolio | M35: 0.16 | N35: 0.14 | O35: 0.13 | P35: 0.12 | Q35: 0.11 | R35: 0.11 | S35: 0.11
C36: b unlevered (industry) | D36: 0.8 | E36: 0.8 | F36: 0.8 | G36: 0.8 | H36: 0.8 | I36: 0.8 | J36: 0.8 | L36: b unlevered (industry) | M36: 0.8 | N36: 0.8 | O36: 0.8 | P36: 0.8 | Q36: 0.8 | R36: 0.8 | S36: 0.8
C37: Debt risk premium | D37: 0 | E37: 0.01 | F37: 0.015 | G37: 0.02 | H37: 0.02 | I37: 0.02 | J37: 0.02 | L37: Debt risk premium | M37: 0 | N37: 0.01 | O37: 0.015 | P37: 0.02 | Q37: 0.02 | R37: 0.02 | S37: 0.02
C39: rE | D39: =D34+D36*(D35-D34) -> 0.148 | E39: =E34+E36*(E35-E34) -> 0.128 | F39: =F34+F36*(F35-F34) -> 0.118 | G39: =G34+G36*(G35-G34) -> 0.108 | H39: =H34+H36*(H35-H34) -> 0.098 | I39: =I34+I36*(I35-I34) -> 0.098 | J39: =J34+J36*(J35-J34) -> 0.098 | L39: rE | M39: =M34+M36*(M35-M34) -> 0.148 | N39: =N34+N36*(N35-N34) -> 0.128 | O39: =O34+O36*(O35-O34) -> 0.118 | P39: =P34+P36*(P35-P34) -> 0.108 | Q39: =Q34+Q36*(Q35-Q34) -> 0.098 | R39: =R34+R36*(R35-R34) -> 0.098 | S39: =S34+S36*(S35-S34) -> 0.098
C40: rD | D40: =D34+D37 -> 0.1 | E40: =E34+E37 -> 0.09 | F40: =F34+F37 -> 0.085 | G40: =G34+G37 -> 0.08 | H40: =H34+H37 -> 0.07 | I40: =I34+I37 -> 0.07 | J40: =J34+J37 -> 0.07 | L40: rD | M40: =M34+M37 -> 0.1 | N40: =N34+N37 -> 0.09 | O40: =O34+O37 -> 0.085 | P40: =P34+P37 -> 0.08 | Q40: =Q34+Q37 -> 0.07 | R40: =R34+R37 -> 0.07 | S40: =S34+S37 -> 0.07
C41: rA | D41: =D39*(1-D31)+(D40*D31) -> 0.148 | E41: =E39*(1-E31)+(E40*E31) -> 0.12140816 | F41: =F39*(1-F31)+(F40*F31) -> 0.10951129 | G41: =G39*(1-G31)+(G40*G31) -> 0.0996 | H41: =H39*(1-H31)+(H40*H31) -> 0.0896 | I41: =I39*(1-I31)+(I40*I31) -> 0.0896 | J41: =J39*(1-J31)+(J40*J31) -> 0.0896 | L41: rA | M41: =M39*(1-M31)+M40*M31 -> 0.148 | N41: =N39*(1-N31)+N40*N31 -> 0.12271652 | O41: =O39*(1-O31)+O40*O31 -> 0.11123216 | P41: =P39*(1-P31)+P40*P31 -> 0.0996 | Q41: =Q39*(1-Q31)+Q40*Q31 -> 0.0896 | R41: =R39*(1-R31)+R40*R31 -> 0.0896 | S41: =S39*(1-S31)+S40*S31 -> 0.0896
C42: WACC | D42: =D41-D31*D40*D33 -> 0.148 | E42: =E41-E31*E40*E33 -> 0.11828572 | F42: =F41-F31*F40*F33 -> 0.10513832 | G42: =G41-G31*G40*G33 -> 0.0948 | H42: =H41-H31*H40*H33 -> 0.0854 | I42: =I41-I31*I40*I33 -> 0.0854 | J42: =J41-J31*J40*J33 -> 0.0854 | L42: Wacc | M42: =(M41-M31*M40*M33) -> 0.148 | N42: =(N41-N31*N40*N33) -> 0.12021382 | O42: =(O41-O31*O40*O33) -> 0.10774569 | P42: =(P41-P31*P40*P33) -> 0.0948 | Q42: =(Q41-Q31*Q40*Q33) -> 0.0854 | R42: =(R41-R31*R40*R33) -> 0.0854 | S42: =(S41-S31*S40*S33) -> 0.0854
L43: IC boy | M43: =M25 -> 750000 | N43: =M43+M49 -> 810000 | O43: =N43+N49 -> 860000 | P43: =O43+O49 -> 903000 | Q43: =P43+P49 -> 936927 | R43: =Q43+Q49 -> 966302.13 | S43: =R43+R49 -> 1050617.7
C44: IC | D44: =D25 -> 750000 | E44: =E25 -> 810000 | F44: =F25 -> 860000 | G44: =G25 -> 903000 | H44: =H25 -> 936927 | I44: =I25 -> 966302.13 | J44: =J25 -> 1050617.7 | L44: Debt boy | M44: =M43*M32 -> 0 | N44: =N43*N32 -> 162000 | O44: =O43*O32 -> 258000 | P44: =P31*P59 -> 398715.89 | Q44: =Q31*Q59 -> 412765.26 | R44: =R31*R59 -> 421577.8 | S44: =S31*S59 -> 446872.46 | T44: =S44+(S44*S30) -> 473684.81
C45: D | D45: =D44*D32 -> 0 | E45: =E44*E32 -> 162000 | F45: =F44*F32 -> 258000 | G45: =G31*G65 -> 398715.89 | H45: =H31*H65 -> 412765.26 | I45: =I31*I65 -> 421577.8 | J45: =J31*J65 -> 446872.46 | K45: =J45*(1+J30) -> 473684.81 | L45: BV Equity boy | M45: =M43-M44 -> 750000 | N45: =N43-N44 -> 648000 | O45: =O43-O44 -> 602000 | P45: =P43-P44 -> 504284.11 | Q45: =Q43-Q44 -> 524161.74 | R45: =R43-R44 -> 544724.33 | S45: =S43-S44 -> 603745.22
C46: E | D46: =D44-D45 -> 750000 | E46: =E44-E45 -> 648000 | F46: =F44-F45 -> 602000 | G46: =G44-G45 -> 504284.11 | H46: =H44-H45 -> 524161.74 | I46: =I44-I45 -> 544724.33 | J46: =J44-J45 -> 603745.22
C48: EBIT | L48: Noplat | M48: =M43*M27 -> 82500 | N48: =N43*N27 -> 97200 | O48: =O43*O27 -> 107500 | P48: =O49*P28+O48 -> 113090 | Q48: =P49*Q28+P48 -> 117500.51 | R48: =Q49*R28+Q48 -> 120009.15 | S48: =R49*S28+R48 -> 127209.69
C49: NOPLAT | D49: =D25*D27 -> 82500 | E49: =E25*E27 -> 97200 | F49: =F25*F27 -> 107500 | G49: =F49+G28*F26 -> 113090 | H49: =H28*G50+G49 -> 117500.51 | I49: =I28*H50+H49 -> 120009.15 | J49: =J28*I50+I49 -> 127209.69 | L49: dIC | M49: =M26 -> 60000 | N49: =N26 -> 50000 | O49: =O48*O29 -> 43000 | P49: =P48*P29 -> 33927 | Q49: =Q48*Q29 -> 29375.127 | R49: =R48*R29 -> 84315.559 | S49: =S48*S29 -> 89374.493
C50: dIC | D50: =D26 -> 60000 | E50: =E26 -> 50000 | F50: =F26 -> 43000 | G50: =G26 -> 33927 | H50: =H26 -> 29375.127 | I50: =I26 -> 84315.559 | J50: =J26 -> 89374.493 | L50: FCFF | M50: =M48-M49 -> 22500 | N50: =N48-N49 -> 47200 | O50: =O48-O49 -> 64500 | P50: =P48-P49 -> 79163 | Q50: =Q48-Q49 -> 88125.382 | R50: =R48-R49 -> 35693.587 | S50: =S48-S49 -> 37835.202
L51: Interest | M51: =M44*M40 -> 0 | N51: =N44*N40 -> 14580 | O51: =O44*O40 -> 21930 | P51: =P44*P40 -> 31897.271 | Q51: =Q44*Q40 -> 28893.568 | R51: =R44*R40 -> 29510.446 | S51: =S44*S40 -> 31281.072
C52: FCFF | D52: =D49-D50 -> 22500 | E52: =E49-E50 -> 47200 | F52: =F49-F50 -> 64500 | G52: =G49-G50 -> 79163 | H52: =H49-H50 -> 88125.382 | I52: =I49-I50 -> 35693.587 | J52: =J49-J50 -> 37835.202 | L52: Tax shield | M52: =M51*M33 -> 0 | N52: =N51*N33 -> 2916 | O52: =O51*O33 -> 4386 | P52: =P51*P33 -> 6379.4543 | Q52: =Q51*Q33 -> 5778.7136 | R52: =R51*R33 -> 5902.0891 | S52: =S51*S33 -> 6256.2145
C53: Interest | D53: =D45*D40 -> 0 | E53: =E45*E40 -> 14580 | F53: =F45*F40 -> 21930 | G53: =G45*G40 -> 31897.271 | H53: =H45*H40 -> 28893.568 | I53: =I45*I40 -> 29510.446 | J53: =J45*J40 -> 31281.072 | L53: d Debt | M53: =N44-M44 -> 162000 | N53: =O44-N44 -> 96000 | O53: =P44-O44 -> 140715.89 | P53: =Q44-P44 -> 14049.366 | Q53: =R44-Q44 -> 8812.5382 | R53: =S44-R44 -> 25294.668 | S53: =T44-S44 -> 26812.348
C54: Tax Sheild | D54: =D53*D33 -> 0 | E54: =E53*E33 -> 2916 | F54: =F53*F33 -> 4386 | G54: =G53*G33 -> 6379.4543 | H54: =H53*H33 -> 5778.7136 | I54: =I53*I33 -> 5902.0891 | J54: =J53*J33 -> 6256.2145 | L54: FCFE | M54: =M50-M51+M52+M53 -> 184500 | N54: =N50-N51+N52+N53 -> 131536 | O54: =O50-O51+O52+O53 -> 187671.89 | P54: =P50-P51+P52+P53 -> 67694.549 | Q54: =Q50-Q51+Q52+Q53 -> 73823.066 | R54: =R50-R51+R52+R53 -> 37379.898 | S54: =S50-S51+S52+S53 -> 39622.692
C55: d Debt | D55: =E45-D45 -> 162000 | E55: =F45-E45 -> 96000 | F55: =G45-F45 -> 140715.89 | G55: =H45-G45 -> 14049.366 | H55: =I45-H45 -> 8812.5382 | I55: =J45-I45 -> 25294.668 | J55: =K45-J45 -> 26812.348
C56: FCFE | D56: =D52-D53-D54+D55 -> 184500 | E56: =E52-E53-E54+E55 -> 125704 | F56: =F52-F53-F54+F55 -> 178899.89 | G56: =G52-G53-G54+G55 -> 54935.641 | H56: =H52-H53-H54+H55 -> 62265.639 | I56: =I52-I53-I54+I55 -> 25575.72 | J56: =J52-J53-J54+J55 -> 27110.263
B57: Valuation | L57: FCFF | M57: =M50 -> 22500 | N57: =N50 -> 47200 | O57: =O50 -> 64500 | P57: =P50 -> 79163 | Q57: =Q50 -> 88125.382 | R57: =R50 -> 35693.587 | S57: =S50 -> 37835.202
B58: APV | C58: FCFF + TS | D58: =D52+D54 -> 22500 | E58: =E52+E54 -> 50116 | F58: =F52+F54 -> 68886 | G58: =G52+G54 -> 85542.454 | H58: =H52+H54 -> 93904.096 | I58: =I52+I54 -> 41595.676 | J58: =J52+J54 -> 44091.416 | L58: WACC | M58: =M42 -> 0.148 | N58: =N42 -> 0.12021382 | O58: =O42 -> 0.10774569 | P58: =P42 -> 0.0948 | Q58: =Q42 -> 0.0854 | R58: =R42 -> 0.0854 | S58: =S42 -> 0.0854
C59: =C41 -> rA | D59: =D41 -> 0.148 | E59: =E41 -> 0.12140816 | F59: =F41 -> 0.10951129 | G59: =G41 -> 0.0996 | H59: =H41 -> 0.0896 | I59: =I41 -> 0.0896 | J59: =J41 -> 0.0896 | L59: V boy | M59: =(M57+N59)/(1+M58) -> 1034531.2 | N59: =(N57+O59)/(1+N58) -> 1165141.9 | O59: =(O57+P59)/(1+O58) -> 1258008 | P59: =(P57+Q59)/(1+P58) -> 1329053 | Q59: =(Q57+R59)/(1+Q58) -> 1375884.2 | R59: =R57/(R58-R30) -> 1405259.3 | S59: =S57/(S58-S30) -> 1489574.9
...

Sheet Task 3
B2: =+Admin!C12 -> Date | C2: =+Admin!D12 -> 45280
B3: =+Admin!C13 -> Student name | C3: =+Admin!D13 -> 0
B4: =+Admin!C14 -> Neptun code | C4: =+Admin!D14 -> 0
B6: =+Admin!C16 -> Study program | C6: =+Admin!D16 -> Master in Finance
B7: =+Admin!C17 -> Instructor | C7: =+Admin!D17 -> Péter Juhász, PhD, CFA
B9: Points achived:
B26: P/E
B27: EV/EBIT
B28: P/BV
B29: EV/BV
B30: EV/S
B32: P/L
B33: Sales Revenue | C33: 10500000
B34: D&A | C34: 700000
B35: Operational profit | C35: 800000
B36: Profit before tax | C36: 700000
B37: Tax | C37: 250000
B38: After tax profit | C38: =+C36-C37 -> 450000
B40: Balance sheet
B41: PP&E | C41: 4000000
B42: Inventory | C42: 500000
B43: Receivables | C43: 700000
B44: Cash | C44: 250000
B46: Equity | C46: =SUM(C41:C44)-C49-C48-C47 -> 2850000
B47: Variable rate bank loans | C47: 1100000
B48: Outstanding face value of bonds | C48: 1000000
B49: Payables | C49: 500000
B51: Closing price of bonds | C51: 9
B52: Number of bonds | C52: 100000
B53: Closing price of shares | C53: 5
B54: Number of shares | C54: 2000000
B56: EBIT

Sheet PE
B2: =+Admin!C12 -> Date | C2: =+Admin!D12 -> 45280
B3: =+Admin!C13 -> Student name | C3: =+Admin!D13 -> 0
B4: =+Admin!C14 -> Neptun code | C4: =+Admin!D14 -> 0
B6: =+Admin!C16 -> Study program | C6: =+Admin!D16 -> Master in Finance
B7: =+Admin!C17 -> Instructor | C7: =+Admin!D17 -> Péter Juhász, PhD, CFA
B9: Points achived:

Sheet Theory
B2: =+Admin!C12 -> Date | C2: =+Admin!D12 -> 45280
B3: =+Admin!C13 -> Student name | C3: =+Admin!D13 -> 0
B4: =+Admin!C14 -> Neptun code | C4: =+Admin!D14 -> 0
B6: =+Admin!C16 -> Study program | C6: =+Admin!D16 -> Master in Finance
B7: =+Admin!C17 -> Instructor | C7: =+Admin!D17 -> Péter Juhász, PhD, CFA
B9: Points achived:

Sheet Bonus Task DCF compare
B2: =+Admin!C12 -> Date | C2: =+Admin!D12 -> 45280
B3: =+Admin!C13 -> Student name | C3: =+Admin!D13 -> 0
B4: =+Admin!C14 -> Neptun code | C4: =+Admin!D14 -> 0
B6: =+Admin!C16 -> Study program | C6: =+Admin!D16 -> Master in Finance
B7: =+Admin!C17 -> Instructor | C7: =+Admin!D17 -> Péter Juhász, PhD, CFA
B9: Points achived:
B24: General data | C24: 2024 | D24: =+C24+1 -> 2025 | E24: =+D24+1 -> 2026 | F24: =+E24+1 -> 2027 | G24: =+F24+1 -> 2028 | H24: TV1 | I24: TV2
B25: IC boy | C25: 20000
B26: g TV | I26: 0.04
B27: rA | C27: 0.09 | D27: 0.09 | E27: 0.09 | F27: 0.09 | G27: 0.09 | H27: 0.09 | I27: 0.09
B28: D/V boy | H28: 0.35 | I28: 0.35
B29: rD | H29: 0.05 | I29: 0.05
B30: t | C30: 0.2 | D30: 0.2 | E30: 0.2 | F30: 0.2 | G30: 0.2 | H30: 0.2 | I30: 0.2
B32: Option A
B33: ROIC | C33: 0.1 | D33: 0.1 | E33: 0.1 | F33: 0.1 | G33: 0.1
B34: D/V | C34: 0.35 | D34: 0.35 | E34: 0.35 | F34: 0.35 | G34: 0.35
B35: rD | C35: 0.05 | D35: 0.05 | E35: 0.05 | F35: 0.05 | G35: 0.05
B36: g | D36: 0.04 | E36: 0.04 | F36: 0.04 | G36: 0.04 | H36: 0.04
B38: Option B
B39: Additional IC boy | C39: 1000
B40: ROIC | C40: 0.09
B41: RONIC | D41: 0.13 | E41: 0.12 | F41: 0.11 | G41: 0.1
B42: D/IC | C42: 0.5 | D42: 0.5 | E42: 0.5 | F42: 0.5 | G42: 0.5
B43: rD | C43: 0.07 | D43: 0.07 | E43: 0.07 | F43: 0.07 | G43: 0.07
B44: dIC | C44: 2000 | D44: 1900 | E44: 1800 | F44: 1700 | G44: 1600
