Workbook
Name lista: OFFSET(#REF!,0,0,COUNTA(#REF!),1)

Sheet OpeningPage

Sheet Admin
C9: Applied Business Valuation
C12: Date | D12: 45272
C13: Student name | I13: Master in Finance
C14: Neptun code | I14: Master in Accounting
C16: Study program | D16: Master in Finance
C17: Instructor | D17: Péter Juhász, PhD, CFA
C20: Total points achieved | D20: =+BCF!C9+'Asset Val.'!C9+Theory!C9+'M&A'!C9+DCF!C9+'Bonus Task CoE'!C9 -> 0

Sheet BCF
B2: =+Admin!C12 -> Date | C2: =+Admin!D12 -> 45272
B3: =+Admin!C13 -> Student name | C3: =+Admin!D13 -> 0
B4: =+Admin!C14 -> Neptun code | C4: =+Admin!D14 -> 0
B6: =+Admin!C16 -> Study program | C6: =+Admin!D16 -> Master in Finance
B7: =+Admin!C17 -> Instructor | C7: =+Admin!D17 -> Péter Juhász, PhD, CFA
B9: Points achived:
D18: =+E18-1 -> 2021 | E18: =+F18-1 -> 2022 | F18: =+YEAR(TODAY())-1 -> 2023 | J18: =+K18-1 -> 2021 | K18: =+L18-1 -> 2022 | L18: =+YEAR(TODAY())-1 -> 2023
C19: Sales | D19: 19000 | E19: 22000 | F19: 25000 | I19: Sales | J19: 19000 | K19: 22000 | L19: 25000
C20: Other income | D20: 0 | E20: 500 | F20: 0 | I20: Other income | J20: 0 | K20: 500 | L20: 0
C21: Material expenses | D21: 10000 | E21: 12000 | F21: 13000 | I21: Material expenses | J21: 10000 | K21: 12000 | L21: 13000
C22: Labour expenses | D22: 5000 | E22: 6000 | F22: 7000 | I22: Labour expenses | J22: 5000 | K22: 6000 | L22: 7000
C23: D&A | D23: 2000 | E23: 2300 | F23: 2500 | I23: D&A | J23: 2000 | K23: 2300 | L23: 2500
C24: EBIT | D24: =+D19+D20-D21-D22-D23 -> 2000 | E24: =+E19+E20-E21-E22-E23 -> 2200 | F24: =+F19+F20-F21-F22-F23 -> 2500 | I24: EBIT | J24: =+J19+J20-J21-J22-J23 -> 2000 | K24: =+K19+K20-K21-K22-K23 -> 2200 | L24: =+L19+L20-L21-L22-L23 -> 2500
C25: Dividend received | D25: 100 | E25: 60 | F25: 0 | I25: Dividend received | J25: 100 | K25: 60 | L25: 0
C26: Interests received | D26: 0 | E26: 0 | F26: 10 | I26: Interests received | J26: 0 | K26: 0 | L26: 10
C27: Interests paid on short term loans | D27: 30 | E27: 20 | F27: 10 | I27: Interests paid on short term loans | J27: 30 | K27: 20 | L27: 10
C28: Interests paid on long term loans | D28: 200 | E28: 250 | F28: 300 | I28: Interests paid on long term loans | J28: 200 | K28: 250 | L28: 300
C29: Financial profit | D29: =+D25+D26-D27-D28 -> -130 | E29: =+E25+E26-E27-E28 -> -210 | F29: =+F25+F26-F27-F28 -> -300 | I29: Financial profit | J29: =+J25+J26-J27-J28 -> -130 | K29: =+K25+K26-K27-K28 -> -210 | L29: =+L25+L26-L27-L28 -> -300
C30: Profit before tax | D30: =+D29+D24 -> 1870 | E30: =+E29+E24 -> 1990 | F30: =+F29+F24 -> 2200 | I30: Profit before tax | J30: =+J29+J24 -> 1870 | K30: =+K29+K24 -> 1990 | L30: =+L29+L24 -> 2200
C31: Corporate tax | D31: 300 | E31: 330 | F31: 370 | I31: Corporate tax | J31: 300 | K31: 330 | L31: 370
C32: Profit after tax | D32: =+D30-D31 -> 1570 | E32: =+E30-E31 -> 1660 | F32: =+F30-F31 -> 1830 | I32: Profit after tax | J32: =+J30-J31 -> 1570 | K32: =+K30-K31 -> 1660 | L32: =+L30-L31 -> 1830
C33: Dividend | D33: 1000 | E33: 1200 | F33: 1400 | I33: Dividend | J33: 1000 | K33: 1200 | L33: 1400
C34: Retained earnings | D34: =+D32-D33 -> 570 | E34: =+E32-E33 -> 460 | F34: =+F32-F33 -> 430 | I34: Retained earnings | J34: =+J32-J33 -> 570 | K34: =+K32-K33 -> 460 | L34: =+L32-L33 -> 430
C36: Cash | D36: 500 | E36: 600 | F36: 400 | I36: Cash | J36: 500 | K36: 600 | L36: 400
C37: of which operational cash | D37: 200 | E37: 220 | F37: 250 | I37: of which operational cash | J37: 200 | K37: 220 | L37: 250
C38: Marketable securities | D38: 0 | E38: 50 | F38: 40 | I38: Marketable securities | J38: 0 | K38: 50 | L38: 40
C39: Receivables | D39: 600 | E39: 800 | F39: 1000 | I39: Receivables | J39: 600 | K39: 800 | L39: 1000
C40: Inventory | D40: 400 | E40: 500 | F40: 450 | I40: Inventory | J40: 400 | K40: 500 | L40: 450
C41: Current assets | D41: =+D36+D38+D39+D40 -> 1500 | E41: =+E36+E38+E39+E40 -> 1950 | F41: =+F36+F38+F39+F40 -> 1890 | I41: Current assets | J41: =+J36+J38+J39+J40 -> 1500 | K41: =+K36+K38+K39+K40 -> 1950 | L41: =+L36+L38+L39+L40 -> 1890
C42: Invested assets | D42: 15000 | E42: 20000 | F42: 19500 | I42: Invested assets | J42: 15000 | K42: 20000 | L42: 19500
C43: Total of assests | D43: =+D42+D41 -> 16500 | E43: =+E42+E41 -> 21950 | F43: =+F42+F41 -> 21390 | I43: Total of assests | J43: =+J42+J41 -> 16500 | K43: =+K42+K41 -> 21950 | L43: =+L42+L41 -> 21390
C44: Short term loans | D44: 300 | E44: 200 | F44: 250 | I44: Short term loans | J44: 300 | K44: 200 | L44: 250
C45: Payables | D45: 300 | E45: 240 | F45: 450 | I45: Payables | J45: 300 | K45: 240 | L45: 450
C46: Short term liabilities | D46: =+D44+D45 -> 600 | E46: =+E44+E45 -> 440 | F46: =+F44+F45 -> 700 | I46: Short term liabilities | J46: =+J44+J45 -> 600 | K46: =+K44+K45 -> 440 | L46: =+L44+L45 -> 700
C47: Long term debt | D47: 5000 | E47: 6000 | F47: 7000 | I47: Long term debt | J47: 5000 | K47: 6000 | L47: 7000
C48: Equity | D48: =+D43-D46-D47 -> 10900 | E48: =+E43-E46-E47 -> 15510 | F48: =+F43-F46-F47 -> 13690 | I48: Equity | J48: =+J43-J46-J47 -> 10900 | K48: =+K43-K46-K47 -> 15510 | L48: =+L43-L46-L47 -> 13690
C49: Total of Liabilities and Equity | D49: =+D46+D47+D48 -> 16500 | E49: =+E46+E47+E48 -> 21950 | F49: =+F46+F47+F48 -> 21390 | I49: Total of Liabilities and Equity | J49: =+J46+J47+J48 -> 16500 | K49: =+K46+K47+K48 -> 21950 | L49: =+L46+L47+L48 -> 21390
C52: t | E52: =E31/(E30-E25) -> 0.17098446 | F52: =F31/(F30-F25) -> 0.16818182 | I52: t | J52: =J31/(J30-J25) -> 0.16949153 | K52: =K31/(K30-K25) -> 0.17098446 | L52: =L31/(L30-L25) -> 0.16818182
C54: EBIT | E54: =E24 -> 2200 | F54: =F24 -> 2500
C55: Int Liquidity Debt | I55: Cash Flow | J55: =+K55-1 -> 2021 | K55: =+L55-1 -> 2022 | L55: =+YEAR(TODAY())-1 -> 2023
...

Sheet DCF
B2: =+Admin!C12 -> Date | C2: =+Admin!D12 -> 45272
B3: =+Admin!C13 -> Student name | C3: =+Admin!D13 -> 0
B4: =+Admin!C14 -> Neptun code | C4: =+Admin!D14 -> 0
B6: =+Admin!C16 -> Study program | C6: =+Admin!D16 -> Master in Finance
B7: =+Admin!C17 -> Instructor | C7: =+Admin!D17 -> Péter Juhász, PhD, CFA
B9: Points achived:
D24: 2024 | E24: =+D24+1 -> 2025 | F24: =+E24+1 -> 2026 | G24: =+F24+1 -> 2027 | H24: =+G24+1 -> 2028 | I24: TV1 | J24: TV2 | M24: 2024 | N24: 2025 | O24: 2026 | P24: 2027 | Q24: 2028 | R24: TV1 | S24: TV2
C25: rA | D25: 0.12 | E25: 0.12 | F25: 0.12 | G25: 0.12 | H25: 0.12 | I25: 0.12 | J25: 0.12 | L25: rA | M25: 0.12 | N25: 0.12 | O25: 0.12 | P25: 0.12 | Q25: 0.12 | R25: 0.12 | S25: 0.12
C26: D/V boy | D26: =+D34/D57 -> 0.092228923 | E26: =+E34/E57 -> 0.18367387 | F26: 0.3 | G26: 0.4 | H26: 0.5 | I26: 0.5 | J26: 0.5 | L26: D/V boy | M26: =M36/M56 -> 0.092228923 | N26: =N36/N56 -> 0.18367387 | O26: 0.3 | P26: 0.4 | Q26: 0.5 | R26: 0.5 | S26: 0.5
C27: D/IC boy | D27: 0.1 | E27: 0.2 | L27: D/IC boy | M27: 0.1 | N27: 0.2
C28: rD | D28: 0.06 | E28: 0.07 | F28: 0.072 | G28: 0.073 | H28: 0.074 | I28: 0.074 | J28: 0.074 | L28: rD | M28: 0.06 | N28: 0.07 | O28: 0.072 | P28: 0.073 | Q28: 0.074 | R28: 0.074 | S28: 0.074
C29: ROIC | D29: 0.115 | L29: ROIC | M29: 0.115
C30: RONIC | E30: 0.16 | F30: 0.15 | G30: 0.14 | H30: 0.13 | I30: =I38 -> 0.11445 | J30: =J38 -> 0.11445 | L30: RONIC | N30: 0.16 | O30: 0.15 | P30: 0.14 | Q30: 0.13 | R30: =R35 -> 0.11445 | S30: =S35 -> 0.11445
C31: g targeted for the given year | E31: 0.15 | F31: 0.12 | G31: 0.1 | H31: 0.08 | I31: 0.05 | J31: 0.05 | L31: g targeted for the given year | N31: 0.15 | O31: 0.12 | P31: 0.1 | Q31: 0.08 | R31: 0.05 | S31: 0.05
C32: t | D32: 0.15 | E32: 0.15 | F32: 0.15 | G32: 0.15 | H32: 0.15 | I32: 0.15 | J32: 0.15 | L32: t | M32: 0.15 | N32: 0.15 | O32: 0.15 | P32: 0.15 | Q32: 0.15 | R32: 0.15 | S32: 0.15
C33: IC boy | D33: 100000 | E33: =D33+D43 -> 110781.25 | F33: =E33+E43 -> 121361.25 | G33: =F33+F43 -> 131941.25 | H33: =G33+G43 -> 141967.83 | I33: =H33+H43 -> 149655.32 | L33: k | M33: =N31/N30 -> 0.9375
C34: D | D34: =D27*D33 -> 10000 | E34: =E27*E33 -> 22156.25 | F34: =+F26*F53 -> 39667.786 | G34: =+G26*G53 -> 57373.063 | H34: =+H26*H53 -> 76874.862 | I34: =+I26*I53 -> 80718.606 | J34: =+I34*(1+J31) -> 84754.536 | L34: IC boy | M34: 100000 | N34: =M34+M41 -> 110781.25 | O34: =N34+N41 -> 121361.25 | P34: =O34+O41 -> 131941.25 | Q34: =P34+P41 -> 141967.83 | R34: =Q34+Q41 -> 149655.32 | S34: =R34+R41 -> 157727.18
C35: E | D35: =+D33-D34 -> 90000 | E35: =+E33-E34 -> 88625 | F35: =+F33-F34 -> 81693.464 | G35: =+G33-G34 -> 74568.187 | H35: =+H33-H34 -> 65092.972 | I35: =+I33-I34 -> 68936.715 | L35: WACC | M35: =M25-M26*M28*M32 -> 0.11916994 | N35: =N25-N26*N28*N32 -> 0.11807142 | O35: =O25-O26*O28*O32 -> 0.11676 | P35: =P25-P26*P28*P32 -> 0.11562 | Q35: =Q25-Q26*Q28*Q32 -> 0.11445 | R35: =R25-R26*R28*R32 -> 0.11445 | S35: =S25-S26*S28*S32 -> 0.11445
L36: Debt boy | M36: =M34*M27 -> 10000 | N36: =N34*N27 -> 22156.25 | O36: =O26*O51 -> 39667.786 | P36: =P26*P51 -> 57373.063 | Q36: =Q26*Q51 -> 76874.862 | R36: =R26*R51 -> 80718.606 | S36: =R36*(1+S31) -> 84754.536
C37: K | D37: =E31/E30 -> 0.9375 | E37: =F31/F30 -> 0.8 | F37: =G31/G30 -> 0.71428571 | G37: =H31/H30 -> 0.61538462 | H37: =I31/I30 -> 0.436872 | I37: =J31/J30 -> 0.436872 | L37: BV Equity boy
C38: WACC | D38: =D25-D26*D28*D32 -> 0.11916994 | E38: =E25-E26*E28*E32 -> 0.11807142 | F38: =F25-F26*F28*F32 -> 0.11676 | G38: =G25-G26*G28*G32 -> 0.11562 | H38: =H25-H26*H28*H32 -> 0.11445 | I38: =I25-I26*I28*I32 -> 0.11445 | J38: =J25-J26*J28*J32 -> 0.11445
C39: rE | D39: =(D25-D26*D28)/(1-D26) -> 0.12609596 | E39: =(E25-E26*E28)/(1-E26) -> 0.13125003 | F39: =(F25-F26*F28)/(1-F26) -> 0.14057143 | G39: =(G25-G26*G28)/(1-G26) -> 0.15133333 | H39: =(H25-H26*H28)/(1-H26) -> 0.166 | I39: =(I25-I26*I28)/(1-I26) -> 0.166 | J39: =(J25-J26*J28)/(1-J26) -> 0.166 | L39: EBIT | M39: =M40/(1-M32) -> 13529.412 | N39: =N40/(1-N32) -> 15558.824 | O39: =O40/(1-O32) -> 17425.882 | P39: =P40/(1-P32) -> 19168.471 | Q39: =Q40/(1-Q32) -> 20701.948 | R39: =R40/(1-R32) -> 21737.046 | S39: =S40/(1-S32) -> 22823.898
L40: Noplat | M40: =M29*M34 -> 11500 | N40: =(1+N31)*M40 -> 13225 | O40: =(1+O31)*N40 -> 14812 | P40: =(1+P31)*O40 -> 16293.2 | Q40: =(1+Q31)*P40 -> 17596.656 | R40: =(1+R31)*Q40 -> 18476.489 | S40: =(1+S31)*R40 -> 19400.313
C41: EBIT | L41: dIC | M41: =M33*M40 -> 10781.25 | N41: =(O40-N40)/O30 -> 10580 | O41: =(P40-O40)/P30 -> 10580 | P41: =(Q40-P40)/Q30 -> 10026.585 | Q41: =(R40-Q40)/R30 -> 7687.4862 | R41: =(S40-R40)/S30 -> 8071.8606
C42: NOPLAT | D42: =D29*D33 -> 11500 | E42: =D42+D43*E30 -> 13225 | F42: =E42+E43*F30 -> 14812 | G42: =F42+F43*G30 -> 16293.2 | H42: =G42+G43*H30 -> 17596.656 | I42: =H42+H43*I30 -> 18476.489 | L42: FCFF | M42: =M40-M41 -> 718.75 | N42: =N40-N41 -> 2645 | O42: =O40-O41 -> 4232 | P42: =P40-P41 -> 6266.6154 | Q42: =Q40-Q41 -> 9909.1698 | R42: =R40-R41 -> 10404.628
C43: dIC | D43: =D37*D42 -> 10781.25 | E43: =E37*E42 -> 10580 | F43: =F37*F42 -> 10580 | G43: =G37*G42 -> 10026.585 | H43: =H37*H42 -> 7687.4862 | I43: =I37*I42 -> 8071.8606 | J43: =J37*J42 -> 0 | L43: Interest | M43: =M36*M28 -> 600 | N43: =N36*N28 -> 1550.9375 | O43: =O36*O28 -> 2856.0806 | P43: =P36*P28 -> 4188.2336 | Q43: =Q36*Q28 -> 5688.7398 | R43: =R36*R28 -> 5973.1768 | S43: =S36*S28 -> 6271.8356
C44: FCFF | D44: =D42-D43 -> 718.75 | E44: =E42-E43 -> 2645 | F44: =F42-F43 -> 4232 | G44: =G42-G43 -> 6266.6154 | H44: =H42-H43 -> 9909.1698 | I44: =I42-I43 -> 10404.628 | L44: Tax shield | M44: =M43*M32 -> 90 | N44: =N43*N32 -> 232.64063 | O44: =O43*O32 -> 428.41209 | P44: =P43*P32 -> 628.23504 | Q44: =Q43*Q32 -> 853.31097 | R44: =R43*R32 -> 895.97652 | S44: =S43*S32 -> 940.77535
C45: Interest | D45: =D34*D28 -> 600 | E45: =E34*E28 -> 1550.9375 | F45: =F34*F28 -> 2856.0806 | G45: =G34*G28 -> 4188.2336 | H45: =H34*H28 -> 5688.7398 | I45: =I34*I28 -> 5973.1768 | L45: d Debt | M45: =N36-M36 -> 12156.25 | N45: =O36-N36 -> 17511.536 | O45: =P36-O36 -> 17705.276 | P45: =Q36-P36 -> 19501.8 | Q45: =R36-Q36 -> 3843.7431 | R45: =S36-R36 -> 4035.9303 | S45: =T36-S36 -> -84754.536
C46: Tax Shield | D46: =D45*D32 -> 90 | E46: =E45*E32 -> 232.64063 | F46: =F45*F32 -> 428.41209 | G46: =G45*G32 -> 628.23504 | H46: =H45*H32 -> 853.31097 | I46: =I45*I32 -> 895.97652 | L46: FCFE | M46: =M42-M43+M44+M45 -> 12365 | N46: =N42-N43+N44+N45 -> 18838.239 | O46: =O42-O43+O44+O45 -> 19509.608 | P46: =P42-P43+P44+P45 -> 22208.417 | Q46: =Q42-Q43+Q44+Q45 -> 8917.484 | R46: =R42-R43+R44+R45 -> 9363.3582 | S46: =S42-S43+S44+S45 -> -90085.596
C47: Change in Debt (Increase in Debt) | D47: =E34-D34 -> 12156.25 | E47: =F34-E34 -> 17511.536 | F47: =G34-F34 -> 17705.276 | G47: =H34-G34 -> 19501.8 | H47: =I34-H34 -> 3843.7431 | I47: =J34-I34 -> 4035.9303
C48: FCFE | D48: =D44-D45+D46+D47 -> 12365 | E48: =E44-E45+E46+E47 -> 18838.239 | F48: =F44-F45+F46+F47 -> 19509.608 | G48: =G44-G45+G46+G47 -> 22208.417 | H48: =H44-H45+H46+H47 -> 8917.484 | I48: =I44-I45+I46+I47 -> 9363.3582 | K48: Valuation
K49: FCFF | L49: FCFF | M49: =M42 -> 718.75 | N49: =N42 -> 2645 | O49: =O42 -> 4232 | P49: =P42 -> 6266.6154 | Q49: =Q42 -> 9909.1698 | R49: =R42 -> 10404.628
B50: Valuation | L50: WACC | M50: =M35 -> 0.11916994 | N50: =N35 -> 0.11807142 | O50: =O35 -> 0.11676 | P50: =P35 -> 0.11562 | Q50: =Q35 -> 0.11445 | R50: =R35 -> 0.11445
B51: FCFF | C51: FCFF | D51: =+D44 -> 718.75 | E51: =+E44 -> 2645 | F51: =+F44 -> 4232 | G51: =+G44 -> 6266.6154 | H51: =+H44 -> 9909.1698 | I51: =+I44 -> 10404.628 | L51: V boy | M51: =(N51+M49)/(1+M50) -> 108425.86 | N51: =(O51+N49)/(1+N50) -> 120628.21 | O51: =(P51+O49)/(1+O50) -> 132225.95 | P51: =(Q51+P49)/(1+P50) -> 143432.66 | Q51: =(R51+Q49)/(1+Q50) -> 153749.72 | R51: =R49/(R50-R31) -> 161437.21
C52: WACC | D52: =+D38 -> 0.11916994 | E52: =+E38 -> 0.11807142 | F52: =+F38 -> 0.11676 | G52: =+G38 -> 0.11562 | H52: =+H38 -> 0.11445 | I52: =+I38 -> 0.11445
C53: V boy | D53: =(D51+E53)/(1+D52) -> 108425.86 | E53: =(E51+F53)/(1+E52) -> 120628.21 | F53: =(F51+G53)/(1+F52) -> 132225.95 | G53: =(G51+H53)/(1+G52) -> 143432.66 | H53: =(H51+I53)/(1+H52) -> 153749.72 | I53: =+I51/(I52-$I$31) -> 161437.21 | K53: APV
L54: FCFF+TS | M54: =M49+M44 -> 808.75 | N54: =N49+N44 -> 2877.6406 | O54: =O49+O44 -> 4660.4121 | P54: =P49+P44 -> 6894.8504 | Q54: =Q49+Q44 -> 10762.481 | R54: =R49+R44 -> 11300.605
B55: APV | C55: FCFF+TS | D55: =+D44+D46 -> 808.75 | E55: =+E44+E46 -> 2877.6406 | F55: =+F44+F46 -> 4660.4121 | G55: =+G44+G46 -> 6894.8504 | H55: =+H44+H46 -> 10762.481 | I55: =+I44+I46 -> 11300.605 | L55: rA | M55: =M25 -> 0.12 | N55: =N25 -> 0.12 | O55: =O25 -> 0.12 | P55: =P25 -> 0.12 | Q55: =Q25 -> 0.12 | R55: =R25 -> 0.12
C56: rA | D56: =+D25 -> 0.12 | E56: =+E25 -> 0.12 | F56: =+F25 -> 0.12 | G56: =+G25 -> 0.12 | H56: =+H25 -> 0.12 | I56: =+I25 -> 0.12 | L56: V boy | M56: =(N56+M54)/(1+M55) -> 108425.86 | N56: =(O56+N54)/(1+N55) -> 120628.21 | O56: =(P56+O54)/(1+O55) -> 132225.95 | P56: =(Q56+P54)/(1+P55) -> 143432.66 | Q56: =(R56+Q54)/(1+Q55) -> 153749.72 | R56: =R54/(R55-R31) -> 161437.21
C57: V boy | D57: =(D55+E57)/(1+D56) -> 108425.86 | E57: =(E55+F57)/(1+E56) -> 120628.21 | F57: =(F55+G57)/(1+F56) -> 132225.95 | G57: =(G55+H57)/(1+G56) -> 143432.66 | H57: =(H55+I57)/(1+H56) -> 153749.72 | I57: =+I55/(I56-$I$31) -> 161437.21 | L57: check
...

Sheet PE
V3: RiskIt Co.
O4: (1+rFIN)^t=Prob.fail*(1+rFAIL)^t+Prob.success*(1+rSUCCESS)^t
B5: rFinancing | C5: 0.2 | V5: rFinancing | W5: 0.2
B9: rReinvestment | C9: 0.09 | V9: rReinvestment | W9: 0.07
P12: Today
O13: Book value of equity (M) | P13: 200
O14: Book value of debt (M) | P14: 0
O16: Venture capital contribution (M) | P16: 200
P18: in 3 years time
O19: Venture capital contribution (M) | P19: 300 | V19: GreatIdea Ltd
F20: Post money value of E | G20: =L24/(1+C36)^5 -> 1096.5481 | Z20: Post money value | AA20: =AF24/(1+W37)^4 -> 355.49518
C21: Today | G21: In 3 years | L21: In 8 years | P21: in 8 years time | W21: Today | AA21: In 2 years | AF21: In 6 years
B22: Equity | C22: 200 | F22: Capital increase 2 | G22: 300 | K22: Sales price (V) | L22: =1500*4 -> 6000 | O22: Expected Debt (M) | P22: 500 | V22: Equity | W22: 30 | Z22: Capital increase 2 | AA22: 100 | AE22: Sales price | AF22: 1500 | AT22: RiskIt Co.
B23: Pre money value | C23: =C26-C24 -> 102.69901 | F23: Pre money value | G23: =+G20-G22 -> 796.5481 | K23: D | L23: 500 | O23: Expected Sales multiple | P23: 4 | V23: Pre money vlaue | W23: =W26-W24 -> 58.746532 | Z23: Pre money value | AA23: =AA20-W25 -> 255.49518 | AE23: D | AF23: =AA22 -> 100
B24: Capital increase 1 | C24: 200 | F24: Bank loan | G24: 0 | K24: E | L24: =L22-L23 -> 5500 | O24: Expected Sales (M) | P24: 1500 | V24: Capital increase 1 | W24: 70 | Z24: Bank loan | AA24: 100 | AE24: E | AF24: =AF22-AF23 -> 1400 | AT24: rFinancing | AU24: 0.2
B25: Total investment (IC) | C25: =C22+C24 -> 400 | F25: PE stake (year 3) | G25: =+G22/G20 -> 0.27358581 | H25: % of owner who invested in year 2 | K25: PE stake altogether | L25: =+L26+L27 -> 0.58836516 | V25: Total investment (IC) | W25: =W22+W24 -> 100 | Z25: PE Stake (y=2) | AA25: =AA22/AA20 -> 0.28129777 | AB25: % of ownwrr who invested in the first year
B26: Post money value | C26: =+G23/(1+C36)^3 -> 302.69901 | E26: 0.25 | F26: 1-PE | G26: =1-G25 -> 0.72641419 | K26: PE stake (year 3) | L26: =G25 -> 0.27358581 | V26: Post monay vslue | W26: =AA23/(1+W37)^2 -> 128.74653 | Z26: 1-PE | AA26: =1-AA25 -> 0.71870223 | AE26: PE Stake (y=2) | AF26: =AA25 -> 0.28129777
F27: PE stake (taking year 1 into consideration) | G27: =G26*C28 -> 0.31477935 | H27: % of owner who invested in year 1 | K27: PE stake (taking year 1 into consideration) | L27: =G27 -> 0.31477935 | X27: 0.3 | Z27: PE stake (inc Year 1) | AA27: =AA26*W28 -> 0.39076125 | AB27: % of ownwrr who invested in the 0 year | AE27: PE stake (inc Year 1) | AF27: =AA27 -> 0.39076125
B28: PE (private equity firm) stake (we guess with a random number and then use solver) | C28: 0.43333315 | F28: Founders stake | G28: =C31*G26 -> 0.41163484 | H28: % of founders | K28: Founders stake | L28: =G28 -> 0.41163484 | V28: PE stake(guess) | W28: 0.54370397 | Z28: Founders stake | AA28: =W31*AA26 -> 0.32794098 | AB28: % of founders | AE28: Founders stake | AF28: =AA28 -> 0.32794098 | AT28: rReinvestment | AU28: 0.07
B29: PE stake guess - market base | C29: 0.43333215 | V29: PE stake (guess)- market based | W29: =W24/W26 -> 0.54370396
B30: diff | C30: =C29-C28 -> -1e-06 | E30: 0.75 | F30: Liquidation ratio | G30: 0 | K30: Total value with reinvestment in case of failure | L30: =G31*(1+C9)^5 -> 615.44958 | V30: diff | W30: =W29-W28 -> -2.3272501e-09 | X30: 0.7 | Z30: Liquidation ratio | AA30: 0.9 | AE30: Total Value | AF30: =AA31*(1+W9)^4 -> 117.97164
B31: Founders stake | C31: =1-C28 -> 0.56666685 | F31: Liquidation | G31: =+P16+P13 -> 400 | K31: PE value out of total | L31: =G32*(1+C9)^5 -> 266.69471 | U31: Q2 Answer | V31: Founders stake | W31: =1-W28 -> 0.45629603 | X31: years | Z31: Liquidation | AA31: =AA30*W25 -> 90 | AE31: PE Value | AF31: =AA32*(1+W9)^4 -> 64.141649
B32: Investment horizon | C32: 8 | D32: years | F32: Inflow for PE | G32: =+C28*G31 -> 173.33326 | Z32: Inflow for PE | AA32: =AA31*W28 -> 48.933357 | AE32: PE Value | AF32: =AF30*W28 -> 64.141649
B33: Chance of failure | C33: 0.75 | F33: Inflow for founders | G33: =G31-G32 -> 226.66674 | K33: Founders cash inflow | L33: =+L24*L28 -> 2263.9916 | V33: Investment horizon | W33: 6
B34: Yearly return of failure | C34: =+(L31/C24)^(1/8)-1 -> 0.036628274 | F34: founders yearly return | G34: =(G33/C23)^(1/3)-1 -> 0.30198858 | K34: Founders yearly return | L34: =(L33/C23)^(1/8)-1 -> 0.47201951 | V34: Chance of failure | W34: 0.7 | AE34: Founders cash inflow | AF34: =AF24*AF28 -> 459.11737 | AG34: after selling in 6 years
B35: Chance of success | C35: 0.25 | V35: Yearly return for failure | W35: =(AF31/W24)^(1/6)-1 -> -0.014461306 | AE35: Founders yearly return | AF35: =(AF34/W23)^(1/6)-1 -> 0.40871643
B36: Yearly return of success | C36: =(((1+C5)^C32-C33*(1+C34)^C32)/C35)^(1/C32)-1 -> 0.38059724 | V36: Chance of success | W36: 0.3
U37: Q1 Answer | V37: Yearly return on success | W37: =(((1+W5)^W33-W34*(1+W35)^W33)/W36)^(1/W33)-1 -> 0.40871643 | X37: (1+rfin)^t=Prob fail *(1+r fail)^t+Prob success*(1+rsuccess)^t
AT38: GreatIdea Ltd
AX39: Post money value | AY39: =BD43/(1+AU56)^4 -> 274.67781
F40: Post money value of E | G40: =L44/(1+C56)^5 -> 1226.5743 | V40: rFinancing | W40: 0.2 | AU40: Today | AY40: In 2 years | BD40: In 6 years
C41: Today | G41: In 3 years | L41: In 8 years | AH41: Investment sum | AI41: Year | AJ41: Dependance on success | AT41: Equity | AU41: 30 | AX41: Capital increase 2 | AY41: 100 | BC41: Sales price | BD41: 1100
B42: Equity | C42: 200 | F42: Capital increase 2 | G42: 300 | K42: Sales price (V) | L42: =1500*4 -> 6000 | V42: Today | Z42: In 2 years | AD42: In 6 years | AG42: Owner= founders | AH42: =W45 -> 30 | AI42: 0 | AJ42: Nope | AT42: Pre money vlaue | AU42: =AU45-AU43 -> 21.548139 | AX42: Pre money value | AY42: =AY39-AU44 -> 174.67781 | BC42: D | BD42: 100
B43: Pre money value | C43: =C46-C44 -> 176.5988 | F43: Pre money value | G43: =+G40-G42 -> 926.57426 | K43: D | L43: 500 | V43: Total IC | W43: =W45+W48 -> 100 | AG43: PE1 = First Invesor | AH43: =W48 -> 70 | AI43: 0 | AJ43: Nope | AT43: Capital increase 1 | AU43: 70 | AX43: Bank loan | AY43: 100 | BC43: E | BD43: =BD41-BD42 -> 1000
B44: Capital increase 1 | C44: 200 | F44: Bank loan | G44: 0 | K44: E | L44: =L42-L43 -> 5500 | Z44: Success (Business will continue) | AD44: Success (Business will be sold) | AG44: PE2 = 2nd Investor= Loan providor | AH44: =AA47 -> 100 | AI44: 2 | AJ44: Only in case of the succes in the first 2 years | AT44: Total investment (IC) | AU44: =AU41+AU43 -> 100 | AX44: PE Stake (y=2) | AY44: =AY41/AY39 -> 0.3640629 | AZ44: % of owner who invested in the first year
B45: Total investment (IC) | C45: =C42+C44 -> 400 | F45: PE stake (year 3) | G45: =+G42/G40 -> 0.24458364 | H45: % of owner who invested in year 2 | K45: PE stake altogether if we assume req. Rate of return is 35% for success case | L45: =+L46+L47 -> 0.64576272 | V45: Equity - Initial | W45: 30 | AT45: Post monay vslue | AU45: =AY42/(1+AU56)^2 -> 91.548139 | AX45: 1-PE | AY45: =1-AY44 -> 0.6359371 | BC45: PE Stake (y=2) | BD45: =AY44 -> 0.3640629
B46: Post money value | C46: =+G43/(1+C56)^3 -> 376.5988 | E46: 0.25 | F46: 1-PE | G46: =1-G45 -> 0.75541636 | K46: PE stake (year 3) | L46: =G45 -> 0.24458364 | Y46: 3) | Z46: Equity - Pre Money Value | AA46: =AA48-AA47 -> 255.49518 | AD46: Value (Sales Price) | AE46: 1500 | AG46: Steps | AV46: 0.3 | AX46: PE stake (inc Year 1) | AY46: =AY45*AU47 -> 0.48625343 | AZ46: % of owner who invested in the 0 year | BC46: PE stake (inc Year 1) | BD46: =AY46 -> 0.48625343
F47: PE stake (taking year 1 into consideration) | G47: =G46*C48 -> 0.40117907 | H47: % of owner who invested in year 1 | K47: PE stake (taking year 1 into consideration) | L47: =G47 -> 0.40117907 | U47: 5) | V47: Equity - Pre Money Value | W47: =W49-W48 -> 58.746533 | Z47: Additional IC 2 | AA47: 100 | AD47: Debt | AE47: 100 | AG47: 1. Fill out the investments in the noted terms | AT47: PE stake(guess) | AU47: 0.76462505 | AX47: Founders stake | AY47: =AU50*AY45 -> 0.14968366 | AZ47: % of founders | BC47: Founders stake | BD47: =AY47 -> 0.14968366
B48: PE (private equity firm) stake (we guess with a random number and then use solver) | C48: 0.53107014 | F48: Founders stake | G48: =C51*G46 -> 0.35423728 | H48: % of founders | K48: Founders stake | L48: =G48 -> 0.35423728 | V48: Additional IC 1 | W48: 70 | Y48: 2) | Z48: Equity - Post Money Value | AA48: =AE48/(1+W64)^4 -> 355.49518 | AC48: 1) | AD48: Equity | AE48: =AE46-AE47 -> 1400 | AG48: 2. Put a random PE-1 stake - will use solver later on | AT48: PE stake (guess)- market based | AU48: =AU43/AU45 -> 0.76462505
B49: PE stake guess - market base | C49: =C44/C46 -> 0.53106914 | U49: 4) | V49: Equity - Post Money Value | W49: =AA46/(1+W64)^2 -> 128.74653 | AG49: 3.Founder stake 1-PE 1 Stake | AT49: diff | AU49: =AU48-AU47 -> -2.6852871e-09 | AV49: 0.7 | AX49: Liquidation ratio | AY49: 0.9 | BC49: Total Value | BD49: =AY50*(1+AU28)^4 -> 117.97164
...

Sheet Sheet2

Sheet M&A
B2: =+Admin!C12 -> Date | C2: =+Admin!D12 -> 45272
B3: =+Admin!C13 -> Student name | C3: =+Admin!D13 -> 0
B4: =+Admin!C14 -> Neptun code | C4: =+Admin!D14 -> 0
B6: =+Admin!C16 -> Study program | C6: =+Admin!D16 -> Master in Finance
B7: =+Admin!C17 -> Instructor | C7: =+Admin!D17 -> Péter Juhász, PhD, CFA
B9: Points achived:
R13: Points achived:
Q14: Adam
AA15: Mridul | AL15: Exchange rate
AM16: 0 | AN16: 0
AM17: 0 | AN17: 0
AM18: 0 | AN18: 0
AM20: 0 | AN20: 0
AM21: 0 | AN21: 0
AM23: Points achived:
D27: Firm A | E27: Firm B | F27: Together | I27: transaction fee | J27: 6000000 | K27: 3000000 | L27: HUF
C28: rA | D28: 0.1 | E28: 0.1 | F28: 0.1 | J28: Firm A | K28: Firm B | L28: Together
C29: t | D29: 0.15 | E29: 0.15 | F29: 0.15 | I29: rA | J29: 0.1 | K29: 0.1 | L29: 0.1 | AD29: Firm A | AE29: Firm B | AF29: Together
C30: Noplat | D30: 840 | E30: 100 | F30: 1000 | I30: t | J30: 0.15 | K30: 0.15 | L30: 0.15 | T30: Firm A | U30: Firm B | V30: Together | AC30: FCFF | AD30: 500 | AF30: 600 | AH30: Trick is to know how to get the FCFF
C31: D/V | D31: 0.4 | E31: 0.25 | F31: 0.4 | I31: Noplat | J31: 840 | K31: 100 | L31: 1000 | M31: M HUF? | S31: number of shares | T31: 2000000 | U31: 4000000 | AC31: FCFE | AE31: 70
C32: rD | D32: 0.05 | E32: 0.05 | F32: 0.05 | I32: D/V | J32: 0.4 | K32: 0.25 | L32: 0.4 | S32: t | T32: 0.2 | U32: 0.2 | V32: 0.2 | AC32: g | AD32: 0.03 | AE32: 0.04 | AF32: 0.033
C33: RONIC | D33: 0.101 | E33: 0.12 | F33: 0.102 | I33: rD | J33: 0.05 | K33: 0.05 | L33: 0.05 | S33: rA | T33: 0.12 | U33: 0.12 | V33: 0.12 | AC33: rA | AD33: 0.1 | AE33: 0.1 | AF33: 0.1
C34: g | D34: 0.03 | E34: 0.04 | F34: 0.033 | I34: RONIC | J34: 0.101 | K34: 0.12 | L34: 0.102 | S34: g | T34: 0.03 | U34: 0.04 | V34: 0.0325 | AC34: D/V | AD34: 0.25 | AE34: 0.3 | AF34: 0.25
C35: Number of shares | D35: 10000000 | E35: 5000000 | I35: g | J35: 0.03 | K35: 0.04 | L35: 0.033 | S35: rD | T35: 0.06 | U35: 0.06 | V35: 0.06 | AC35: rD | AD35: 0.05 | AE35: 0.06 | AF35: 0.05
I36: Number of shares | J36: 10000000 | K36: 5000000 | S36: D/V | T36: 0.3 | U36: 0.2 | V36: 0.3 | AC36: t | AD36: 0.15 | AE36: 0.15 | AF36: 0.15
C37: K | D37: =D34/D33 -> 0.2970297 | E37: =E34/E33 -> 0.33333333 | F37: =F34/F33 -> 0.32352941 | S37: FCFF (M HUF) | T37: 500 | V37: 710 | AC37: # of shares | AD37: 1000000 | AE37: 2000000 | AO37: Firm A | AP37: Firm B | AQ37: Together
C38: WACC | D38: =D28-D32*D31*D29 -> 0.097 | E38: =E28-E32*E31*E29 -> 0.098125 | F38: =F28-F32*F31*F29 -> 0.097 | I38: K | J38: =J35/J34 -> 0.2970297 | K38: =K35/K34 -> 0.33333333 | L38: =L35/L34 -> 0.32352941 | S38: FCFE (M HUF) | U38: 150 | AN38: FCFF | AO38: 500 | AQ38: 600
C39: rE | D39: =(D28-D32*D31)/(1-D31) -> 0.13333333 | E39: =(E28-E32*E31)/(1-E31) -> 0.11666667 | F39: =(F28-F32*F31)/(1-F31) -> 0.13333333 | I39: FCFF | J39: =J31*(1-J38) -> 590.49505 | K39: =K31*(1-K38) -> 66.666667 | L39: =L31*(1-L38) -> 676.47059 | S39: E/V | U39: =1-U36 -> 0.8 | AC39: rE | AD39: =(AD33-AD35*AD34)/(1-AD34) -> 0.11666667 | AE39: =(AE33-AE35*AE34)/(1-AE34) -> 0.11714286 | AF39: =(AF33-AF35*AF34)/(1-AF34) -> 0.11666667 | AN39: FCFE | AP39: 70
I40: WACC | J40: =J29-J32*J33*J30 -> 0.097 | K40: =K29-K32*K33*K30 -> 0.098125 | L40: =L29-L32*L33*L30 -> 0.097 | AN40: g | AO40: 0.03 | AP40: 0.04 | AQ40: 0.033
N41: Without synergy | O41: Synergy | R41: (rA-rD*D/V)/(1-D/V) | S41: rE | T41: =(T33-T35*T36)/(1-T36) -> 0.14571429 | U41: =(U33-U35*U36)/(1-U36) -> 0.135 | V41: =(V33-V35*V36)/(1-V36) -> 0.14571429 | AN41: rA | AO41: 0.1 | AP41: 0.1 | AQ41: 0.1
C42: NOPLAT | D42: =D30 -> 840 | E42: =E30 -> 100 | F42: =F30 -> 1000 | I42: V | J42: =J39/(J40-J35) -> 8813.3589 | K42: =K39/(K40-K35) -> 1146.9534 | L42: =L39/(L40-L35) -> 10569.853 | N42: =J42+K42 -> 9960.3124 | O42: =L42-N42 -> 609.54059 | AC42: WACC | AD42: =AD33-AD35*AD34*AD36 -> 0.098125 | AE42: =AE33-AE35*AE34*AE36 -> 0.0973 | AF42: =AF33-AF35*AF34*AF36 -> 0.098125 | AN42: D/V | AO42: 0.25 | AP42: 0.3 | AQ42: 0.25
C43: dIC | D43: =D37*D42 -> 249.50495 | E43: =E37*E42 -> 33.333333 | F43: =F37*F42 -> 323.52941 | I43: D | J43: =J42*J32 -> 3525.3436 | K43: =K42*K32 -> 286.73835 | L43: =L42*L32 -> 4227.9412 | N43: =J43+K43 -> 3812.0819 | O43: =L43-N43 -> 415.85925 | R43: rA-D/V*rD*t | S43: WACC | T43: =T33-T35*T36*T32 -> 0.1164 | U43: =U33-U35*U36*U32 -> 0.1176 | V43: =V33-V35*V36*V32 -> 0.1164 | AC43: k | AD43: =AD32/AD42 -> 0.30573248 | AE43: =AE32/AE42 -> 0.41109969 | AF43: =AF32/AF42 -> 0.33630573 | AN43: rD | AO43: 0.05 | AP43: 0.06 | AQ43: 0.05
C44: FCFF | D44: =D42-D43 -> 590.49505 | E44: =E42-E43 -> 66.666667 | F44: =F42-F43 -> 676.47059 | I44: E | J44: =J42-J43 -> 5288.0154 | K44: =K42-K43 -> 860.21505 | L44: =L42-L43 -> 6341.9118 | N44: =J44+K44 -> 6148.2304 | O44: =L44-N44 -> 193.68134 | X44: Without synergy | Y44: Synergy | AC44: NOPLAT | AD44: =AD30/(1-AD43) -> 720.18349 | AE44: =AE30/(1-AE43) -> 0 | AF44: =AF30/(1-AF43) -> 904.03071 | AN44: t | AO44: 0.15 | AP44: 0.15 | AQ44: 0.15
C45: WACC | D45: =D38 -> 0.097 | E45: =E38 -> 0.098125 | F45: =F38 -> 0.097 | R45: FCFF/(wacc-g) OR E/(E/V) | S45: V | T45: =T37/(T43-T34) -> 5787.037 | U45: =U47/U39 -> 1973.6842 | V45: =V37/(V43-V34) -> 8462.4553 | X45: =T45+U45 -> 7760.7212 | Y45: =V45-X45 -> 701.73406 | AN45: # of shares | AO45: 1000000 | AP45: 2000000
C46: V boy | D46: =D44/(D45-D34) -> 8813.3589 | E46: =E44/(E45-E34) -> 1146.9534 | F46: =F44/(F45-F34) -> 10569.853 | J46: base | K46: transaction cost (M HUF) | L46: Bargaining range | S46: D | T46: =T45*T36 -> 1736.1111 | U46: =U45*U36 -> 394.73684 | V46: =V45*V36 -> 2538.7366 | X46: =T46+U46 -> 2130.848 | AC46: V | AD46: =AD30/(AD42-AD32) -> 7339.4495 | AE46: =AE48/(1-AE34) -> 1296.2963 | AF46: =AF30/(AF42-AF32) -> 9213.0518
I47: Min | J47: =K44 -> 860.21505 | K47: 3 | L47: =J47-K47 -> 857.21505 | S47: E | T47: =T45-T46 -> 4050.9259 | U47: =U38/(U41-U34) -> 1578.9474 | V47: =V45-V46 -> 5923.7187 | X47: =T47+U47 -> 5629.8733 | AC47: D | AD47: =AD46*AD34 -> 1834.8624 | AE47: =AE46-AE48 -> 388.88889 | AF47: =AF46*AF34 -> 2303.263 | AN47: rE | AO47: =(AO41-AO43*AO42)/(1-AO42) -> 0.11666667 | AP47: =(AP41-AP43*AP42)/(1-AP42) -> 0.11714286 | AQ47: =(AQ41-AQ43*AQ42)/(1-AQ42) -> 0.11666667
C48: D | D48: =D31*D46 -> 3525.3436 | E48: =E31*E46 -> 286.73835 | F48: =F31*F46 -> 4227.9412 | I48: Max | J48: =J47+O42 -> 1469.7556 | K48: 6 | L48: =J48+K48 -> 1475.7556 | AC48: E | AD48: =AD46-AD47 -> 5504.5872 | AE48: =AE31/(AE39-AE32) -> 907.40741 | AF48: =AF46-AF47 -> 6909.7889
C49: E | D49: =D46-D48 -> 5288.0154 | E49: =E46-E48 -> 860.21505 | F49: =F46-F48 -> 6341.9118 | T49: base | U49: transaction cost (M HUF) | V49: Bargaining range | AC49: Synergy | AF49: =AF46-AD46-AE46 -> 577.30599 | AG49: this we got from substracting together value - Firm A - Firm B | AN49: WACC | AO49: =AO41-AO42*AO43*AO44 -> 0.098125 | AP49: =AP41-AP42*AP43*AP44 -> 0.0973 | AQ49: =AQ41-AQ42*AQ43*AQ44 -> 0.098125 | AS49: Synergy
C50: Share Price | D50: =D49*1000000/D35 -> 528.80154 | E50: =E49*1000000/E35 -> 172.04301 | S50: Min | T50: =U47 -> 1578.9474 | U50: 4 | V50: =T50+U50 -> 1582.9474 | AD50: Base | AN50: V boy | AO50: =AO38/(AO49-AO40) -> 7339.4495 | AP50: =AP51*1/(1-AP42) -> 1296.2963 | AQ50: =AQ38/(AQ49-AQ40) -> 9213.0518 | AS50: =AQ50-AP50-AO50 -> 577.30599
S51: Max | T51: =T50+Y45 -> 2280.6814 | U51: 8 | V51: =T51-U51 -> 2272.6814 | AC51: Min | AD51: =AE48 -> 907.40741 | AF51: this is the minimum that you need to pay for the Equity of the company you want to acquire | AN51: E boy | AO51: =AO53 -> 5504.5872 | AP51: =AP39/(AP47-AP40) -> 907.40741 | AQ51: =AQ53 -> 6909.7889
...

Sheet Asset Val.
B2: =+Admin!C12 -> Date | C2: =+Admin!D12 -> 45272
B3: =+Admin!C13 -> Student name | C3: =+Admin!D13 -> 0
B4: =+Admin!C14 -> Neptun code | C4: =+Admin!D14 -> 0
B6: =+Admin!C16 -> Study program | C6: =+Admin!D16 -> Master in Finance
B7: =+Admin!C17 -> Instructor | C7: =+Admin!D17 -> Péter Juhász, PhD, CFA
B9: Points achived:
B20: Corporate tax rate | C20: 0.15 | F20: Corporate tax rate | G20: 0.15
B21: Required rate of return on renting | C21: 0.09 | F21: Required rate of return on renting | G21: 0.09
B22: Capitalisation rate for EBITDA | C22: 0.08 | F22: Capitalisation rate for EBITDA | G22: 0.08
B23: Average inflation during the last 20 years | C23: 0.02 | F23: Average inflation during the last 20 years | G23: 0.02
B25: Age of the building | C25: 20 | D25: years | F25: Age of the building | G25: 20 | H25: years
B26: Useful operational years left over | C26: 25 | D26: years | F26: Useful operational years left over | G26: 25 | H26: years
B27: Accounting life time left over | C27: 20 | D27: years | F27: Accounting life time left over | G27: 20 | H27: years
B29: Total net monthly rental income before D&A | C29: 200 | F29: Total net monthly rental income before D&A | G29: 200
B30: Expected g of rental fees | C30: 0.05 | F30: Expected g of rental fees | G30: 0.05
B32: Net book value of the building | C32: 28000 | F32: Net book value of the building | G32: 28000
B33: Gross book value of the building | C33: 50000 | F33: Gross book value of the building | G33: 50000
B35: D&A | C35: =C32/C27 -> 1400
B37: Growing annuity of Rent | C37: =C29/(C21-C30)*(1-((1+C30)^C26)/((1+C21)^C26)) -> 3036.4587 | F37: Rental fee | G37: =+G29*12*(1-G20)/(G21-G30)*(1-(1+G30)^G26/(1+G21)^G26) -> 30971.879 | H37: Growing annuity WITHOUT D&A= (c/(r-g) * (1- (1+g)^n / (1+r) ^n))* (1+r)
B38: TS of D&A | C38: =C35*C20/C21*(1-1/(1+C21)^C27) -> 1916.9946
B39: Total PV with TS | C39: =+C37+C38 -> 4953.4533 | F39: D&A | G39: =G32/G27 -> 1400
B40: Book Value of the Building | C40: =C32 -> 28000 | F40: tax shield of D&A | G40: =G39*G20 -> 210
B41: PV in 20 Years | C41: =C39+C40 -> 32953.453 | F41: PV of tax shield | G41: =G40/G21*(1-1/(1+G21)^G27) -> 1916.9946 | H41: Non growing annuity (20 yrs)
B42: PV Today | C42: =C41/(1+C21)^20 -> 5879.914
E43: 1 | F43: Total value | G43: =G37+G41 -> 32888.874
F46: Net income | G46: =G29*12 -> 2400
F47: Capitalization rate | G47: =G22 -> 0.08
E48: 2 | F48: Value | G48: =G46/G47 -> 30000
E51: 3 | F51: Adjusted purchase cost | G51: =+G33*(1+G23)^G25*G32/G33 -> 41606.527
B59: Adjusted historical cost | C59: =+C33*(1+C23)^C25*C32/C33 -> 41606.527
B60: Capitalization | C60: =+C29*12/C22 -> 30000
B62: DCF | C62: =+C63+C64 -> 32888.874
B63: Rental income | C63: =+C29*12*(1-C20)/(C21-C30)*(1-(1+C30)^C26/(1+C21)^C26) -> 30971.879
B64: TS | C64: =+C32/C27*C20/C21*(1-1/(1+C21)^C27) -> 1916.9946

Sheet Value of ratios
B2: Date | C2: 45280
B3: Student name | L3: 0 | M3: 0
B4: Neptun code | L4: 0 | M4: 0
L5: 0 | M5: 0
B6: Study program | C6: Master in Finance
B7: Instructor | C7: Péter Juhász, PhD, CFA | L7: 0 | M7: 0
L8: 0 | M8: 0
B9: Points achived:
L10: Points achived:
B26: P/E | E26: P/E | F26: =F54/F60 -> 12.307692
B27: EV/EBIT | E27: P/BV | F27: =F56/F49 -> 1.8823529 | L27: P/E | M27: =M54/M61 -> 22.222222
B28: P/BV | E28: P/S | F28: =F56/F34 -> 0.64 | L28: EV/EBIT | M28: =(M59-M45)/M36 -> 14.6875
B29: EV/BV | E29: EV/EBITDA | F29: =(F58-F41)/(F36) -> 13.25 | L29: P/BV | M29: =M57/M47 -> 3.5087719
B30: EV/S | E30: EV/tBV | F30: =(F58-F41)/F61 -> 1.7966102 | L30: EV/BV | M30: =(M59-M45)/M62 -> 2.1559633
L31: EV/S | M31: =(M59-M45)/M34 -> 1.1190476
B32: P/L
B33: Sales Revenue | C33: 10500000 | E33: P/L | L33: P/L
B34: D&A | C34: 700000 | E34: Revenue from Sales | F34: 10000000 | L34: Sales Revenue | M34: 10500000
B35: Operational profit | C35: 800000 | E35: D&A | F35: 600000 | L35: D&A | M35: 700000
B36: Profit before tax | C36: 700000 | E36: Operational profit | F36: 800000 | L36: Operational profit | M36: 800000
B37: Tax | C37: 250000 | E37: Profit before tax | F37: 700000 | L37: Profit before tax | M37: 700000
B38: After tax profit | C38: =+C36-C37 -> 450000 | E38: After tax profit | F38: 520000 | L38: Tax | M38: 250000
L39: After tax profit | M39: =+M37-M38 -> 450000
B40: Balance sheet | E40: Balance sheet
B41: PP&E | C41: 4000000 | E41: Cash | F41: 200000 | L41: Balance sheet
B42: Inventory | C42: 500000 | E42: Receivables | F42: 800000 | L42: PP&E | M42: 4000000
B43: Receivables | C43: 700000 | E43: Inventory | F43: 500000 | L43: Inventory | M43: 500000
B44: Cash | C44: 250000 | E44: PP&E | F44: 4000000 | L44: Receivables | M44: 700000
E45: Goodwill | F45: 400000 | L45: Cash | M45: 250000
B46: Equity | C46: =SUM(C41:C44)-C49-C48-C47 -> 2850000
B47: Variable rate bank loans | C47: 1100000 | E47: Payables | F47: 500000 | L47: Equity | M47: =SUM(M42:M45)-M50-M49-M48 -> 2850000
B48: Outstanding face value of bonds | C48: 1000000 | E48: Debt (Bonds only) | F48: 2000000 | L48: Variable rate bank loans | M48: 1100000
B49: Payables | C49: 500000 | E49: Equity | F49: =SUM(F41:F45)-F47-F48 -> 3400000 | L49: Outstanding face value of bonds | M49: 1000000
L50: Payables | M50: 500000
B51: Closing price of bonds | C51: 9 | E51: Number of bonds | F51: 100000
B52: Number of bonds | C52: 100000 | E52: Closing price of bonds | F52: 24 | L52: Closing price of bonds | M52: 9
B53: Closing price of shares | C53: 5 | E53: Number of shares | F53: 2000000 | L53: Number of bonds | M53: 100000
B54: Number of shares | C54: 2000000 | E54: Closing price of shares | F54: 3.2 | L54: Closing price of shares | M54: 5
L55: Number of shares | M55: 2000000
B56: EBIT | E56: Equity Market Value | F56: =F53*F54 -> 6400000
...

Sheet Bonus DCF comparison
B2: Date | C2: 45280
B3: Student name
B4: Neptun code
B6: Study program | C6: Master in Finance
B7: Instructor | C7: Péter Juhász, PhD, CFA
B9: Points achived:
B24: General data | C24: 2024 | D24: =+C24+1 -> 2025 | E24: =+D24+1 -> 2026 | F24: =+E24+1 -> 2027 | G24: =+F24+1 -> 2028 | H24: TV1 | I24: TV2
B25: IC boy | C25: 20000
B26: g TV | I26: 0.04
B27: rA | C27: 0.09 | D27: 0.09 | E27: 0.09 | F27: 0.09 | G27: 0.09 | H27: 0.09 | I27: 0.09
B28: D/V boy | H28: 0.35 | I28: 0.35
B29: rD | H29: 0.05 | I29: 0.05
B30: t | C30: 0.2 | D30: 0.2 | E30: 0.2 | F30: 0.2 | G30: 0.2 | H30: 0.2 | I30: 0.2
B32: Option A
B33: ROIC | C33: 0.1 | D33: 0.1 | E33: 0.1 | F33: 0.1 | G33: 0.1
B34: D/V | C34: 0.35 | D34: 0.35 | E34: 0.35 | F34: 0.35 | G34: 0.35
B35: rD | C35: 0.05 | D35: 0.05 | E35: 0.05 | F35: 0.05 | G35: 0.05
B36: g | D36: 0.04 | E36: 0.04 | F36: 0.04 | G36: 0.04 | H36: 0.04
B38: Option B
B39: Additional IC boy | C39: 1000
B40: ROIC | C40: 0.09
B41: RONIC | D41: 0.13 | E41: 0.12 | F41: 0.11 | G41: 0.1
B42: D/IC | C42: 0.5 | D42: 0.5 | E42: 0.5 | F42: 0.5 | G42: 0.5
B43: rD | C43: 0.07 | D43: 0.07 | E43: 0.07 | F43: 0.07 | G43: 0.07
B44: dIC | C44: 2000 | D44: 1900 | E44: 1800 | F44: 1700 | G44: 1600

Sheet Bonus Task CoE
B2: =+Admin!C12 -> Date | C2: =+Admin!D12 -> 45272
B3: =+Admin!C13 -> Student name | C3: =+Admin!D13 -> 0
B4: =+Admin!C14 -> Neptun code | C4: =+Admin!D14 -> 0
B6: =+Admin!C16 -> Study program | C6: =+Admin!D16 -> Master in Finance
B7: =+Admin!C17 -> Instructor | C7: =+Admin!D17 -> Péter Juhász, PhD, CFA
B9: Points achived:
B18: rF | C18: 0.03
B19: Market risk premium | C19: 0.06
B21: A
B22: D/V | C22: 0.5
B23: rD | C23: 0.05
B25: Only betaE is missing, why can't we just take the average of peers?!
C30: P | D30: number of shares | E30: Capitalisation | F30: betaE | G30: rE | H30: Debt | I30: debt risk premium | J30: betaD | K30: rD | L30: D/V
B31: X | C31: 10 | D31: 1000000 | E31: =C31*D31 -> 10000000 | F31: =(G31-C18)/C19 -> 1.3333333 | G31: 0.11 | H31: 5000000 | I31: =K31-C18 -> 0.006 | J31: 0.2 | K31: =C18+J31*(C19-C18) -> 0.036 | L31: =H31/E31 -> 0.5
B32: Y | E32: 5000000 | F32: 1.4 | G32: =$C$18+F32*$C$19 -> 0.114 | H32: =L32*E32 -> 2000000 | I32: 0.028 | L32: 0.4
B33: Z | F33: 1.2 | G33: =$C$18+F33*$C$19 -> 0.102 | J33: 0.15 | L33: 0.2
B38: rF | C38: 0.03
B39: Market risk premium | C39: 0.06
B41: A
B42: D/V | C42: 0.5
B43: rD | C43: 0.05
C50: P | D50: number of shares | E50: Capitalisation | F50: betaE | G50: rE | H50: Debt | I50: debt risk premium | J50: betaD | K50: rD | L50: D/V | M50: D/E | N50: E/V | O50: E | P50: rA
B51: X | C51: 10 | D51: 1000000 | E51: =C51*D51 -> 10000000 | F51: =(G51-C38)/C39 -> 1.3333333 | G51: 0.11 | H51: 5000000 | I51: =K51-C38 -> 0.012 | J51: 0.2 | K51: =C38+J51*C39 -> 0.042 | L51: =H51/(E51+H51) -> 0.33333333 | M51: =L51/(1-L51) -> 0.5 | N51: =1-L51 -> 0.66666667 | O51: =H51+E51 -> 15000000 | P51: =N51*G51+L51*K51 -> 0.087333333
B52: Y | E52: 5000000 | F52: 1.4 | G52: =$C$18+F52*$C$19 -> 0.114 | H52: =L52*E52 -> 2000000 | I52: 0.028 | J52: =I52/(K52-C38) -> 1 | K52: =I52+C38 -> 0.058 | L52: 0.4 | M52: =L52/(1-L52) -> 0.66666667 | N52: =1-L52 -> 0.6 | O52: =H52+E52 -> 7000000 | P52: =N52*G52+L52*K52 -> 0.0916
B53: Z | F53: 1.2 | G53: =$C$18+F53*$C$19 -> 0.102 | I53: =J53*C38 -> 0.0045 | J53: 0.15 | K53: =C38+J53*C39 -> 0.039 | L53: 0.2 | M53: =L53/(1-L53) -> 0.25 | N53: =1-L53 -> 0.8 | P53: =N53*G53+L53*K53 -> 0.0894
B54: A | E54: Average | F54: =AVERAGE(F51:F53) -> 1.3111111 | G54: =(P54-C42*K54)/N54 -> 0.12888889 | K54: =C43 -> 0.05 | L54: =C42 -> 0.5 | N54: =1-L54 -> 0.5 | O54: Average | P54: =AVERAGE(P51:P53) -> 0.089444444

Sheet Bonus Estimate element
B19: my calculations
B20: required results | D20: Competitor A | E20: Competitor B | F20: Competitor C | G20: Target Firm
B21: not sure at all about the ones in red lol | C21: # of shares | D21: 100000 | E21: 20000 | F21: 10000 | G21: 25000
C22: Current share quote | E22: 0.4 | F22: 0.7 | G22: 0.4
C23: E (market value) | D23: 7000 | E23: 8000 | F23: 7000 | G23: 10000
C24: D | D24: 5000 | E24: 2000 | G24: 7000
C25: V | D25: 12000 | E25: 10000 | G25: 17000
C26: D/V | D26: 0.4167 | E26: 0.2 | F26: 0.3 | G26: 0.4118
C27: beta E = (rE - rf) / (rM - rf) | D27: 1.2 | G27: 1.42
C28: beta D = (rD - rf) / (rM - rf) | E28: 0.2 | G28: 0.13
C29: beta A = (rA - rf) / (rM - rf) | G29: 0.89
C30: rE = rA + D/E * (rA - rD) | D30: 0.126 | E30: 0.12 | F30: 0.13 | G30: 0.144
C31: rD | D31: 0.045 | E31: 0.046 | F31: 0.05 | G31: 0.04
C32: rA = D/V * rD + (1-D/V) * rE | D32: 0.0923 | E32: 0.1052 | F32: 0.106 | G32: 0.1012
C33: rf | D33: 0.03 | E33: 0.03 | F33: 0.03 | G33: 0.03
C34: rM-rf | D34: 0.08 | E34: 0.08 | F34: 0.08 | G34: 0.08
C36: The 4 firms have different sizes and financing stuctures, but their operations should be roughly the same
C37: ==> it makes more sense to consider the average of rA for the target firm rather than rE … and based on rA we can calculated rE then the betas

Sheet Theory
B2: =+Admin!C12 -> Date | C2: =+Admin!D12 -> 45272
B3: =+Admin!C13 -> Student name | C3: =+Admin!D13 -> 0
B4: =+Admin!C14 -> Neptun code | C4: =+Admin!D14 -> 0
B6: =+Admin!C16 -> Study program | C6: =+Admin!D16 -> Master in Finance
B7: =+Admin!C17 -> Instructor | C7: =+Admin!D17 -> Péter Juhász, PhD, CFA | E7: Make the tab green once copied all the task to document
B9: Points achived:
J11: Adam
W13: Adam
S20: dcf | T20: 1200 | U20: 1400
S21: mm | T21: 900 | U21: 1100
S22: Ct | T22: 1000 | U22: 1200
S23: AB | T23: 600 | U23: 800
B37: Mridul
C63: From exam 12.12
