Workbook

Sheet Task1
A1: Date | B1: 45404
C4: Bond name | D4: 2028/A | E4: 2030/A | F4: 2032/A
C5: ISIN | D5: HU0000402532 | E5: HU0000403696 | F5: HU0000405550
C6: Expiration date | D6: 47048 | E6: 47716 | F6: 48542 | I6: Portfolio | J6: Market Value | K6: =SUM(D14:F14) -> 99995519 | L6: HUF
C7: Principal repayment | D7: at maturity | E7: at maturity | F7: at maturity | J7: Duration | K7: =SUMPRODUCT(D14:F14,D15:F15)/K6 -> 5.3219392 | L7: =ROUND(K7*365,0) -> 1943
C8: Interest type | D8: Fix | E8: Fix | F8: Fix
C9: Interest rate | D9: 0.0675 | E9: 0.03 | F9: 0.0475
C10: Interest payment frequency | D10: 1 year | E10: 1 year | F10: 1 year
C11: Next payment | D11: 45587 | E11: 45525 | F11: 45620
C12: Nominal value | D12: 10000 | E12: 10000 | F12: =E12 -> 10000
C13: Piece | D13: 4152 | E13: 3323 | F13: 3548 | G13: solver
C14: Market price | D14: =D13*H25 -> 42187479 | E14: =E13*H34 -> 27012926 | F14: =F13*H45 -> 30795115
C15: Duration | D15: =J25 -> 3.9034058 | E15: =J34 -> 5.6555852 | F15: =J45 -> 6.9725775
C18: Price and Duration Calculation
E19: t | F19: CF | G19: r | H19: PV | I19: w | J19: D
C20: 2028/A | D20: =D11 -> 45587 | E20: =D20-$B$1 -> 183 | F20: =$D$12*$D$9 -> 675 | G20: =_xlfn.XLOOKUP(E20,'zero-coupon-yields_202405171536'!$B$2:$B$1411,'zero-coupon-yields_202405171536'!D2:D1411,1,1)/100 -> 0.070976 | H20: =F20/(1+G20)^(E20/365) -> 652.18846 | I20: =H20/$H$25 -> 0.064186971 | J20: =I20*E20/365 -> 0.032181413
D21: =D20+365 -> 45952 | E21: =D21-$B$1 -> 548 | F21: =$D$12*$D$9 -> 675 | G21: =_xlfn.XLOOKUP(E21,'zero-coupon-yields_202405171536'!$B$2:$B$1411,'zero-coupon-yields_202405171536'!D3:D1412,1,1)/100 -> 0.071681 | H21: =F21/(1+G21)^(E21/365) -> 608.3651 | I21: =H21/$H$25 -> 0.059873971 | J21: =I21*E21/365 -> 0.089892976
D22: =D21+365 -> 46317 | E22: =D22-$B$1 -> 913 | F22: =$D$12*$D$9 -> 675 | G22: =_xlfn.XLOOKUP(E22,'zero-coupon-yields_202405171536'!$B$2:$B$1411,'zero-coupon-yields_202405171536'!D4:D1413,1,1)/100 -> 0.072059 | H22: =F22/(1+G22)^(E22/365) -> 567.17315 | I22: =H22/$H$25 -> 0.055819949 | J22: =I22*E22/365 -> 0.13962634
D23: =D22+365 -> 46682 | E23: =D23-$B$1 -> 1278 | F23: =$D$12*$D$9 -> 675 | G23: =_xlfn.XLOOKUP(E23,'zero-coupon-yields_202405171536'!$B$2:$B$1411,'zero-coupon-yields_202405171536'!D5:D1414,1,1)/100 -> 0.072114 | H23: =F23/(1+G23)^(E23/365) -> 528.95529 | I23: =H23/$H$25 -> 0.05205863 | J23: =I23*E23/365 -> 0.18227652
D24: =D6 -> 47048 | E24: =D24-$B$1 -> 1644 | F24: =$D$12*(1+$D$9) -> 10675 | G24: =_xlfn.XLOOKUP(E24,'zero-coupon-yields_202405171536'!$B$2:$B$1411,'zero-coupon-yields_202405171536'!D6:D1415,1,1)/100 -> 0.072025 | H24: =F24/(1+G24)^(E24/365) -> 7804.0788 | I24: =H24/$H$25 -> 0.76806048 | J24: =I24*E24/365 -> 3.4594286
H25: =SUM(H20:H24) -> 10160.761 | I25: =SUM(I20:I24) -> 1 | J25: =SUM(J20:J24) -> 3.9034058
C27: =E4 -> 2030/A | D27: =E11 -> 45525 | E27: =D27-$B$1 -> 121 | F27: =$E$12*$E$9 -> 300 | G27: =_xlfn.XLOOKUP(E27,'zero-coupon-yields_202405171536'!$B$2:$B$1411,'zero-coupon-yields_202405171536'!D2:D1411,1,1)/100 -> 0.070828 | H27: =F27/(1+G27)^(E27/365) -> 293.27089 | I27: =H27/$H$34 -> 0.036076772 | J27: =I27*E27/365 -> 0.011959697
D28: =D27+365 -> 45890 | E28: =D28-$B$1 -> 486 | F28: =$E$12*$E$9 -> 300 | G28: =_xlfn.XLOOKUP(E28,'zero-coupon-yields_202405171536'!$B$2:$B$1411,'zero-coupon-yields_202405171536'!D3:D1412,1,1)/100 -> 0.071582 | H28: =F28/(1+G28)^(E28/365) -> 273.61646 | I28: =H28/$H$34 -> 0.033658978 | J28: =I28*E28/365 -> 0.04481716
D29: =D28+365 -> 46255 | E29: =D29-$B$1 -> 851 | F29: =$E$12*$E$9 -> 300 | G29: =_xlfn.XLOOKUP(E29,'zero-coupon-yields_202405171536'!$B$2:$B$1411,'zero-coupon-yields_202405171536'!D4:D1413,1,1)/100 -> 0.072021 | H29: =F29/(1+G29)^(E29/365) -> 255.09507 | I29: =H29/$H$34 -> 0.031380567 | J29: =I29*E29/365 -> 0.073164006
D30: =D29+365 -> 46620 | E30: =D30-$B$1 -> 1216 | F30: =$E$12*$E$9 -> 300 | G30: =_xlfn.XLOOKUP(E30,'zero-coupon-yields_202405171536'!$B$2:$B$1411,'zero-coupon-yields_202405171536'!D5:D1414,1,1)/100 -> 0.072119 | H30: =F30/(1+G30)^(E30/365) -> 237.8847 | I30: =H30/$H$34 -> 0.02926343 | J30: =I30*E30/365 -> 0.097491317
D31: =D30+365 -> 46985 | E31: =D31-$B$1 -> 1581 | F31: =$E$12*$E$9 -> 300 | G31: =_xlfn.XLOOKUP(E31,'zero-coupon-yields_202405171536'!$B$2:$B$1411,'zero-coupon-yields_202405171536'!D6:D1415,1,1)/100 -> 0.072045 | H31: =F31/(1+G31)^(E31/365) -> 221.94909 | I31: =H31/$H$34 -> 0.027303108 | J31: =I31*E31/365 -> 0.1182636
D32: =D31+365 -> 47350 | E32: =D32-$B$1 -> 1946 | F32: =$E$12*$E$9 -> 300 | G32: =_xlfn.XLOOKUP(E32,'zero-coupon-yields_202405171536'!$B$2:$B$1411,'zero-coupon-yields_202405171536'!D7:D1416,1,1)/100 -> 0.071911 | H32: =F32/(1+G32)^(E32/365) -> 207.1714 | I32: =H32/$H$34 -> 0.025485227 | J32: =I32*E32/365 -> 0.13587466
D33: =E6 -> 47716 | E33: =D33-$B$1 -> 2312 | F33: =E12*(1+E9) -> 10300 | G33: =_xlfn.XLOOKUP(E33,'zero-coupon-yields_202405171536'!$B$2:$B$1411,'zero-coupon-yields_202405171536'!D8:D1417,1,1)/100 -> 0.071767 | H33: =F33/(1+G33)^(E33/365) -> 6640.0904 | I33: =H33/$H$34 -> 0.81683192 | J33: =I33*E33/365 -> 5.1740148
H34: =SUM(H27:H33) -> 8129.078 | I34: =SUM(I27:I33) -> 1 | J34: =SUM(J27:J33) -> 5.6555852
C36: =F4 -> 2032/A | D36: =F11 -> 45620 | E36: =D36-$B$1 -> 216 | F36: =$F$12*$F$9 -> 475 | G36: =_xlfn.XLOOKUP(E36,'zero-coupon-yields_202405171536'!$B$2:$B$1411,'zero-coupon-yields_202405171536'!D2:D1411,1,1)/100 -> 0.071039 | H36: =F36/(1+G36)^(E36/365) -> 456.09511 | I36: =H36/$H$45 -> 0.052548122 | J36: =I36*E36/365 -> 0.031096971
D37: =D36+365 -> 45985 | E37: =D37-$B$1 -> 581 | F37: =$F$12*$F$9 -> 475 | G37: =_xlfn.XLOOKUP(E37,'zero-coupon-yields_202405171536'!$B$2:$B$1411,'zero-coupon-yields_202405171536'!D3:D1412,1,1)/100 -> 0.071721 | H37: =F37/(1+G37)^(E37/365) -> 425.41233 | I37: =H37/$H$45 -> 0.049013064 | J37: =I37*E37/365 -> 0.078018056
D38: =D37+365 -> 46350 | E38: =D38-$B$1 -> 946 | F38: =$F$12*$F$9 -> 475 | G38: =_xlfn.XLOOKUP(E38,'zero-coupon-yields_202405171536'!$B$2:$B$1411,'zero-coupon-yields_202405171536'!D4:D1413,1,1)/100 -> 0.072075 | H38: =F38/(1+G38)^(E38/365) -> 396.60355 | I38: =H38/$H$45 -> 0.045693916 | J38: =I38*E38/365 -> 0.11842862
D39: =D38+365 -> 46715 | E39: =D39-$B$1 -> 1311 | F39: =$F$12*$F$9 -> 475 | G39: =_xlfn.XLOOKUP(E39,'zero-coupon-yields_202405171536'!$B$2:$B$1411,'zero-coupon-yields_202405171536'!D5:D1414,1,1)/100 -> 0.07211 | H39: =F39/(1+G39)^(E39/365) -> 369.89674 | I39: =H39/$H$45 -> 0.042616942 | J39: =I39*E39/365 -> 0.15307072
D40: =D39+365 -> 47080 | E40: =D40-$B$1 -> 1676 | F40: =$F$12*$F$9 -> 475 | G40: =_xlfn.XLOOKUP(E40,'zero-coupon-yields_202405171536'!$B$2:$B$1411,'zero-coupon-yields_202405171536'!D6:D1415,1,1)/100 -> 0.072013 | H40: =F40/(1+G40)^(E40/365) -> 345.1609 | I40: =H40/$H$45 -> 0.03976705 | J40: =I40*E40/365 -> 0.18260158
D41: =D40+365 -> 47445 | E41: =D41-$B$1 -> 2041 | F41: =$F$12*$F$9 -> 475 | G41: =_xlfn.XLOOKUP(E41,'zero-coupon-yields_202405171536'!$B$2:$B$1411,'zero-coupon-yields_202405171536'!D7:D1416,1,1)/100 -> 0.071873 | H41: =F41/(1+G41)^(E41/365) -> 322.20977 | I41: =H41/$H$45 -> 0.03712278 | J41: =I41*E41/365 -> 0.20758245
D42: =D41+365 -> 47810 | E42: =D42-$B$1 -> 2406 | F42: =$F$12*$F$9 -> 475 | G42: =_xlfn.XLOOKUP(E42,'zero-coupon-yields_202405171536'!$B$2:$B$1411,'zero-coupon-yields_202405171536'!D8:D1417,1,1)/100 -> 0.071735 | H42: =F42/(1+G42)^(E42/365) -> 300.85967 | I42: =H42/$H$45 -> 0.034662969 | J42: =I42*E42/365 -> 0.22849069
D43: =D42+365 -> 48175 | E43: =D43-$B$1 -> 2771 | F43: =$F$12*$F$9 -> 475 | G43: =_xlfn.XLOOKUP(E43,'zero-coupon-yields_202405171536'!$B$2:$B$1411,'zero-coupon-yields_202405171536'!D9:D1418,1,1)/100 -> 0.071631 | H43: =F43/(1+G43)^(E43/365) -> 280.92896 | I43: =H43/$H$45 -> 0.032366691 | J43: =I43*E43/365 -> 0.24572082
D44: =F6 -> 48542 | E44: =D44-$B$1 -> 3138 | F44: =F12*(1+F9) -> 10475 | G44: =_xlfn.XLOOKUP(E44,'zero-coupon-yields_202405171536'!$B$2:$B$1411,'zero-coupon-yields_202405171536'!D10:D1419,1,1)/100 -> 0.071556 | H44: =F44/(1+G44)^(E44/365) -> 5782.4031 | I44: =H44/$H$45 -> 0.66620846 | J44: =I44*E44/365 -> 5.7275676
H45: =SUM(H36:H44) -> 8679.5701 | I45: =SUM(I36:I44) -> 1 | J45: =SUM(J36:J44) -> 6.9725775
C48: Portfolio Cash Flow | D48: 45587 | E48: 45952 | F48: 46317 | G48: 46682 | H48: 47048 | I48: 45525 | J48: 45890 | K48: 46255 | L48: 46620 | M48: 46985 | N48: 47350 | O48: 47716 | P48: 45620 | Q48: 45985 | R48: 46350 | S48: 46715 | T48: 47080 | U48: 47445 | V48: 47810 | W48: 48175 | X48: 48542
...

Sheet Task2
B4: day | C4: year | F4: Mapped cash flow dates (years) | P4: Portfolio | T4: Correlation Matrix
A5: =Task1!D4 -> 2028/A | B5: =Task1!E20 -> 183 | C5: =B5/365 -> 0.50136986 | R5: 1 day
B6: =Task1!E21 -> 548 | C6: =B6/365 -> 1.5013699 | F6: t | G6: r(t) | H6: DF(t) | I6: CF' | J6: PV | K6: w(t) | L6: DUR | M6: w(t)*bond price volatility | T6: t | U6: 0.25 | V6: 0.5 | W6: 1 | X6: 3 | Y6: 5 | Z6: 10
B7: =Task1!E22 -> 913 | C7: =B7/365 -> 2.5013699 | F7: 0.25 | G7: {=_xlfn.XLOOKUP(Task1!$B$1,'Benchmark yields table'!$A$3:$A$599,_xlfn.XLOOKUP(Task2!F7,'Benchmark yields table'!$B$2:$I$2,'Benchmark yields table'!$B$3:$I$599))/100} -> 0.0668 | H7: =1/(1+G7)^F7 -> 0.98396409 | I7: =L45*M44 -> 358865.5 | J7: =H7*I7 -> 353110.76 | K7: =J7/$J$13 -> 0.0035200348 | L7: =K7*F7 -> 0.00088000871 | M7: =K7*U15 -> 1.7180811e-06 | Q7: Volatility | R7: {=SQRT(MMULT(TRANSPOSE(M7:M12),MMULT(U7:Z12,M7:M12)))} -> 0.0051693086 | T7: 0.25 | U7: =CORREL(_xlfn.XLOOKUP($T7,'Benchmark yields table'!$J$2:$Q$2,'Benchmark yields table'!$J$20:$Q$599),_xlfn.XLOOKUP(U$6,'Benchmark yields table'!$J$2:$Q$2,'Benchmark yields table'!$J$20:$Q$599)) -> 1 | V7: =CORREL(_xlfn.XLOOKUP($T7,'Benchmark yields table'!$J$2:$Q$2,'Benchmark yields table'!$J$20:$Q$599),_xlfn.XLOOKUP(V$6,'Benchmark yields table'!$J$2:$Q$2,'Benchmark yields table'!$J$20:$Q$599)) -> 0.60501119 | W7: =CORREL(_xlfn.XLOOKUP($T7,'Benchmark yields table'!$J$2:$Q$2,'Benchmark yields table'!$J$20:$Q$599),_xlfn.XLOOKUP(W$6,'Benchmark yields table'!$J$2:$Q$2,'Benchmark yields table'!$J$20:$Q$599)) -> 0.51525983 | X7: =CORREL(_xlfn.XLOOKUP($T7,'Benchmark yields table'!$J$2:$Q$2,'Benchmark yields table'!$J$20:$Q$599),_xlfn.XLOOKUP(X$6,'Benchmark yields table'!$J$2:$Q$2,'Benchmark yields table'!$J$20:$Q$599)) -> 0.38125654 | Y7: =CORREL(_xlfn.XLOOKUP($T7,'Benchmark yields table'!$J$2:$Q$2,'Benchmark yields table'!$J$20:$Q$599),_xlfn.XLOOKUP(Y$6,'Benchmark yields table'!$J$2:$Q$2,'Benchmark yields table'!$J$20:$Q$599)) -> 0.36677534 | Z7: =CORREL(_xlfn.XLOOKUP($T7,'Benchmark yields table'!$J$2:$Q$2,'Benchmark yields table'!$J$20:$Q$599),_xlfn.XLOOKUP(Z$6,'Benchmark yields table'!$J$2:$Q$2,'Benchmark yields table'!$J$20:$Q$599)) -> 0.3658849
B8: =Task1!E23 -> 1278 | C8: =B8/365 -> 3.5013699 | F8: 0.5 | G8: {=_xlfn.XLOOKUP(Task1!$B$1,'Benchmark yields table'!$A$3:$A$599,_xlfn.XLOOKUP(Task2!F8,'Benchmark yields table'!$B$2:$I$2,'Benchmark yields table'!$B$3:$I$599))/100} -> 0.0692 | H8: =1/(1+G8)^F8 -> 0.96709809 | I8: =M23*SUM(L24)+M44*SUM(L47)+M73*SUM(L74) -> 4631897.6 | J8: =H8*I8 -> 4479499.3 | K8: =J8/$J$13 -> 0.044654526 | L8: =K8*F8 -> 0.022327263 | M8: =K8*V15 -> 2.9048412e-05 | Q8: Multiplier for 99% confidence | R8: =NORMSINV(1-R13) -> -2.3263479 | T8: 0.5 | U8: =CORREL(_xlfn.XLOOKUP($T8,'Benchmark yields table'!$J$2:$Q$2,'Benchmark yields table'!$J$20:$Q$599),_xlfn.XLOOKUP(U$6,'Benchmark yields table'!$J$2:$Q$2,'Benchmark yields table'!$J$20:$Q$599)) -> 0.60501119 | V8: =CORREL(_xlfn.XLOOKUP($T8,'Benchmark yields table'!$J$2:$Q$2,'Benchmark yields table'!$J$20:$Q$599),_xlfn.XLOOKUP(V$6,'Benchmark yields table'!$J$2:$Q$2,'Benchmark yields table'!$J$20:$Q$599)) -> 1 | W8: =CORREL(_xlfn.XLOOKUP($T8,'Benchmark yields table'!$J$2:$Q$2,'Benchmark yields table'!$J$20:$Q$599),_xlfn.XLOOKUP(W$6,'Benchmark yields table'!$J$2:$Q$2,'Benchmark yields table'!$J$20:$Q$599)) -> 0.73079441 | X8: =CORREL(_xlfn.XLOOKUP($T8,'Benchmark yields table'!$J$2:$Q$2,'Benchmark yields table'!$J$20:$Q$599),_xlfn.XLOOKUP(X$6,'Benchmark yields table'!$J$2:$Q$2,'Benchmark yields table'!$J$20:$Q$599)) -> 0.53728582 | Y8: =CORREL(_xlfn.XLOOKUP($T8,'Benchmark yields table'!$J$2:$Q$2,'Benchmark yields table'!$J$20:$Q$599),_xlfn.XLOOKUP(Y$6,'Benchmark yields table'!$J$2:$Q$2,'Benchmark yields table'!$J$20:$Q$599)) -> 0.5331356 | Z8: =CORREL(_xlfn.XLOOKUP($T8,'Benchmark yields table'!$J$2:$Q$2,'Benchmark yields table'!$J$20:$Q$599),_xlfn.XLOOKUP(Z$6,'Benchmark yields table'!$J$2:$Q$2,'Benchmark yields table'!$J$20:$Q$599)) -> 0.55077977
B9: =Task1!E24 -> 1644 | C9: =B9/365 -> 4.5041096 | F9: 1 | G9: {=_xlfn.XLOOKUP(Task1!$B$1,'Benchmark yields table'!$A$3:$A$599,_xlfn.XLOOKUP(Task2!F9,'Benchmark yields table'!$B$2:$I$2,'Benchmark yields table'!$B$3:$I$599))/100} -> 0.0688 | H9: =1/(1+G9)^F9 -> 0.93562874 | I9: =M23*SUM(L26,L28,L32)+M44*SUM(L49,L53)+M73*SUM(L76,L78,L82) -> 5226346.3 | J9: =H9*I9 -> 4889919.8 | K9: =J9/$J$13 -> 0.048745862 | L9: =K9*F9 -> 0.048745862 | M9: =K9*W15 -> 5.8787736e-05 | Q9: VaR (1 day, 99%) | R9: =-R7*R8 -> 0.01202561 | T9: 1 | U9: =CORREL(_xlfn.XLOOKUP($T9,'Benchmark yields table'!$J$2:$Q$2,'Benchmark yields table'!$J$20:$Q$599),_xlfn.XLOOKUP(U$6,'Benchmark yields table'!$J$2:$Q$2,'Benchmark yields table'!$J$20:$Q$599)) -> 0.51525983 | V9: =CORREL(_xlfn.XLOOKUP($T9,'Benchmark yields table'!$J$2:$Q$2,'Benchmark yields table'!$J$20:$Q$599),_xlfn.XLOOKUP(V$6,'Benchmark yields table'!$J$2:$Q$2,'Benchmark yields table'!$J$20:$Q$599)) -> 0.73079441 | W9: =CORREL(_xlfn.XLOOKUP($T9,'Benchmark yields table'!$J$2:$Q$2,'Benchmark yields table'!$J$20:$Q$599),_xlfn.XLOOKUP(W$6,'Benchmark yields table'!$J$2:$Q$2,'Benchmark yields table'!$J$20:$Q$599)) -> 1 | X9: =CORREL(_xlfn.XLOOKUP($T9,'Benchmark yields table'!$J$2:$Q$2,'Benchmark yields table'!$J$20:$Q$599),_xlfn.XLOOKUP(X$6,'Benchmark yields table'!$J$2:$Q$2,'Benchmark yields table'!$J$20:$Q$599)) -> 0.66514828 | Y9: =CORREL(_xlfn.XLOOKUP($T9,'Benchmark yields table'!$J$2:$Q$2,'Benchmark yields table'!$J$20:$Q$599),_xlfn.XLOOKUP(Y$6,'Benchmark yields table'!$J$2:$Q$2,'Benchmark yields table'!$J$20:$Q$599)) -> 0.66363795 | Z9: =CORREL(_xlfn.XLOOKUP($T9,'Benchmark yields table'!$J$2:$Q$2,'Benchmark yields table'!$J$20:$Q$599),_xlfn.XLOOKUP(Z$6,'Benchmark yields table'!$J$2:$Q$2,'Benchmark yields table'!$J$20:$Q$599)) -> 0.67559884
A10: =Task1!E4 -> 2030/A | B10: =Task1!E27 -> 121 | C10: =B10/365 -> 0.33150685 | F10: 3 | G10: {=_xlfn.XLOOKUP(Task1!$B$1,'Benchmark yields table'!$A$3:$A$599,_xlfn.XLOOKUP(Task2!F10,'Benchmark yields table'!$B$2:$I$2,'Benchmark yields table'!$B$3:$I$599))/100} -> 0.0725 | H10: =1/(1+G10)^F10 -> 0.8106028 | I10: =M23*SUM(L30,L34,L36,L40)+M44*SUM(L51,L55,L57,L61)+M73*SUM(L80,L84,L86,L90) -> 21391831 | J10: =H10*I10 -> 17340278 | K10: =J10/$J$13 -> 0.17285903 | L10: =K10*F10 -> 0.51857708 | M10: =K10*X15 -> 0.00048992242 | Q10: VaR (HUF, 1 day, 99%) | R10: =R9*Task1!K6 -> 1202507.1 | T10: 3 | U10: =CORREL(_xlfn.XLOOKUP($T10,'Benchmark yields table'!$J$2:$Q$2,'Benchmark yields table'!$J$20:$Q$599),_xlfn.XLOOKUP(U$6,'Benchmark yields table'!$J$2:$Q$2,'Benchmark yields table'!$J$20:$Q$599)) -> 0.38125654 | V10: =CORREL(_xlfn.XLOOKUP($T10,'Benchmark yields table'!$J$2:$Q$2,'Benchmark yields table'!$J$20:$Q$599),_xlfn.XLOOKUP(V$6,'Benchmark yields table'!$J$2:$Q$2,'Benchmark yields table'!$J$20:$Q$599)) -> 0.53728582 | W10: =CORREL(_xlfn.XLOOKUP($T10,'Benchmark yields table'!$J$2:$Q$2,'Benchmark yields table'!$J$20:$Q$599),_xlfn.XLOOKUP(W$6,'Benchmark yields table'!$J$2:$Q$2,'Benchmark yields table'!$J$20:$Q$599)) -> 0.66514828 | X10: =CORREL(_xlfn.XLOOKUP($T10,'Benchmark yields table'!$J$2:$Q$2,'Benchmark yields table'!$J$20:$Q$599),_xlfn.XLOOKUP(X$6,'Benchmark yields table'!$J$2:$Q$2,'Benchmark yields table'!$J$20:$Q$599)) -> 1 | Y10: =CORREL(_xlfn.XLOOKUP($T10,'Benchmark yields table'!$J$2:$Q$2,'Benchmark yields table'!$J$20:$Q$599),_xlfn.XLOOKUP(Y$6,'Benchmark yields table'!$J$2:$Q$2,'Benchmark yields table'!$J$20:$Q$599)) -> 0.95541409 | Z10: =CORREL(_xlfn.XLOOKUP($T10,'Benchmark yields table'!$J$2:$Q$2,'Benchmark yields table'!$J$20:$Q$599),_xlfn.XLOOKUP(Z$6,'Benchmark yields table'!$J$2:$Q$2,'Benchmark yields table'!$J$20:$Q$599)) -> 0.91480363
B11: =Task1!E28 -> 486 | C11: =B11/365 -> 1.3315068 | F11: 5 | G11: {=_xlfn.XLOOKUP(Task1!$B$1,'Benchmark yields table'!$A$3:$A$599,_xlfn.XLOOKUP(Task2!F11,'Benchmark yields table'!$B$2:$I$2,'Benchmark yields table'!$B$3:$I$599))/100} -> 0.0721 | H11: =1/(1+G11)^F11 -> 0.70603059 | I11: =M23*SUM(L38,L42)+M44*SUM(L59,L63,L65,L69)+M73*SUM(L88,L92,L94,L98,L102,L106) -> 76488558 | J11: =H11*I11 -> 54003262 | K11: =J11/$J$13 -> 0.5383392 | L11: =K11*F11 -> 2.691696 | M11: =K11*Y15 -> 0.002719078 | Q11: VaR (10 days, 99%) | R11: =R9*SQRT(10) -> 0.038028318 | T11: 5 | U11: =CORREL(_xlfn.XLOOKUP($T11,'Benchmark yields table'!$J$2:$Q$2,'Benchmark yields table'!$J$20:$Q$599),_xlfn.XLOOKUP(U$6,'Benchmark yields table'!$J$2:$Q$2,'Benchmark yields table'!$J$20:$Q$599)) -> 0.36677534 | V11: =CORREL(_xlfn.XLOOKUP($T11,'Benchmark yields table'!$J$2:$Q$2,'Benchmark yields table'!$J$20:$Q$599),_xlfn.XLOOKUP(V$6,'Benchmark yields table'!$J$2:$Q$2,'Benchmark yields table'!$J$20:$Q$599)) -> 0.5331356 | W11: =CORREL(_xlfn.XLOOKUP($T11,'Benchmark yields table'!$J$2:$Q$2,'Benchmark yields table'!$J$20:$Q$599),_xlfn.XLOOKUP(W$6,'Benchmark yields table'!$J$2:$Q$2,'Benchmark yields table'!$J$20:$Q$599)) -> 0.66363795 | X11: =CORREL(_xlfn.XLOOKUP($T11,'Benchmark yields table'!$J$2:$Q$2,'Benchmark yields table'!$J$20:$Q$599),_xlfn.XLOOKUP(X$6,'Benchmark yields table'!$J$2:$Q$2,'Benchmark yields table'!$J$20:$Q$599)) -> 0.95541409 | Y11: =CORREL(_xlfn.XLOOKUP($T11,'Benchmark yields table'!$J$2:$Q$2,'Benchmark yields table'!$J$20:$Q$599),_xlfn.XLOOKUP(Y$6,'Benchmark yields table'!$J$2:$Q$2,'Benchmark yields table'!$J$20:$Q$599)) -> 1 | Z11: =CORREL(_xlfn.XLOOKUP($T11,'Benchmark yields table'!$J$2:$Q$2,'Benchmark yields table'!$J$20:$Q$599),_xlfn.XLOOKUP(Z$6,'Benchmark yields table'!$J$2:$Q$2,'Benchmark yields table'!$J$20:$Q$599)) -> 0.96353862
B12: =Task1!E29 -> 851 | C12: =B12/365 -> 2.3315068 | F12: 10 | G12: {=_xlfn.XLOOKUP(Task1!$B$1,'Benchmark yields table'!$A$3:$A$599,_xlfn.XLOOKUP(Task2!F12,'Benchmark yields table'!$B$2:$I$2,'Benchmark yields table'!$B$3:$I$599))/100} -> 0.0712 | H12: =1/(1+G12)^F12 -> 0.50268319 | I12: =M44*SUM(L67,L71)+M73*SUM(L96,L104,L100,L108) -> 38291502 | J12: =H12*I12 -> 19248494 | K12: =J12/$J$13 -> 0.19188135 | L12: =K12*F12 -> 1.9188135 | M12: =K12*Z15 -> 0.001969072 | T12: 10 | U12: =CORREL(_xlfn.XLOOKUP($T12,'Benchmark yields table'!$J$2:$Q$2,'Benchmark yields table'!$J$20:$Q$599),_xlfn.XLOOKUP(U$6,'Benchmark yields table'!$J$2:$Q$2,'Benchmark yields table'!$J$20:$Q$599)) -> 0.3658849 | V12: =CORREL(_xlfn.XLOOKUP($T12,'Benchmark yields table'!$J$2:$Q$2,'Benchmark yields table'!$J$20:$Q$599),_xlfn.XLOOKUP(V$6,'Benchmark yields table'!$J$2:$Q$2,'Benchmark yields table'!$J$20:$Q$599)) -> 0.55077977 | W12: =CORREL(_xlfn.XLOOKUP($T12,'Benchmark yields table'!$J$2:$Q$2,'Benchmark yields table'!$J$20:$Q$599),_xlfn.XLOOKUP(W$6,'Benchmark yields table'!$J$2:$Q$2,'Benchmark yields table'!$J$20:$Q$599)) -> 0.67559884 | X12: =CORREL(_xlfn.XLOOKUP($T12,'Benchmark yields table'!$J$2:$Q$2,'Benchmark yields table'!$J$20:$Q$599),_xlfn.XLOOKUP(X$6,'Benchmark yields table'!$J$2:$Q$2,'Benchmark yields table'!$J$20:$Q$599)) -> 0.91480363 | Y12: =CORREL(_xlfn.XLOOKUP($T12,'Benchmark yields table'!$J$2:$Q$2,'Benchmark yields table'!$J$20:$Q$599),_xlfn.XLOOKUP(Y$6,'Benchmark yields table'!$J$2:$Q$2,'Benchmark yields table'!$J$20:$Q$599)) -> 0.96353862 | Z12: =CORREL(_xlfn.XLOOKUP($T12,'Benchmark yields table'!$J$2:$Q$2,'Benchmark yields table'!$J$20:$Q$599),_xlfn.XLOOKUP(Z$6,'Benchmark yields table'!$J$2:$Q$2,'Benchmark yields table'!$J$20:$Q$599)) -> 1
B13: =Task1!E30 -> 1216 | C13: =B13/365 -> 3.3315068 | J13: =SUM(J7:J12) -> 1.0031456e+08 | K13: =J13/$J$13 -> 1 | L13: =SUM(L7:L12) -> 5.2010397 | Q13: Significance | R13: 0.99
B14: =Task1!E31 -> 1581 | C14: =B14/365 -> 4.3315068 | T14: "bond price volatilities" for Bechmark yield curve points
B15: =Task1!E32 -> 1946 | C15: =B15/365 -> 5.3315068 | U15: {=_xlfn.XLOOKUP(Task1!$B$1,'Benchmark yields table'!$A$3:$A$20,_xlfn.XLOOKUP(U6,'Benchmark yields table'!$BF$2:$BM$2,'Benchmark yields table'!$BF$3:$BM$20))} -> 0.0004880864 | V15: {=_xlfn.XLOOKUP(Task1!$B$1,'Benchmark yields table'!$A$3:$A$20,_xlfn.XLOOKUP(V6,'Benchmark yields table'!$BF$2:$BM$2,'Benchmark yields table'!$BF$3:$BM$20))} -> 0.00065051439 | W15: {=_xlfn.XLOOKUP(Task1!$B$1,'Benchmark yields table'!$A$3:$A$20,_xlfn.XLOOKUP(W6,'Benchmark yields table'!$BF$2:$BM$2,'Benchmark yields table'!$BF$3:$BM$20))} -> 0.0012060047 | X15: {=_xlfn.XLOOKUP(Task1!$B$1,'Benchmark yields table'!$A$3:$A$20,_xlfn.XLOOKUP(X6,'Benchmark yields table'!$BF$2:$BM$2,'Benchmark yields table'!$BF$3:$BM$20))} -> 0.002834231 | Y15: {=_xlfn.XLOOKUP(Task1!$B$1,'Benchmark yields table'!$A$3:$A$20,_xlfn.XLOOKUP(Y6,'Benchmark yields table'!$BF$2:$BM$2,'Benchmark yields table'!$BF$3:$BM$20))} -> 0.0050508639 | Z15: {=_xlfn.XLOOKUP(Task1!$B$1,'Benchmark yields table'!$A$3:$A$20,_xlfn.XLOOKUP(Z6,'Benchmark yields table'!$BF$2:$BM$2,'Benchmark yields table'!$BF$3:$BM$20))} -> 0.010261925
B16: =Task1!E33 -> 2312 | C16: =B16/365 -> 6.3342466
A17: =Task1!F4 -> 2032/A | B17: =Task1!E36 -> 216 | C17: =B17/365 -> 0.59178082
B18: =Task1!E37 -> 581 | C18: =B18/365 -> 1.5917808
B19: =Task1!E38 -> 946 | C19: =B19/365 -> 2.5917808
B20: =Task1!E39 -> 1311 | C20: =B20/365 -> 3.5917808 | F20: Cash Flow Mapping
B21: =Task1!E40 -> 1676 | C21: =B21/365 -> 4.5917808 | G21: t | H21: r(t) | I21: stddev(t) | J21: DF(t) | K21: CF | L21: CF' | M21: number of securities
B22: =Task1!E41 -> 2041 | C22: =B22/365 -> 5.5917808
B23: =Task1!E42 -> 2406 | C23: =B23/365 -> 6.5917808 | F23: =Task1!D4 -> 2028/A | M23: =Task1!D13 -> 4152
B24: =Task1!E43 -> 2771 | C24: =B24/365 -> 7.5917808 | F24: =1-((G25-G24)/(G26-G24)) -> 0.99726027 | G24: 0.5 | H24: {=_xlfn.XLOOKUP(Task1!$B$1,'Benchmark yields table'!$A$3:$A$599,_xlfn.XLOOKUP(Task2!G24,'Benchmark yields table'!$B$2:$I$2,'Benchmark yields table'!$B$3:$I$599))/100} -> 0.0692 | I24: {=_xlfn.XLOOKUP(Task1!$B$1,'Benchmark yields table'!$A$3:$A$599,_xlfn.XLOOKUP(Task2!G24,'Benchmark yields table'!$BF$2:$BM$2,'Benchmark yields table'!$BF$3:$BM$599))} -> 0.00065051439 | J24: =1/(1+H24)^G24 -> 0.96709809 | L24: =K25*M25 -> 670.61375 | M24: alfa | N24: PV= | P24: =K25*J25 -> 652.73171 | Q24: Korrel | R24: Vol | S24: =I25 -> 0.00065203628 | T24: a | V24: =I24^2+I26^2-2*Q25*I24*I26 -> 7.3096559e-07 | W24: =(-V25+SQRT(V25^2-4*V24*V26))/(2*V24) -> 1.4173419
B25: =Task1!E44 -> 3138 | C25: =B25/365 -> 8.5972603 | G25: =C5 -> 0.50136986 | H25: =F24*H24+(1-F24)*H26 -> 0.069198904 | I25: =F24*I24+(1-F24)*I26 -> 0.00065203628 | J25: =1/(1+H25)^G25 -> 0.96700995 | K25: =Task1!F20 -> 675 | M25: =MIN(W24:W25) -> 0.99350186 | N25: PV'= | P25: =L24*J24+L26*J26 -> 652.65318 | Q25: {=_xlfn.XLOOKUP(G24,$T$7:$T$12,_xlfn.XLOOKUP(G26,$U$6:$Z$6,$U$7:$Z$12))} -> 0.73079441 | R25: Vol' | S25: =SQRT((M25*I24)^2+((1-M25)*I26)^2+2*M25*(1-M25)*Q25*I24*I26) -> 0.00065203628 | T25: b | V25: =2*Q25*I24*I26-2*I26^2 -> -1.7622438e-06 | W25: =(-V25-SQRT(V25^2-4*V24*V26))/(2*V24) -> 0.99350186
G26: 1 | H26: {=_xlfn.XLOOKUP(Task1!$B$1,'Benchmark yields table'!$A$3:$A$599,_xlfn.XLOOKUP(Task2!G26,'Benchmark yields table'!$B$2:$I$2,'Benchmark yields table'!$B$3:$I$599))/100} -> 0.0688 | I26: {=_xlfn.XLOOKUP(Task1!$B$1,'Benchmark yields table'!$A$3:$A$599,_xlfn.XLOOKUP(Task2!G26,'Benchmark yields table'!$BF$2:$BM$2,'Benchmark yields table'!$BF$3:$BM$599))} -> 0.0012060047 | J26: =1/(1+H26)^G26 -> 0.93562874 | L26: =(1-M25)*K25 -> 4.3862466 | N26: Pvdiff | P26: =ABS(P24-P25) -> 0.078536621 | R26: Voldiff | S26: =ABS(S24-S25) -> 0 | T26: c | V26: =I26^2-I25^2 -> 1.0292959e-06
F28: =1-((G29-G28)/(G30-G28)) -> 0.74931507 | G28: 1 | H28: {=_xlfn.XLOOKUP(Task1!$B$1,'Benchmark yields table'!$A$3:$A$599,_xlfn.XLOOKUP(G28,'Benchmark yields table'!$B$2:$I$2,'Benchmark yields table'!$B$3:$I$599))/100} -> 0.0688 | I28: {=_xlfn.XLOOKUP(Task1!$B$1,'Benchmark yields table'!$A$3:$A$599,_xlfn.XLOOKUP(G28,'Benchmark yields table'!$BF$2:$BM$2,'Benchmark yields table'!$BF$3:$BM$599))} -> 0.0012060047 | J28: =1/(1+H28)^G28 -> 0.93562874 | L28: =K29*M29 -> 442.40156 | M28: alfa | N28: PV= | P28: =K29*J29 -> 610.03382 | Q28: Korrel | R28: Vol | S28: =I29 -> 0.0016141765 | T28: a | V28: =I28^2+I30^2-2*Q29*I28*I30 -> 4.9402317e-06 | W28: =(-V29+SQRT(V29^2-4*V28*V30))/(2*V28) -> 1.6761915
G29: =C6 -> 1.5013699 | H29: =H28*F28+(1-F28)*H30 -> 0.069727534 | I29: =I28*F28+(1-F28)*I30 -> 0.0016141765 | J29: =1/(1+H29)^G29 -> 0.9037538 | K29: =Task1!F21 -> 675 | M29: =MIN(W28:W29) -> 0.65540972 | N29: PV'= | P29: =L28*J28+L30*J30 -> 602.46856 | Q29: {=_xlfn.XLOOKUP(G28,$T$7:$T$12,_xlfn.XLOOKUP(G30,$U$6:$Z$6,$U$7:$Z$12))} -> 0.66514828 | R29: Vol' | S29: =SQRT((M29*I28)^2+((1-M29)*I30)^2+2*M29*(1-M29)*Q29*I28*I30) -> 0.0016141765 | T29: b | V29: =2*Q29*I28*I30-2*I30^2 -> -1.151865e-05 | W29: =(-V29-SQRT(V29^2-4*V28*V30))/(2*V28) -> 0.65540972
G30: 3 | H30: {=_xlfn.XLOOKUP(Task1!$B$1,'Benchmark yields table'!$A$3:$A$599,_xlfn.XLOOKUP(G30,'Benchmark yields table'!$B$2:$I$2,'Benchmark yields table'!$B$3:$I$599))/100} -> 0.0725 | I30: {=_xlfn.XLOOKUP(Task1!$B$1,'Benchmark yields table'!$A$3:$A$599,_xlfn.XLOOKUP(G30,'Benchmark yields table'!$BF$2:$BM$2,'Benchmark yields table'!$BF$3:$BM$599))} -> 0.002834231 | J30: =1/(1+H30)^G30 -> 0.8106028 | L30: =(1-M29)*K29 -> 232.59844 | N30: Pvdiff | P30: =ABS(P28-P29) -> 7.5652561 | R30: Voldiff | S30: =ABS(S28-S29) -> 0 | T30: c | V30: =I30^2-I29^2 -> 5.4272999e-06
F32: =1-((G33-G32)/(G34-G32)) -> 0.24931507 | G32: 1 | H32: {=_xlfn.XLOOKUP(Task1!$B$1,'Benchmark yields table'!$A$3:$A$599,_xlfn.XLOOKUP(G32,'Benchmark yields table'!$B$2:$I$2,'Benchmark yields table'!$B$3:$I$599))/100} -> 0.0688 | I32: {=_xlfn.XLOOKUP(Task1!$B$1,'Benchmark yields table'!$A$3:$A$599,_xlfn.XLOOKUP(G32,'Benchmark yields table'!$BF$2:$BM$2,'Benchmark yields table'!$BF$3:$BM$599))} -> 0.0012060047 | J32: =1/(1+H32)^G32 -> 0.93562874 | L32: =K33*M33 -> 137.13648 | M32: alfa | N32: PV= | P32: =K33*J33 -> 567.81079 | Q32: Korrel | R32: Vol | S32: =I33 -> 0.0024282897 | T32: a | V32: =I32^2+I34^2-2*Q33*I32*I34 -> 4.9402317e-06 | W32: =(-V33+SQRT(V33^2-4*V32*V34))/(2*V32) -> 2.128436
G33: =C7 -> 2.5013699 | H33: =H32*F32+(1-F32)*H34 -> 0.071577534 | I33: =I32*F32+(1-F32)*I34 -> 0.0024282897 | J33: =1/(1+H33)^G33 -> 0.84120118 | K33: =Task1!F22 -> 675 | M33: =MIN(W32:W33) -> 0.20316515 | N33: PV'= | P33: =L32*J32+L34*J34 -> 564.30251 | Q33: {=_xlfn.XLOOKUP(G32,$T$7:$T$12,_xlfn.XLOOKUP(G34,$U$6:$Z$6,$U$7:$Z$12))} -> 0.66514828 | R33: Vol' | S33: =SQRT((M33*I32)^2+((1-M33)*I34)^2+2*M33*(1-M33)*Q33*I32*I34) -> 0.0024282897 | T33: b | V33: =2*Q33*I32*I34-2*I34^2 -> -1.151865e-05 | W33: =(-V33-SQRT(V33^2-4*V32*V34))/(2*V32) -> 0.20316515
G34: 3 | H34: {=_xlfn.XLOOKUP(Task1!$B$1,'Benchmark yields table'!$A$3:$A$599,_xlfn.XLOOKUP(G34,'Benchmark yields table'!$B$2:$I$2,'Benchmark yields table'!$B$3:$I$599))/100} -> 0.0725 | I34: {=_xlfn.XLOOKUP(Task1!$B$1,'Benchmark yields table'!$A$3:$A$599,_xlfn.XLOOKUP(G34,'Benchmark yields table'!$BF$2:$BM$2,'Benchmark yields table'!$BF$3:$BM$599))} -> 0.002834231 | J34: =1/(1+H34)^G34 -> 0.8106028 | L34: =(1-M33)*K33 -> 537.86352 | N34: Pvdiff | P34: =ABS(P32-P33) -> 3.5082896 | R34: Voldiff | S34: =ABS(S32-S33) -> 4.3368087e-19 | T34: c | V34: =I34^2-I33^2 -> 2.1362749e-06
F36: =1-((G37-G36)/(G38-G36)) -> 0.74931507 | G36: 3 | H36: {=_xlfn.XLOOKUP(Task1!$B$1,'Benchmark yields table'!$A$3:$A$599,_xlfn.XLOOKUP(G36,'Benchmark yields table'!$B$2:$I$2,'Benchmark yields table'!$B$3:$I$599))/100} -> 0.0725 | I36: {=_xlfn.XLOOKUP(Task1!$B$1,'Benchmark yields table'!$A$3:$A$599,_xlfn.XLOOKUP(G36,'Benchmark yields table'!$BF$2:$BM$2,'Benchmark yields table'!$BF$3:$BM$599))} -> 0.002834231 | J36: =1/(1+H36)^G36 -> 0.8106028 | L36: =K37*M37 -> 494.62086 | M36: alfa | N36: PV= | P36: =K37*J37 -> 528.46199 | Q36: Korrel | R36: Vol | S36: =I37 -> 0.0033899075 | T36: a | V36: =I36^2+I38^2-2*Q37*I36*I38 -> 6.189984e-06 | W36: =(-V37+SQRT(V37^2-4*V36*V38))/(2*V36) -> 3.0908804
G37: =C8 -> 3.5013699 | H37: =F36*H36+(1-F36)*H38 -> 0.072399726 | I37: =I36*F36+(1-F36)*I38 -> 0.0033899075 | J37: =1/(1+H37)^G37 -> 0.78290666 | K37: =Task1!F23 -> 675 | M37: =MIN(W36:W37) -> 0.73277164 | N37: PV'= | P37: =L36*J36+L38*J38 -> 528.29424 | Q37: {=_xlfn.XLOOKUP(G36,$T$7:$T$12,_xlfn.XLOOKUP(G38,$U$6:$Z$6,$U$7:$Z$12))} -> 0.95541409 | R37: Vol' | S37: =SQRT((M37*I36)^2+((1-M37)*I38)^2+2*M37*(1-M37)*Q37*I36*I38) -> 0.0033899075 | T37: b | V37: =2*Q37*I36*I38-2*I38^2 -> -2.3668345e-05 | W37: =(-V37-SQRT(V37^2-4*V36*V38))/(2*V36) -> 0.73277164
G38: 5 | H38: {=_xlfn.XLOOKUP(Task1!$B$1,'Benchmark yields table'!$A$3:$A$599,_xlfn.XLOOKUP(G38,'Benchmark yields table'!$B$2:$I$2,'Benchmark yields table'!$B$3:$I$599))/100} -> 0.0721 | I38: {=_xlfn.XLOOKUP(Task1!$B$1,'Benchmark yields table'!$A$3:$A$599,_xlfn.XLOOKUP(G38,'Benchmark yields table'!$BF$2:$BM$2,'Benchmark yields table'!$BF$3:$BM$599))} -> 0.0050508639 | J38: =1/(1+H38)^G38 -> 0.70603059 | L38: =(1-M37)*K37 -> 180.37914 | N38: Pvdiff | P38: =ABS(P36-P37) -> 0.16774951 | R38: Voldiff | S38: =ABS(S36-S37) -> 4.3368087e-19 | T38: c | V38: =I38^2-I37^2 -> 1.4019753e-05
F40: =1-((G41-G40)/(G42-G40)) -> 0.24794521 | G40: 3 | H40: {=_xlfn.XLOOKUP(Task1!$B$1,'Benchmark yields table'!$A$3:$A$599,_xlfn.XLOOKUP(G40,'Benchmark yields table'!$B$2:$I$2,'Benchmark yields table'!$B$3:$I$599))/100} -> 0.0725 | I40: {=_xlfn.XLOOKUP(Task1!$B$1,'Benchmark yields table'!$A$3:$A$599,_xlfn.XLOOKUP(G40,'Benchmark yields table'!$BF$2:$BM$2,'Benchmark yields table'!$BF$3:$BM$599))} -> 0.002834231 | J40: =1/(1+H40)^G40 -> 0.8106028 | L40: =K41*M41 -> 2523.8846 | M40: alfa | N40: PV= | P40: =K41*J41 -> 7798.3702 | Q40: Korrel | R40: Vol | S40: =I41 -> 0.0045012604 | T40: a | V40: =I40^2+I42^2-2*Q41*I40*I42 -> 6.189984e-06 | W40: =(-V41+SQRT(V41^2-4*V40*V42))/(2*V40) -> 3.5872225
G41: =C9 -> 4.5041096 | H41: =F40*H40+(1-F40)*H42 -> 0.072199178 | I41: =I40*F40+(1-F40)*I42 -> 0.0045012604 | J41: =1/(1+H41)^G41 -> 0.73052648 | K41: =Task1!F24 -> 10675 | M41: =MIN(W40:W41) -> 0.23642947 | N41: PV'= | P41: =L40*J40+L42*J42 -> 7800.8048 | Q41: {=_xlfn.XLOOKUP(G40,$T$7:$T$12,_xlfn.XLOOKUP(G42,$U$6:$Z$6,$U$7:$Z$12))} -> 0.95541409 | R41: Vol' | S41: =SQRT((M41*I40)^2+((1-M41)*I42)^2+2*M41*(1-M41)*Q41*I40*I42) -> 0.0045012604 | T41: b | V41: =2*Q41*I40*I42-2*I42^2 -> -2.3668345e-05 | W41: =(-V41-SQRT(V41^2-4*V40*V42))/(2*V40) -> 0.23642947
G42: 5 | H42: {=_xlfn.XLOOKUP(Task1!$B$1,'Benchmark yields table'!$A$3:$A$599,_xlfn.XLOOKUP(G42,'Benchmark yields table'!$B$2:$I$2,'Benchmark yields table'!$B$3:$I$599))/100} -> 0.0721 | I42: {=_xlfn.XLOOKUP(Task1!$B$1,'Benchmark yields table'!$A$3:$A$599,_xlfn.XLOOKUP(G42,'Benchmark yields table'!$BF$2:$BM$2,'Benchmark yields table'!$BF$3:$BM$599))} -> 0.0050508639 | J42: =1/(1+H42)^G42 -> 0.70603059 | L42: =(1-M41)*K41 -> 8151.1154 | N42: Pvdiff | P42: =ABS(P40-P41) -> 2.4345313 | R42: Voldiff | S42: =ABS(S40-S41) -> 0 | T42: c | V42: =I42^2-I41^2 -> 5.2498809e-06
F44: =Task1!E4 -> 2030/A | M44: =Task1!E13 -> 3323
F45: =1-((G46-G45)/(G47-G45)) -> 0.6739726 | G45: 0.25 | H45: {=_xlfn.XLOOKUP(Task1!$B$1,'Benchmark yields table'!$A$3:$A$599,_xlfn.XLOOKUP(Task2!G45,'Benchmark yields table'!$B$2:$I$2,'Benchmark yields table'!$B$3:$I$599))/100} -> 0.0668 | I45: {=_xlfn.XLOOKUP(Task1!$B$1,'Benchmark yields table'!$A$3:$A$599,_xlfn.XLOOKUP(Task2!G45,'Benchmark yields table'!$BF$2:$BM$2,'Benchmark yields table'!$BF$3:$BM$599))} -> 0.0004880864 | J45: =1/(1+H45)^G45 -> 0.98396409 | L45: =K46*M46 -> 107.99443 | M45: alfa | N45: PV= | P45: =K46*J46 -> 293.56616 | Q45: Korrel | R45: Vol | S45: =I46 -> 0.00054104237 | T45: a | V45: =I45^2+I47^2-2*Q46*I45*I47 -> 2.7720646e-07 | W45: =(-V46+SQRT(V46^2-4*V45*V47))/(2*V45) -> 1.3071771
G46: =C10 -> 0.33150685 | H46: =F45*H45+(1-F45)*H47 -> 0.067582466 | I46: =F45*I45+(1-F45)*I47 -> 0.00054104237 | J46: =1/(1+H46)^G46 -> 0.97855385 | K46: =Task1!F27 -> 300 | M46: =MIN(W45:W46) -> 0.35998144 | N46: PV'= | P46: =L45*J45+L47*J47 -> 291.95086 | Q46: {=_xlfn.XLOOKUP(G45,$T$7:$T$12,_xlfn.XLOOKUP(G47,$U$6:$Z$6,$U$7:$Z$12))} -> 0.60501119 | R46: Vol' | S46: =SQRT((M46*I45)^2+((1-M46)*I47)^2+2*M46*(1-M46)*Q46*I45*I47) -> 0.00054104237 | T46: b | V46: =2*Q46*I45*I47-2*I47^2 -> -4.621471e-07 | W46: =(-V46-SQRT(V46^2-4*V45*V47))/(2*V45) -> 0.35998144
G47: 0.5 | H47: {=_xlfn.XLOOKUP(Task1!$B$1,'Benchmark yields table'!$A$3:$A$599,_xlfn.XLOOKUP(Task2!G47,'Benchmark yields table'!$B$2:$I$2,'Benchmark yields table'!$B$3:$I$599))/100} -> 0.0692 | I47: {=_xlfn.XLOOKUP(Task1!$B$1,'Benchmark yields table'!$A$3:$A$599,_xlfn.XLOOKUP(Task2!G47,'Benchmark yields table'!$BF$2:$BM$2,'Benchmark yields table'!$BF$3:$BM$599))} -> 0.00065051439 | J47: =1/(1+H47)^G47 -> 0.96709809 | L47: =(1-M46)*K46 -> 192.00557 | N47: Pvdiff | P47: =ABS(P45-P46) -> 1.6152949 | R47: Voldiff | S47: =ABS(S45-S46) -> 0 | T47: c | V47: =I47^2-I46^2 -> 1.3044213e-07
F49: =1-((G50-G49)/(G51-G49)) -> 0.83424658 | G49: 1 | H49: {=_xlfn.XLOOKUP(Task1!$B$1,'Benchmark yields table'!$A$3:$A$599,_xlfn.XLOOKUP(G49,'Benchmark yields table'!$B$2:$I$2,'Benchmark yields table'!$B$3:$I$599))/100} -> 0.0688 | I49: {=_xlfn.XLOOKUP(Task1!$B$1,'Benchmark yields table'!$A$3:$A$599,_xlfn.XLOOKUP(G49,'Benchmark yields table'!$BF$2:$BM$2,'Benchmark yields table'!$BF$3:$BM$599))} -> 0.0012060047 | J49: =1/(1+H49)^G49 -> 0.93562874 | L49: =K50*M50 -> 224.5998 | M49: alfa | N49: PV= | P49: =K50*J50 -> 274.35553 | Q49: Korrel | R49: Vol | S49: =I50 -> 0.0014758888 | T49: a | V49: =I49^2+I51^2-2*Q50*I49*I51 -> 4.9402317e-06 | W49: =(-V50+SQRT(V50^2-4*V49*V51))/(2*V49) -> 1.5829352
...

Sheet Task3
C4: date | D4: 44851
E5: t | F5: CF | G5: r | H5: PV | I5: w | J5: D
C6: 2028/A | D6: 45587 | E6: 183 | F6: 675 | G6: =_xlfn.XLOOKUP(E6,'zero-coupon-yields_202405172251'!$B$2:$B$1490,'zero-coupon-yields_202405172251'!$D$2:$D$1490,,1,1)/100 -> 0.136458 | H6: =F6/(1+G6)^(E6/365) -> 633.0689 | I6: =H6/$H$11 -> 0.077169335 | J6: =I6*E6/365 -> 0.038690379
D7: 45952 | E7: 548 | F7: 675 | G7: =_xlfn.XLOOKUP(E7,'zero-coupon-yields_202405172251'!$B$2:$B$1490,'zero-coupon-yields_202405172251'!$D$2:$D$1490,,1,1)/100 -> 0.1418 | H7: =F7/(1+G7)^(E7/365) -> 553.14606 | I7: =H7/$H$11 -> 0.067426964 | J7: =I7*E7/365 -> 0.10123281
D8: 46317 | E8: 913 | F8: 675 | G8: =_xlfn.XLOOKUP(E8,'zero-coupon-yields_202405172251'!$B$2:$B$1490,'zero-coupon-yields_202405172251'!$D$2:$D$1490,,1,1)/100 -> 0.143124 | H8: =F8/(1+G8)^(E8/365) -> 483.04861 | I8: =H8/$H$11 -> 0.058882279 | J8: =I8*E8/365 -> 0.14728636
D9: 46682 | E9: 1278 | F9: 675 | G9: =_xlfn.XLOOKUP(E9,'zero-coupon-yields_202405172251'!$B$2:$B$1490,'zero-coupon-yields_202405172251'!$D$2:$D$1490,,1,1)/100 -> 0.139158 | H9: =F9/(1+G9)^(E9/365) -> 427.74248 | I9: =H9/$H$11 -> 0.052140617 | J9: =I9*E9/365 -> 0.18256358
D10: 47048 | E10: 1644 | F10: 10675 | G10: =_xlfn.XLOOKUP(E10,'zero-coupon-yields_202405172251'!$B$2:$B$1490,'zero-coupon-yields_202405172251'!$D$2:$D$1490,,1,1)/100 -> 0.132021 | H10: =F10/(1+G10)^(E10/365) -> 6106.6269 | I10: =H10/$H$11 -> 0.74438081 | J10: =I10*E10/365 -> 3.3527727
H11: =SUM(H6:H10) -> 8203.633 | I11: =SUM(I6:I10) -> 1 | J11: =SUM(J6:J10) -> 3.8225459
C13: 2030/A | D13: 45525 | E13: 121 | F13: 300 | G13: =_xlfn.XLOOKUP(E13,'zero-coupon-yields_202405172251'!$B$2:$B$1490,'zero-coupon-yields_202405172251'!$D$2:$D$1490,,1,1)/100 -> 0.135242 | H13: =F13/(1+G13)^(E13/365) -> 287.64647 | I13: =H13/$H$20 -> 0.044955572 | J13: =I13*E13/365 -> 0.01490308
D14: 45890 | E14: 486 | F14: 300 | G14: =_xlfn.XLOOKUP(E14,'zero-coupon-yields_202405172251'!$B$2:$B$1490,'zero-coupon-yields_202405172251'!$D$2:$D$1490,,1,1)/100 -> 0.141115 | H14: =F14/(1+G14)^(E14/365) -> 251.6441 | I14: =H14/$H$20 -> 0.039328848 | J14: =I14*E14/365 -> 0.05236663 | N14: =C6 -> 2028/A | O14: =C13 -> 2030/A | P14: =C22 -> 2032/A
D15: 46255 | E15: 851 | F15: 300 | G15: =_xlfn.XLOOKUP(E15,'zero-coupon-yields_202405172251'!$B$2:$B$1490,'zero-coupon-yields_202405172251'!$D$2:$D$1490,,1,1)/100 -> 0.143263 | H15: =F15/(1+G15)^(E15/365) -> 219.55994 | I15: =H15/$H$20 -> 0.034314493 | J15: =I15*E15/365 -> 0.080004476 | M15: piece | N15: =Task1!D13 -> 4152 | O15: =Task1!E13 -> 3323 | P15: =Task1!F13 -> 3548
D16: 46620 | E16: 1216 | F16: 300 | G16: =_xlfn.XLOOKUP(E16,'zero-coupon-yields_202405172251'!$B$2:$B$1490,'zero-coupon-yields_202405172251'!$D$2:$D$1490,,1,1)/100 -> 0.140151 | H16: =F16/(1+G16)^(E16/365) -> 193.79864 | I16: =H16/$H$20 -> 0.030288321 | J16: =I16*E16/365 -> 0.10090575 | M16: price | N16: =H11 -> 8203.633 | O16: =H20 -> 6398.461 | P16: =H31 -> 8663.7269
D17: 46985 | E17: 1581 | F17: 300 | G17: =_xlfn.XLOOKUP(E17,'zero-coupon-yields_202405172251'!$B$2:$B$1490,'zero-coupon-yields_202405172251'!$D$2:$D$1490,,1,1)/100 -> 0.133378 | H17: =F17/(1+G17)^(E17/365) -> 174.4201 | I17: =H17/$H$20 -> 0.027259696 | J17: =I17*E17/365 -> 0.11807556 | M17: Market value | N17: =N15*N16 -> 34061484 | O17: =O15*O16 -> 21262086 | P17: =P15*P16 -> 30738903
D18: 47350 | E18: 1946 | F18: 300 | G18: =_xlfn.XLOOKUP(E18,'zero-coupon-yields_202405172251'!$B$2:$B$1490,'zero-coupon-yields_202405172251'!$D$2:$D$1490,,1,1)/100 -> 0.125231 | H18: =F18/(1+G18)^(E18/365) -> 159.92849 | I18: =H18/$H$20 -> 0.024994838 | J18: =I18*E18/365 -> 0.13326015
D19: 47716 | E19: 2312 | F19: 10300 | G19: =_xlfn.XLOOKUP(E19,'zero-coupon-yields_202405172251'!$B$2:$B$1490,'zero-coupon-yields_202405172251'!$D$2:$D$1490,,1,1)/100 -> 0.116964 | H19: =F19/(1+G19)^(E19/365) -> 5111.4632 | I19: =H19/$H$20 -> 0.79885823 | J19: =I19*E19/365 -> 5.060165 | M19: Portfolio Value
H20: =SUM(H13:H19) -> 6398.461 | I20: =SUM(I13:I19) -> 1 | J20: =SUM(J13:J19) -> 5.5596807 | M20: Yield 2024.04.22 | N20: =Task1!K6 -> 99995519
M21: Yield 2022.10.17 | N21: =SUM(N17:P17) -> 86062473
C22: 2032/A | D22: 45620 | E22: 216 | F22: 475 | G22: =_xlfn.XLOOKUP(E22,'zero-coupon-yields_202405172251'!$B$2:$B$1490,'zero-coupon-yields_202405172251'!$D$2:$D$1490,,1,1)/100 -> 0.136975 | H22: =F22/(1+G22)^(E22/365) -> 440.25195 | I22: =H22/$H$31 -> 0.050815538 | J22: =I22*E22/365 -> 0.030071661 | M22: Change (%) in value | N22: =(N21-N20)/N20 -> -0.13933671
D23: 45985 | E23: 581 | F23: 475 | G23: =_xlfn.XLOOKUP(E23,'zero-coupon-yields_202405172251'!$B$2:$B$1490,'zero-coupon-yields_202405172251'!$D$2:$D$1490,,1,1)/100 -> 0.142067 | H23: 425.41233 | I23: =H23/$H$31 -> 0.049102694 | J23: =I23*E23/365 -> 0.078160726 | M23: Day | N23: =Task1!B1-Task3!D4 -> 553
D24: 46350 | E24: 946 | F24: 475 | G24: =_xlfn.XLOOKUP(E24,'zero-coupon-yields_202405172251'!$B$2:$B$1490,'zero-coupon-yields_202405172251'!$D$2:$D$1490,,1,1)/100 -> 0.142971 | H24: 396.60355 | I24: =H24/$H$31 -> 0.045777476 | J24: =I24*E24/365 -> 0.11864518 | M24: VaR | N24: =Task2!R9*SQRT(Task3!N23) -> 0.28279367
D25: 46715 | E25: 1311 | F25: 475 | G25: =_xlfn.XLOOKUP(E25,'zero-coupon-yields_202405172251'!$B$2:$B$1490,'zero-coupon-yields_202405172251'!$D$2:$D$1490,,1,1)/100 -> 0.138566 | H25: 369.89674 | I25: =H25/$H$31 -> 0.042694875 | J25: =I25*E25/365 -> 0.15335063
D26: 47080 | E26: 1676 | F26: 475 | G26: =_xlfn.XLOOKUP(E26,'zero-coupon-yields_202405172251'!$B$2:$B$1490,'zero-coupon-yields_202405172251'!$D$2:$D$1490,,1,1)/100 -> 0.131253 | H26: 345.1609 | I26: =H26/$H$31 -> 0.039839771 | J26: =I26*E26/365 -> 0.1829355
D27: 47445 | E27: 2041 | F27: 475 | G27: =_xlfn.XLOOKUP(E27,'zero-coupon-yields_202405172251'!$B$2:$B$1490,'zero-coupon-yields_202405172251'!$D$2:$D$1490,,1,1)/100 -> 0.122994 | H27: 322.20977 | I27: =H27/$H$31 -> 0.037190666 | J27: =I27*E27/365 -> 0.20796205 | M27: The value of the portfolio will be 86,065,601.96, if the yields at day 2022.10.17 was used, which means a 13,93% decrease compared to the value calculated in task1.
D28: 47810 | E28: 2406 | F28: 475 | G28: =_xlfn.XLOOKUP(E28,'zero-coupon-yields_202405172251'!$B$2:$B$1490,'zero-coupon-yields_202405172251'!$D$2:$D$1490,,1,1)/100 -> 0.115075 | H28: 300.85967 | I28: =H28/$H$31 -> 0.034726356 | J28: =I28*E28/365 -> 0.22890853 | M28: Daily VaR as calculated in task 2 is about 1,2%. For 553 days it is 28.28% which indicates substantial yield driven changes.
D29: 48175 | E29: 2771 | F29: 475 | G29: =_xlfn.XLOOKUP(E29,'zero-coupon-yields_202405172251'!$B$2:$B$1490,'zero-coupon-yields_202405172251'!$D$2:$D$1490,,1,1)/100 -> 0.108503 | H29: 280.92896 | I29: =H29/$H$31 -> 0.032425879 | J29: =I29*E29/365 -> 0.24617017 | M29: This movement is because of the high inflation in year 2022, it was measured at 14.5% in 2022, compared to the EU average of approximately 9.32%. In addition to the impact of the Russia-Ukraine war on energy prices, the depreciation of the national currency and iefficiencies in the domestic food manfacturing industry have contributed to Hungary recording way higher inflation rates in recent years than the EU average.
D30: 48542 | E30: 3138 | F30: 10475 | G30: =_xlfn.XLOOKUP(E30,'zero-coupon-yields_202405172251'!$B$2:$B$1490,'zero-coupon-yields_202405172251'!$D$2:$D$1490,,1,1)/100 -> 0.103754 | H30: 5782.4031 | I30: =H30/$H$31 -> 0.66742675 | J30: =I30*E30/365 -> 5.7380414
H31: =SUM(H22:H30) -> 8663.7269 | I31: =SUM(I22:I30) -> 1 | J31: =SUM(J22:J30) -> 6.9842459

Sheet Task4
B4: day | C4: year | F4: Mapped cash flow dates (years) | P4: Portfolio | T4: Correlation Matrix
A5: =Task1!D4 -> 2028/A | B5: =Task1!E20 -> 183 | C5: =B5/365 -> 0.50136986 | R5: 1 day
B6: =Task1!E21 -> 548 | C6: =B6/365 -> 1.5013699 | F6: t | G6: r(t) | H6: DF(t) | I6: CF' | J6: PV | K6: w(t) | L6: DUR | M6: w(t)*bond price volatility | T6: t | U6: 0.25 | V6: 0.5 | W6: 1 | X6: 3 | Y6: 5 | Z6: 10
B7: =Task1!E22 -> 913 | C7: =B7/365 -> 2.5013699 | F7: 0.25 | G7: {=_xlfn.XLOOKUP(Task1!$B$1,'Benchmark yields table'!$A$3:$A$599,_xlfn.XLOOKUP(Task4!F7,'Benchmark yields table'!$B$2:$I$2,'Benchmark yields table'!$B$3:$I$599))/100} -> 0.0668 | H7: =1/(1+G7)^F7 -> 0.98396409 | I7: =L45*M44 -> 317503.63 | J7: =H7*I7 -> 312412.17 | K7: =J7/$J$13 -> 0.002968203 | L7: =K7*F7 -> 0.00074205075 | M7: =K7*U15 -> 1.4487395e-06 | Q7: Volatility | R7: {=SQRT(MMULT(TRANSPOSE(M7:M12),MMULT(U7:Z12,M7:M12)))} -> 0.0043072983 | T7: 0.25 | U7: =CORREL(_xlfn.XLOOKUP($T7,'Benchmark yields table'!$J$2:$Q$2,'Benchmark yields table'!$J$20:$Q$599),_xlfn.XLOOKUP(U$6,'Benchmark yields table'!$J$2:$Q$2,'Benchmark yields table'!$J$20:$Q$599)) -> 1 | V7: =CORREL(_xlfn.XLOOKUP($T7,'Benchmark yields table'!$J$2:$Q$2,'Benchmark yields table'!$J$20:$Q$599),_xlfn.XLOOKUP(V$6,'Benchmark yields table'!$J$2:$Q$2,'Benchmark yields table'!$J$20:$Q$599)) -> 0.60501119 | W7: =CORREL(_xlfn.XLOOKUP($T7,'Benchmark yields table'!$J$2:$Q$2,'Benchmark yields table'!$J$20:$Q$599),_xlfn.XLOOKUP(W$6,'Benchmark yields table'!$J$2:$Q$2,'Benchmark yields table'!$J$20:$Q$599)) -> 0.51525983 | X7: =CORREL(_xlfn.XLOOKUP($T7,'Benchmark yields table'!$J$2:$Q$2,'Benchmark yields table'!$J$20:$Q$599),_xlfn.XLOOKUP(X$6,'Benchmark yields table'!$J$2:$Q$2,'Benchmark yields table'!$J$20:$Q$599)) -> 0.38125654 | Y7: =CORREL(_xlfn.XLOOKUP($T7,'Benchmark yields table'!$J$2:$Q$2,'Benchmark yields table'!$J$20:$Q$599),_xlfn.XLOOKUP(Y$6,'Benchmark yields table'!$J$2:$Q$2,'Benchmark yields table'!$J$20:$Q$599)) -> 0.36677534 | Z7: =CORREL(_xlfn.XLOOKUP($T7,'Benchmark yields table'!$J$2:$Q$2,'Benchmark yields table'!$J$20:$Q$599),_xlfn.XLOOKUP(Z$6,'Benchmark yields table'!$J$2:$Q$2,'Benchmark yields table'!$J$20:$Q$599)) -> 0.3658849
B8: =Task1!E23 -> 1278 | C8: =B8/365 -> 3.5013699 | F8: 0.5 | G8: {=_xlfn.XLOOKUP(Task1!$B$1,'Benchmark yields table'!$A$3:$A$599,_xlfn.XLOOKUP(Task4!F8,'Benchmark yields table'!$B$2:$I$2,'Benchmark yields table'!$B$3:$I$599))/100} -> 0.0692 | H8: =1/(1+G8)^F8 -> 0.96709809 | I8: =M23*SUM(L24)+M44*SUM(L47)+M73*SUM(L74) -> 5818081.6 | J8: =H8*I8 -> 5626655.6 | K8: =J8/$J$13 -> 0.053458404 | L8: =K8*F8 -> 0.026729202 | M8: =K8*V15 -> 3.4775461e-05 | Q8: Multiplier for 99% confidence | R8: =NORMSINV(1-R13) -> -2.3263479 | T8: 0.5 | U8: =CORREL(_xlfn.XLOOKUP($T8,'Benchmark yields table'!$J$2:$Q$2,'Benchmark yields table'!$J$20:$Q$599),_xlfn.XLOOKUP(U$6,'Benchmark yields table'!$J$2:$Q$2,'Benchmark yields table'!$J$20:$Q$599)) -> 0.60501119 | V8: =CORREL(_xlfn.XLOOKUP($T8,'Benchmark yields table'!$J$2:$Q$2,'Benchmark yields table'!$J$20:$Q$599),_xlfn.XLOOKUP(V$6,'Benchmark yields table'!$J$2:$Q$2,'Benchmark yields table'!$J$20:$Q$599)) -> 1 | W8: =CORREL(_xlfn.XLOOKUP($T8,'Benchmark yields table'!$J$2:$Q$2,'Benchmark yields table'!$J$20:$Q$599),_xlfn.XLOOKUP(W$6,'Benchmark yields table'!$J$2:$Q$2,'Benchmark yields table'!$J$20:$Q$599)) -> 0.73079441 | X8: =CORREL(_xlfn.XLOOKUP($T8,'Benchmark yields table'!$J$2:$Q$2,'Benchmark yields table'!$J$20:$Q$599),_xlfn.XLOOKUP(X$6,'Benchmark yields table'!$J$2:$Q$2,'Benchmark yields table'!$J$20:$Q$599)) -> 0.53728582 | Y8: =CORREL(_xlfn.XLOOKUP($T8,'Benchmark yields table'!$J$2:$Q$2,'Benchmark yields table'!$J$20:$Q$599),_xlfn.XLOOKUP(Y$6,'Benchmark yields table'!$J$2:$Q$2,'Benchmark yields table'!$J$20:$Q$599)) -> 0.5331356 | Z8: =CORREL(_xlfn.XLOOKUP($T8,'Benchmark yields table'!$J$2:$Q$2,'Benchmark yields table'!$J$20:$Q$599),_xlfn.XLOOKUP(Z$6,'Benchmark yields table'!$J$2:$Q$2,'Benchmark yields table'!$J$20:$Q$599)) -> 0.55077977
B9: =Task1!E24 -> 1644 | C9: =B9/365 -> 4.5041096 | F9: 1 | G9: {=_xlfn.XLOOKUP(Task1!$B$1,'Benchmark yields table'!$A$3:$A$599,_xlfn.XLOOKUP(Task4!F9,'Benchmark yields table'!$B$2:$I$2,'Benchmark yields table'!$B$3:$I$599))/100} -> 0.0688 | H9: =1/(1+G9)^F9 -> 0.93562874 | I9: =M23*SUM(L26,L28,L32)+M44*SUM(L49,L53)+M73*SUM(L76,L78,L82) -> 5575412.9 | J9: =H9*I9 -> 5216516.6 | K9: =J9/$J$13 -> 0.049561707 | L9: =K9*F9 -> 0.049561707 | M9: =K9*W15 -> 5.9771649e-05 | Q9: VaR (1 day, 99%) | R9: =-R7*R8 -> 0.010020274 | T9: 1 | U9: =CORREL(_xlfn.XLOOKUP($T9,'Benchmark yields table'!$J$2:$Q$2,'Benchmark yields table'!$J$20:$Q$599),_xlfn.XLOOKUP(U$6,'Benchmark yields table'!$J$2:$Q$2,'Benchmark yields table'!$J$20:$Q$599)) -> 0.51525983 | V9: =CORREL(_xlfn.XLOOKUP($T9,'Benchmark yields table'!$J$2:$Q$2,'Benchmark yields table'!$J$20:$Q$599),_xlfn.XLOOKUP(V$6,'Benchmark yields table'!$J$2:$Q$2,'Benchmark yields table'!$J$20:$Q$599)) -> 0.73079441 | W9: =CORREL(_xlfn.XLOOKUP($T9,'Benchmark yields table'!$J$2:$Q$2,'Benchmark yields table'!$J$20:$Q$599),_xlfn.XLOOKUP(W$6,'Benchmark yields table'!$J$2:$Q$2,'Benchmark yields table'!$J$20:$Q$599)) -> 1 | X9: =CORREL(_xlfn.XLOOKUP($T9,'Benchmark yields table'!$J$2:$Q$2,'Benchmark yields table'!$J$20:$Q$599),_xlfn.XLOOKUP(X$6,'Benchmark yields table'!$J$2:$Q$2,'Benchmark yields table'!$J$20:$Q$599)) -> 0.66514828 | Y9: =CORREL(_xlfn.XLOOKUP($T9,'Benchmark yields table'!$J$2:$Q$2,'Benchmark yields table'!$J$20:$Q$599),_xlfn.XLOOKUP(Y$6,'Benchmark yields table'!$J$2:$Q$2,'Benchmark yields table'!$J$20:$Q$599)) -> 0.66363795 | Z9: =CORREL(_xlfn.XLOOKUP($T9,'Benchmark yields table'!$J$2:$Q$2,'Benchmark yields table'!$J$20:$Q$599),_xlfn.XLOOKUP(Z$6,'Benchmark yields table'!$J$2:$Q$2,'Benchmark yields table'!$J$20:$Q$599)) -> 0.67559884
A10: =Task1!E4 -> 2030/A | B10: =Task1!E27 -> 121 | C10: =B10/365 -> 0.33150685 | F10: 3 | G10: {=_xlfn.XLOOKUP(Task1!$B$1,'Benchmark yields table'!$A$3:$A$599,_xlfn.XLOOKUP(Task4!F10,'Benchmark yields table'!$B$2:$I$2,'Benchmark yields table'!$B$3:$I$599))/100} -> 0.0725 | H10: =1/(1+G10)^F10 -> 0.8106028 | I10: =M23*SUM(L30,L34,L36,L40)+M44*SUM(L51,L55,L57,L61)+M73*SUM(L80,L84,L86,L90) -> 31106268 | J10: =H10*I10 -> 25214828 | K10: =J10/$J$13 -> 0.23956406 | L10: =K10*F10 -> 0.71869218 | M10: =K10*X15 -> 0.00067897989 | Q10: VaR (HUF, 1 day, 99%) | R10: =R9*Task1!K6 -> 1001982.5 | T10: 3 | U10: =CORREL(_xlfn.XLOOKUP($T10,'Benchmark yields table'!$J$2:$Q$2,'Benchmark yields table'!$J$20:$Q$599),_xlfn.XLOOKUP(U$6,'Benchmark yields table'!$J$2:$Q$2,'Benchmark yields table'!$J$20:$Q$599)) -> 0.38125654 | V10: =CORREL(_xlfn.XLOOKUP($T10,'Benchmark yields table'!$J$2:$Q$2,'Benchmark yields table'!$J$20:$Q$599),_xlfn.XLOOKUP(V$6,'Benchmark yields table'!$J$2:$Q$2,'Benchmark yields table'!$J$20:$Q$599)) -> 0.53728582 | W10: =CORREL(_xlfn.XLOOKUP($T10,'Benchmark yields table'!$J$2:$Q$2,'Benchmark yields table'!$J$20:$Q$599),_xlfn.XLOOKUP(W$6,'Benchmark yields table'!$J$2:$Q$2,'Benchmark yields table'!$J$20:$Q$599)) -> 0.66514828 | X10: =CORREL(_xlfn.XLOOKUP($T10,'Benchmark yields table'!$J$2:$Q$2,'Benchmark yields table'!$J$20:$Q$599),_xlfn.XLOOKUP(X$6,'Benchmark yields table'!$J$2:$Q$2,'Benchmark yields table'!$J$20:$Q$599)) -> 1 | Y10: =CORREL(_xlfn.XLOOKUP($T10,'Benchmark yields table'!$J$2:$Q$2,'Benchmark yields table'!$J$20:$Q$599),_xlfn.XLOOKUP(Y$6,'Benchmark yields table'!$J$2:$Q$2,'Benchmark yields table'!$J$20:$Q$599)) -> 0.95541409 | Z10: =CORREL(_xlfn.XLOOKUP($T10,'Benchmark yields table'!$J$2:$Q$2,'Benchmark yields table'!$J$20:$Q$599),_xlfn.XLOOKUP(Z$6,'Benchmark yields table'!$J$2:$Q$2,'Benchmark yields table'!$J$20:$Q$599)) -> 0.91480363
B11: =Task1!E28 -> 486 | C11: =B11/365 -> 1.3315068 | F11: 5 | G11: {=_xlfn.XLOOKUP(Task1!$B$1,'Benchmark yields table'!$A$3:$A$599,_xlfn.XLOOKUP(Task4!F11,'Benchmark yields table'!$B$2:$I$2,'Benchmark yields table'!$B$3:$I$599))/100} -> 0.0721 | H11: =1/(1+G11)^F11 -> 0.70603059 | I11: =M23*SUM(L38,L42)+M44*SUM(L59,L63,L65,L69)+M73*SUM(L88,L92,L94,L98,L102,L106) -> 88758073 | J11: =H11*I11 -> 62665915 | K11: =J11/$J$13 -> 0.59538385 | L11: =K11*F11 -> 2.9769192 | M11: =K11*Y15 -> 0.0030072028 | Q11: VaR (10 days, 99%) | R11: =R9*SQRT(10) -> 0.031686889 | T11: 5 | U11: =CORREL(_xlfn.XLOOKUP($T11,'Benchmark yields table'!$J$2:$Q$2,'Benchmark yields table'!$J$20:$Q$599),_xlfn.XLOOKUP(U$6,'Benchmark yields table'!$J$2:$Q$2,'Benchmark yields table'!$J$20:$Q$599)) -> 0.36677534 | V11: =CORREL(_xlfn.XLOOKUP($T11,'Benchmark yields table'!$J$2:$Q$2,'Benchmark yields table'!$J$20:$Q$599),_xlfn.XLOOKUP(V$6,'Benchmark yields table'!$J$2:$Q$2,'Benchmark yields table'!$J$20:$Q$599)) -> 0.5331356 | W11: =CORREL(_xlfn.XLOOKUP($T11,'Benchmark yields table'!$J$2:$Q$2,'Benchmark yields table'!$J$20:$Q$599),_xlfn.XLOOKUP(W$6,'Benchmark yields table'!$J$2:$Q$2,'Benchmark yields table'!$J$20:$Q$599)) -> 0.66363795 | X11: =CORREL(_xlfn.XLOOKUP($T11,'Benchmark yields table'!$J$2:$Q$2,'Benchmark yields table'!$J$20:$Q$599),_xlfn.XLOOKUP(X$6,'Benchmark yields table'!$J$2:$Q$2,'Benchmark yields table'!$J$20:$Q$599)) -> 0.95541409 | Y11: =CORREL(_xlfn.XLOOKUP($T11,'Benchmark yields table'!$J$2:$Q$2,'Benchmark yields table'!$J$20:$Q$599),_xlfn.XLOOKUP(Y$6,'Benchmark yields table'!$J$2:$Q$2,'Benchmark yields table'!$J$20:$Q$599)) -> 1 | Z11: =CORREL(_xlfn.XLOOKUP($T11,'Benchmark yields table'!$J$2:$Q$2,'Benchmark yields table'!$J$20:$Q$599),_xlfn.XLOOKUP(Z$6,'Benchmark yields table'!$J$2:$Q$2,'Benchmark yields table'!$J$20:$Q$599)) -> 0.96353862
B12: =Task1!E29 -> 851 | C12: =B12/365 -> 2.3315068 | F12: 10 | G12: {=_xlfn.XLOOKUP(Task1!$B$1,'Benchmark yields table'!$A$3:$A$599,_xlfn.XLOOKUP(Task4!F12,'Benchmark yields table'!$B$2:$I$2,'Benchmark yields table'!$B$3:$I$599))/100} -> 0.0712 | H12: =1/(1+G12)^F12 -> 0.50268319 | I12: =M44*SUM(L67,L71)+M73*SUM(L96,L104,L100,L108) -> 12366911 | J12: =H12*I12 -> 6216638.1 | K12: =J12/$J$13 -> 0.059063781 | L12: =K12*F12 -> 0.59063781 | M12: =K12*Z15 -> 0.00060610807 | T12: 10 | U12: =CORREL(_xlfn.XLOOKUP($T12,'Benchmark yields table'!$J$2:$Q$2,'Benchmark yields table'!$J$20:$Q$599),_xlfn.XLOOKUP(U$6,'Benchmark yields table'!$J$2:$Q$2,'Benchmark yields table'!$J$20:$Q$599)) -> 0.3658849 | V12: =CORREL(_xlfn.XLOOKUP($T12,'Benchmark yields table'!$J$2:$Q$2,'Benchmark yields table'!$J$20:$Q$599),_xlfn.XLOOKUP(V$6,'Benchmark yields table'!$J$2:$Q$2,'Benchmark yields table'!$J$20:$Q$599)) -> 0.55077977 | W12: =CORREL(_xlfn.XLOOKUP($T12,'Benchmark yields table'!$J$2:$Q$2,'Benchmark yields table'!$J$20:$Q$599),_xlfn.XLOOKUP(W$6,'Benchmark yields table'!$J$2:$Q$2,'Benchmark yields table'!$J$20:$Q$599)) -> 0.67559884 | X12: =CORREL(_xlfn.XLOOKUP($T12,'Benchmark yields table'!$J$2:$Q$2,'Benchmark yields table'!$J$20:$Q$599),_xlfn.XLOOKUP(X$6,'Benchmark yields table'!$J$2:$Q$2,'Benchmark yields table'!$J$20:$Q$599)) -> 0.91480363 | Y12: =CORREL(_xlfn.XLOOKUP($T12,'Benchmark yields table'!$J$2:$Q$2,'Benchmark yields table'!$J$20:$Q$599),_xlfn.XLOOKUP(Y$6,'Benchmark yields table'!$J$2:$Q$2,'Benchmark yields table'!$J$20:$Q$599)) -> 0.96353862 | Z12: =CORREL(_xlfn.XLOOKUP($T12,'Benchmark yields table'!$J$2:$Q$2,'Benchmark yields table'!$J$20:$Q$599),_xlfn.XLOOKUP(Z$6,'Benchmark yields table'!$J$2:$Q$2,'Benchmark yields table'!$J$20:$Q$599)) -> 1
B13: =Task1!E30 -> 1216 | C13: =B13/365 -> 3.3315068 | J13: =SUM(J7:J12) -> 1.0525297e+08 | K13: =J13/$J$13 -> 1 | L13: =SUM(L7:L12) -> 4.3632822 | Q13: Significance | R13: 0.99
B14: =Task1!E31 -> 1581 | C14: =B14/365 -> 4.3315068 | T14: "bond price volatilities" for Bechmark yield curve points
B15: =Task1!E32 -> 1946 | C15: =B15/365 -> 5.3315068 | U15: {=_xlfn.XLOOKUP(Task1!$B$1,'Benchmark yields table'!$A$3:$A$20,_xlfn.XLOOKUP(U6,'Benchmark yields table'!$BF$2:$BM$2,'Benchmark yields table'!$BF$3:$BM$20))} -> 0.0004880864 | V15: {=_xlfn.XLOOKUP(Task1!$B$1,'Benchmark yields table'!$A$3:$A$20,_xlfn.XLOOKUP(V6,'Benchmark yields table'!$BF$2:$BM$2,'Benchmark yields table'!$BF$3:$BM$20))} -> 0.00065051439 | W15: {=_xlfn.XLOOKUP(Task1!$B$1,'Benchmark yields table'!$A$3:$A$20,_xlfn.XLOOKUP(W6,'Benchmark yields table'!$BF$2:$BM$2,'Benchmark yields table'!$BF$3:$BM$20))} -> 0.0012060047 | X15: {=_xlfn.XLOOKUP(Task1!$B$1,'Benchmark yields table'!$A$3:$A$20,_xlfn.XLOOKUP(X6,'Benchmark yields table'!$BF$2:$BM$2,'Benchmark yields table'!$BF$3:$BM$20))} -> 0.002834231 | Y15: {=_xlfn.XLOOKUP(Task1!$B$1,'Benchmark yields table'!$A$3:$A$20,_xlfn.XLOOKUP(Y6,'Benchmark yields table'!$BF$2:$BM$2,'Benchmark yields table'!$BF$3:$BM$20))} -> 0.0050508639 | Z15: {=_xlfn.XLOOKUP(Task1!$B$1,'Benchmark yields table'!$A$3:$A$20,_xlfn.XLOOKUP(Z6,'Benchmark yields table'!$BF$2:$BM$2,'Benchmark yields table'!$BF$3:$BM$20))} -> 0.010261925
B16: =Task1!E33 -> 2312 | C16: =B16/365 -> 6.3342466
A17: =Task1!F4 -> 2032/A | B17: =Task1!E36 -> 216 | C17: =B17/365 -> 0.59178082
B18: =Task1!E37 -> 581 | C18: =B18/365 -> 1.5917808
B19: =Task1!E38 -> 946 | C19: =B19/365 -> 2.5917808
B20: =Task1!E39 -> 1311 | C20: =B20/365 -> 3.5917808 | F20: Cash Flow Mapping
B21: =Task1!E40 -> 1676 | C21: =B21/365 -> 4.5917808 | G21: t | H21: r(t) | I21: stddev(t) | J21: DF(t) | K21: CF | L21: CF' | M21: number of securities
B22: =Task1!E41 -> 2041 | C22: =B22/365 -> 5.5917808
B23: =Task1!E42 -> 2406 | C23: =B23/365 -> 6.5917808 | F23: =Task1!D4 -> 2028/A | M23: 7590
B24: =Task1!E43 -> 2771 | C24: =B24/365 -> 7.5917808 | F24: =1-((G25-G24)/(G26-G24)) -> 0.99726027 | G24: 0.5 | H24: {=_xlfn.XLOOKUP(Task1!$B$1,'Benchmark yields table'!$A$3:$A$599,_xlfn.XLOOKUP(Task4!G24,'Benchmark yields table'!$B$2:$I$2,'Benchmark yields table'!$B$3:$I$599))/100} -> 0.0692 | I24: {=_xlfn.XLOOKUP(Task1!$B$1,'Benchmark yields table'!$A$3:$A$599,_xlfn.XLOOKUP(Task4!G24,'Benchmark yields table'!$BF$2:$BM$2,'Benchmark yields table'!$BF$3:$BM$599))} -> 0.00065051439 | J24: =1/(1+H24)^G24 -> 0.96709809 | L24: =K25*M25 -> 670.61375 | M24: alfa | N24: PV= | P24: =K25*J25 -> 652.73171 | Q24: Korrel | R24: Vol | S24: =I25 -> 0.00065203628 | T24: a | V24: =I24^2+I26^2-2*Q25*I24*I26 -> 7.3096559e-07 | W24: =(-V25+SQRT(V25^2-4*V24*V26))/(2*V24) -> 1.4173419
B25: =Task1!E44 -> 3138 | C25: =B25/365 -> 8.5972603 | G25: =C5 -> 0.50136986 | H25: =F24*H24+(1-F24)*H26 -> 0.069198904 | I25: =F24*I24+(1-F24)*I26 -> 0.00065203628 | J25: =1/(1+H25)^G25 -> 0.96700995 | K25: =Task1!F20 -> 675 | M25: =MIN(W24:W25) -> 0.99350186 | N25: PV'= | P25: =L24*J24+L26*J26 -> 652.65318 | Q25: {=_xlfn.XLOOKUP(G24,$T$7:$T$12,_xlfn.XLOOKUP(G26,$U$6:$Z$6,$U$7:$Z$12))} -> 0.73079441 | R25: Vol' | S25: =SQRT((M25*I24)^2+((1-M25)*I26)^2+2*M25*(1-M25)*Q25*I24*I26) -> 0.00065203628 | T25: b | V25: =2*Q25*I24*I26-2*I26^2 -> -1.7622438e-06 | W25: =(-V25-SQRT(V25^2-4*V24*V26))/(2*V24) -> 0.99350186
G26: 1 | H26: {=_xlfn.XLOOKUP(Task1!$B$1,'Benchmark yields table'!$A$3:$A$599,_xlfn.XLOOKUP(Task4!G26,'Benchmark yields table'!$B$2:$I$2,'Benchmark yields table'!$B$3:$I$599))/100} -> 0.0688 | I26: {=_xlfn.XLOOKUP(Task1!$B$1,'Benchmark yields table'!$A$3:$A$599,_xlfn.XLOOKUP(Task4!G26,'Benchmark yields table'!$BF$2:$BM$2,'Benchmark yields table'!$BF$3:$BM$599))} -> 0.0012060047 | J26: =1/(1+H26)^G26 -> 0.93562874 | L26: =(1-M25)*K25 -> 4.3862466 | N26: Pvdiff | P26: =ABS(P24-P25) -> 0.078536621 | R26: Voldiff | S26: =ABS(S24-S25) -> 0 | T26: c | V26: =I26^2-I25^2 -> 1.0292959e-06 | Z26: Target VaR | AB26: =Task2!R9/1.2 -> 0.010021342
F28: =1-((G29-G28)/(G30-G28)) -> 0.74931507 | G28: 1 | H28: {=_xlfn.XLOOKUP(Task1!$B$1,'Benchmark yields table'!$A$3:$A$599,_xlfn.XLOOKUP(G28,'Benchmark yields table'!$B$2:$I$2,'Benchmark yields table'!$B$3:$I$599))/100} -> 0.0688 | I28: {=_xlfn.XLOOKUP(Task1!$B$1,'Benchmark yields table'!$A$3:$A$599,_xlfn.XLOOKUP(G28,'Benchmark yields table'!$BF$2:$BM$2,'Benchmark yields table'!$BF$3:$BM$599))} -> 0.0012060047 | J28: =1/(1+H28)^G28 -> 0.93562874 | L28: =K29*M29 -> 442.40156 | M28: alfa | N28: PV= | P28: =K29*J29 -> 610.03382 | Q28: Korrel | R28: Vol | S28: =I29 -> 0.0016141765 | T28: a | V28: =I28^2+I30^2-2*Q29*I28*I30 -> 4.9402317e-06 | W28: =(-V29+SQRT(V29^2-4*V28*V30))/(2*V28) -> 1.6761915
G29: =C6 -> 1.5013699 | H29: =H28*F28+(1-F28)*H30 -> 0.069727534 | I29: =I28*F28+(1-F28)*I30 -> 0.0016141765 | J29: =1/(1+H29)^G29 -> 0.9037538 | K29: =Task1!F21 -> 675 | M29: =MIN(W28:W29) -> 0.65540972 | N29: PV'= | P29: =L28*J28+L30*J30 -> 602.46856 | Q29: {=_xlfn.XLOOKUP(G28,$T$7:$T$12,_xlfn.XLOOKUP(G30,$U$6:$Z$6,$U$7:$Z$12))} -> 0.66514828 | R29: Vol' | S29: =SQRT((M29*I28)^2+((1-M29)*I30)^2+2*M29*(1-M29)*Q29*I28*I30) -> 0.0016141765 | T29: b | V29: =2*Q29*I28*I30-2*I30^2 -> -1.151865e-05 | W29: =(-V29-SQRT(V29^2-4*V28*V30))/(2*V28) -> 0.65540972 | Z29: Portfolio | AA29: Before | AB29: Adjust Var | AC29: Movement | AD29: Transaction
G30: 3 | H30: {=_xlfn.XLOOKUP(Task1!$B$1,'Benchmark yields table'!$A$3:$A$599,_xlfn.XLOOKUP(G30,'Benchmark yields table'!$B$2:$I$2,'Benchmark yields table'!$B$3:$I$599))/100} -> 0.0725 | I30: {=_xlfn.XLOOKUP(Task1!$B$1,'Benchmark yields table'!$A$3:$A$599,_xlfn.XLOOKUP(G30,'Benchmark yields table'!$BF$2:$BM$2,'Benchmark yields table'!$BF$3:$BM$599))} -> 0.002834231 | J30: =1/(1+H30)^G30 -> 0.8106028 | L30: =(1-M29)*K29 -> 232.59844 | N30: Pvdiff | P30: =ABS(P28-P29) -> 7.5652561 | R30: Voldiff | S30: =ABS(S28-S29) -> 0 | T30: c | V30: =I30^2-I29^2 -> 5.4272999e-06 | Z30: =Task1!D4 -> 2028/A | AA30: =Task1!D13 -> 4152 | AB30: =M23 -> 7590 | AC30: =AB30-AA30 -> 3438 | AD30: =IF(AC30>=1,"buy","sell") -> buy
Z31: =Task1!E4 -> 2030/A | AA31: =Task1!E13 -> 3323 | AB31: =M44 -> 2940 | AC31: =AB31-AA31 -> -383 | AD31: =IF(AC31>=1,"buy","sell") -> sell
F32: =1-((G33-G32)/(G34-G32)) -> 0.24931507 | G32: 1 | H32: {=_xlfn.XLOOKUP(Task1!$B$1,'Benchmark yields table'!$A$3:$A$599,_xlfn.XLOOKUP(G32,'Benchmark yields table'!$B$2:$I$2,'Benchmark yields table'!$B$3:$I$599))/100} -> 0.0688 | I32: {=_xlfn.XLOOKUP(Task1!$B$1,'Benchmark yields table'!$A$3:$A$599,_xlfn.XLOOKUP(G32,'Benchmark yields table'!$BF$2:$BM$2,'Benchmark yields table'!$BF$3:$BM$599))} -> 0.0012060047 | J32: =1/(1+H32)^G32 -> 0.93562874 | L32: =K33*M33 -> 137.13648 | M32: alfa | N32: PV= | P32: =K33*J33 -> 567.81079 | Q32: Korrel | R32: Vol | S32: =I33 -> 0.0024282897 | T32: a | V32: =I32^2+I34^2-2*Q33*I32*I34 -> 4.9402317e-06 | W32: =(-V33+SQRT(V33^2-4*V32*V34))/(2*V32) -> 2.128436 | Z32: =Task1!F4 -> 2032/A | AA32: =Task1!F13 -> 3548 | AB32: =M73 -> 480 | AC32: =AB32-AA32 -> -3068 | AD32: =IF(AC32>=1,"buy","sell") -> sell
