Workbook

Sheet Individual purchase
C5: 2025 | D5: =+C5+1 -> 2026 | E5: =+D5+1 -> 2027 | F5: =+E5+1 -> 2028 | G5: =+F5+1 -> 2029 | H5: =+G5+1 -> 2030
B6: IC boy | C6: 12000
B7: dIC | C7: 1350 | D7: 1150 | E7: 1100
B8: ROIC=Noplat/IC boy | C8: 0.15
B9: RONIC | D9: 0.17 | E9: 0.165 | F9: 0.16 | G9: 0.15 | H9: 0.15
B10: K=dIC/Noplat | F10: 0.33 | G10: 0.33 | H10: 0.33
B11: Debt/IC boy | C11: 0 | D11: 0.05 | E11: 0.1 | F11: 0.15 | G11: 0.2 | H11: 0.2
B12: rD | D12: 0.07 | E12: 0.07 | F12: 0.07 | G12: 0.07 | H12: 0.07
B13: rA | C13: 0.12 | D13: 0.12 | E13: 0.12 | F13: 0.12 | G13: 0.12 | H13: 0.12
B14: t | C14: 0.2 | D14: 0.2 | E14: 0.2 | F14: 0.2 | G14: 0.2 | H14: 0.2
B15: Moving costs/IC eoy | H15: 0.1
B19: Balance sheet | H19: boy | I19: eoy 2030 | J19: boy 2031
B20: =+B6 -> IC boy | C20: =+C6 -> 12000 | D20: =+C20+C43 -> 13350 | E20: =+D20+D43 -> 14500 | F20: =+E20+E43 -> 15600 | G20: =+F20+F43 -> 16390.432 | H20: =+G20+G43 -> 17219.991 | I20: =+H20+H42*H10 -> 18090.613 | J20: 0
B21: BV D boy | C21: =+C20*C11 -> 0 | D21: =+D20*D11 -> 667.5 | E21: =+E20*E11 -> 1450 | F21: =+F20*F11 -> 2340 | G21: =+G20*G11 -> 3278.0865 | H21: =+H20*H11 -> 3443.9983 | I21: 0 | J21: 0
B22: BV E boy | C22: =+C20-C21 -> 12000 | D22: =+D20-D21 -> 12682.5 | E22: =+E20-E21 -> 13050 | F22: =+F20-F21 -> 13260 | G22: =+G20-G21 -> 13112.346 | H22: =+H20-H21 -> 13775.993 | I22: =+I20-I21 -> 18090.613 | J22: 0
B24: effective tax rate | C24: 0.2 | D24: 0.2 | E24: 0.2 | F24: 0.2 | G24: 0.2 | H24: 0.2
B25: effective tax calculated | C25: =+C34/C33 -> 0.2 | D25: =+D34/D33 -> 0.2 | E25: =+E34/E33 -> 0.2 | F25: =+F34/F33 -> 0.2 | G25: =+G34/G33 -> 0.2 | H25: =+H34/H33 -> 0.2
B27: Sales
B28: Other Income | I28: =+I20*0.9 -> 16281.552
B29: Expenses
B30: Other expense | I30: =+I20 -> 18090.613
B31: EBIT | C31: =+C42/(1-C24) -> 2250 | D31: =+D42/(1-D24) -> 2536.875 | E31: =+E42/(1-E24) -> 2774.0625 | F31: =+F42/(1-F24) -> 2994.0625 | G31: =+G42/(1-G24) -> 3142.2686 | H31: =+H42/(1-H24) -> 3297.8109 | I31: =+I28-I30 -> -1809.0613
B32: Interest paid | C32: =+C21*C12 -> 0 | D32: =+D21*D12 -> 46.725 | E32: =+E21*E12 -> 101.5 | F32: =+F21*F12 -> 163.8 | G32: =+G21*G12 -> 229.46606 | H32: =+H21*H12 -> 241.07988
B33: Profit before tax | C33: =+C31-C32 -> 2250 | D33: =+D31-D32 -> 2490.15 | E33: =+E31-E32 -> 2672.5625 | F33: =+F31-F32 -> 2830.2625 | G33: =+G31-G32 -> 2912.8025 | H33: =+H31-H32+I31 -> 1247.6697
B34: Tax | C34: =+IF(C33<0,0,C33*C14) -> 450 | D34: =+IF(D33<0,0,D33*D14) -> 498.03 | E34: =+IF(E33<0,0,E33*E14) -> 534.5125 | F34: =+IF(F33<0,0,F33*F14) -> 566.0525 | G34: =+IF(G33<0,0,G33*G14) -> 582.56051 | H34: =+IF(H33<0,0,H33*H14) -> 249.53393
B35: Profit after tax | C35: =+C33-C34 -> 1800 | D35: =+D33-D34 -> 1992.12 | E35: =+E33-E34 -> 2138.05 | F35: =+F33-F34 -> 2264.21 | G35: =+G33-G34 -> 2330.242 | H35: =+H33-H34 -> 998.13573
B36: Dividend | C36: =+C35-C37 -> 1117.5 | D36: =+D35-D37 -> 1624.62 | E36: =+E35-E37 -> 1928.05 | F36: =+F35-F37 -> 2264.21 | G36: =+G35-G37 -> 1666.5949 | H36: =+H35-H37 -> 998.13573
B37: Retained earnings | C37: =+IF(C35<0,C35,MAX(0,MIN(C39,C35))) -> 682.5 | D37: =+IF(D35<0,D35,MAX(0,MIN(D39,D35))) -> 367.5 | E37: =+IF(E35<0,E35,MAX(0,MIN(E39,E35))) -> 210 | F37: =+IF(F35<0,F35,MAX(0,MIN(F39,F35))) -> 0 | G37: =+IF(G35<0,G35,MAX(0,MIN(G39,G35))) -> 663.64713 | H37: =+IF(H35<0,H35,MAX(0,MIN(H39,H35))) -> 0
B39: dEquity needed | C39: =+D22-C22 -> 682.5 | D39: =+E22-D22 -> 367.5 | E39: =+F22-E22 -> 210 | F39: =+G22-F22 -> -147.654 | G39: =+H22-G22 -> 663.64713 | H39: =+J22-H22 -> -13775.993
B40: Share issue/buyback | C40: =+C39-C37 -> 0 | D40: =+D39-D37 -> 0 | E40: =+E39-E37 -> 0 | F40: =+F39-F37 -> -147.654 | G40: =+G39-G37 -> 0 | H40: =+H39-H37 -> -13775.993
B42: Noplat=EBIT*(1-t) | C42: =+C20*C8 -> 1800 | D42: =+C42+C43*D9 -> 2029.5 | E42: =+D42+D43*E9 -> 2219.25 | F42: =+E42+E43*F9 -> 2395.25 | G42: =+F42+F43*G9 -> 2513.8149 | H42: =+G42+G43*H9 -> 2638.2487 | I42: =+I31*(1-H24) -> -1447.2491
B43: dIC | C43: =+C7 -> 1350 | D43: =+D7 -> 1150 | E43: =+E7 -> 1100 | F43: =+F42*F10 -> 790.4325 | G43: =+G42*G10 -> 829.55891 | H43: =+J20-H20 -> -17219.991
B44: FCFF | C44: =+C42-C43 -> 450 | D44: =+D42-D43 -> 879.5 | E44: =+E42-E43 -> 1119.25 | F44: =+F42-F43 -> 1604.8175 | G44: =+G42-G43 -> 1684.256 | H44: =+H42-H43+I42 -> 18410.991
B45: =+B32 -> Interest paid | C45: =+C32 -> 0 | D45: =+D32 -> 46.725 | E45: =+E32 -> 101.5 | F45: =+F32 -> 163.8 | G45: =+G32 -> 229.46606 | H45: =+H32 -> 241.07988
B46: Tax shield | C46: =+C45*C24 -> 0 | D46: =+D45*D24 -> 9.345 | E46: =+E45*E24 -> 20.3 | F46: =+F45*F24 -> 32.76 | G46: =+G45*G24 -> 45.893211 | H46: =+H45*H24 -> 48.215976
B47: dDebt | C47: =+D21-C21 -> 667.5 | D47: =+E21-D21 -> 782.5 | E47: =+F21-E21 -> 890 | F47: =+G21-F21 -> 938.0865 | G47: =+H21-G21 -> 165.91178 | H47: =+J21-H21 -> -3443.9983
B48: FCFE | C48: =+C44-C45+C46+C47 -> 1117.5 | D48: =+D44-D45+D46+D47 -> 1624.62 | E48: =+E44-E45+E46+E47 -> 1928.05 | F48: =+F44-F45+F46+F47 -> 2411.864 | G48: =+G44-G45+G46+G47 -> 1666.5949 | H48: =+H44-H45+H46+H47 -> 14774.129
B49: =+B36 -> Dividend | C49: =+C36 -> 1117.5 | D49: =+D36 -> 1624.62 | E49: =+E36 -> 1928.05 | F49: =+F36 -> 2264.21 | G49: =+G36 -> 1666.5949 | H49: =+H36 -> 998.13573
B50: dEquity w/o Retained earnings | C50: =+D22-C22-C37 -> 0 | D50: =+E22-D22-D37 -> 0 | E50: =+F22-E22-E37 -> 0 | F50: =+G22-F22-F37 -> -147.654 | G50: =+H22-G22-G37 -> 0 | H50: =+J22-H22-H37 -> -13775.993
B51: dNon-operative wealth | C51: =+C48-C49+C50 -> 0 | D51: =+D48-D49+D50 -> -2.2737368e-13 | E51: =+E48-E49+E50 -> -2.2737368e-13 | F51: =+F48-F49+F50 -> -4.5474735e-13 | G51: =+G48-G49+G50 -> 4.5474735e-13 | H51: =+H48-H49+H50 -> 0
...

Sheet Corporate purchase
C5: 2025 | D5: =+C5+1 -> 2026 | E5: =+D5+1 -> 2027 | F5: =+E5+1 -> 2028 | G5: =+F5+1 -> 2029 | H5: =+G5+1 -> 2030
B6: IC boy | C6: 12000
B7: dIC | C7: 1350 | D7: 1150 | E7: 1100
B8: ROIC=Noplat/IC boy | C8: 0.15
B9: RONIC | D9: 0.17 | E9: 0.165 | F9: 0.16 | G9: 0.15 | H9: 0.15
B10: K=dIC/Noplat | F10: 0.33 | G10: 0.33 | H10: 0.33
B11: Debt/IC boy | C11: 0 | D11: 0.05 | E11: 0.1 | F11: 0.15 | G11: 0.2 | H11: 0.2
B12: rD | D12: 0.07 | E12: 0.07 | F12: 0.07 | G12: 0.07 | H12: 0.07
B13: rA | C13: 0.12 | D13: 0.12 | E13: 0.12 | F13: 0.12 | G13: 0.12 | H13: 0.12
B14: t | C14: 0.2 | D14: 0.2 | E14: 0.2 | F14: 0.2 | G14: 0.2 | H14: 0.2
B15: Moving costs/IC eoy | H15: 0.1
B19: Balance sheet | H19: boy | I19: eoy 2030 | J19: boy 2031
B20: Rental right | C20: 1504.8469 | D20: =+C20-$C$20/6 -> 1254.0391 | E20: =+D20-$C$20/6 -> 1003.2313 | F20: =+E20-$C$20/6 -> 752.42346 | G20: =+F20-$C$20/6 -> 501.61564 | H20: =+G20-$C$20/6 -> 250.80782 | I20: =+H20-$C$20/6 -> 0 | J20: 0
B21: =+B6 -> IC boy | C21: =+C6 -> 12000 | D21: =+C21+C45 -> 13350 | E21: =+D21+D45 -> 14500 | F21: =+E21+E45 -> 15600 | G21: =+F21+F45 -> 16390.432 | H21: =+G21+G45 -> 17219.991 | I21: =+H21+H44*H10 -> 18024.4 | J21: 0
B22: BV D boy | C22: =+C21*C11 -> 0 | D22: =+D21*D11 -> 667.5 | E22: =+E21*E11 -> 1450 | F22: =+F21*F11 -> 2340 | G22: =+G21*G11 -> 3278.0865 | H22: =+H21*H11 -> 3443.9983 | I22: 0 | J22: 0
B23: BV E boy | C23: =+C21-C22+C20 -> 13504.847 | D23: =+D21-D22+D20 -> 13936.539 | E23: =+E21-E22+E20 -> 14053.231 | F23: =+F21-F22+F20 -> 14012.423 | G23: =+G21-G22+G20 -> 13613.962 | H23: =+H21-H22+H20 -> 14026.801 | I23: =+I21-I22+I20 -> 18024.4 | J23: =+J21-J22+J20 -> 0
B25: effective tax rate | C25: 0.2 | D25: 0.2 | E25: 0.2 | F25: 0.2 | G25: 0.2 | H25: 0.2
B26: effective tax calculated | C26: =+C36/C35 -> 0.2 | D26: =+D36/D35 -> 0.2 | E26: =+E36/E35 -> 0.2 | F26: =+F36/F35 -> 0.2 | G26: =+G36/G35 -> 0.2 | H26: =+H36/H35 -> 0.2
B28: Sales
B29: Other Income | I29: =+I21*0.9 -> 16221.96
B30: Expenses
B31: Other expense | I31: =+I21 -> 18024.4
B32: D&A rental right | C32: =+$C$20/6 -> 250.80782 | D32: =+$C$20/6 -> 250.80782 | E32: =+$C$20/6 -> 250.80782 | F32: =+$C$20/6 -> 250.80782 | G32: =+$C$20/6 -> 250.80782 | H32: =+$C$20/6 -> 250.80782
B33: EBIT | C33: =+'Individual purchase'!C31-C32 -> 1999.1922 | D33: =+'Individual purchase'!D31-D32 -> 2286.0672 | E33: =+'Individual purchase'!E31-E32 -> 2523.2547 | F33: =+'Individual purchase'!F31-F32 -> 2743.2547 | G33: =+'Individual purchase'!G31-G32 -> 2891.4608 | H33: =+'Individual purchase'!H31-H32 -> 3047.0031 | I33: =+I29-I31 -> -1802.44
B34: Interest paid | C34: =+C22*C12 -> 0 | D34: =+D22*D12 -> 46.725 | E34: =+E22*E12 -> 101.5 | F34: =+F22*F12 -> 163.8 | G34: =+G22*G12 -> 229.46606 | H34: =+H22*H12 -> 241.07988
B35: Profit before tax | C35: =+C33-C34 -> 1999.1922 | D35: =+D33-D34 -> 2239.3422 | E35: =+E33-E34 -> 2421.7547 | F35: =+F33-F34 -> 2579.4547 | G35: =+G33-G34 -> 2661.9947 | H35: =+H33-H34+I33 -> 1003.4832
B36: Tax | C36: =+IF(C35<0,0,C35*C14) -> 399.83844 | D36: =+IF(D35<0,0,D35*D14) -> 447.86844 | E36: =+IF(E35<0,0,E35*E14) -> 484.35094 | F36: =+IF(F35<0,0,F35*F14) -> 515.89094 | G36: =+IF(G35<0,0,G35*G14) -> 532.39894 | H36: =+IF(H35<0,0,H35*H14) -> 200.69663
B37: Profit after tax | C37: =+C35-C36 -> 1599.3537 | D37: =+D35-D36 -> 1791.4737 | E37: =+E35-E36 -> 1937.4037 | F37: =+F35-F36 -> 2063.5637 | G37: =+G35-G36 -> 2129.5958 | H37: =+H35-H36 -> 802.78653
B38: Dividend | C38: =+C37-C39 -> 1167.6616 | D38: =+D37-D39 -> 1674.7816 | E38: =+E37-E39 -> 1937.4037 | F38: =+F37-F39 -> 2063.5637 | G38: =+G37-G39 -> 1716.7565 | H38: =+H37-H39 -> 802.78653
B39: Retained earnings | C39: =+IF(C37<0,C37,MAX(0,MIN(C41,C37))) -> 431.69218 | D39: =+IF(D37<0,D37,MAX(0,MIN(D41,D37))) -> 116.69218 | E39: =+IF(E37<0,E37,MAX(0,MIN(E41,E37))) -> 0 | F39: =+IF(F37<0,F37,MAX(0,MIN(F41,F37))) -> 0 | G39: =+IF(G37<0,G37,MAX(0,MIN(G41,G37))) -> 412.83931 | H39: =+IF(H37<0,H37,MAX(0,MIN(H41,H37))) -> 0
B41: dEquity needed | C41: =+D23-C23 -> 431.69218 | D41: =+E23-D23 -> 116.69218 | E41: =+F23-E23 -> -40.807821 | F41: =+G23-F23 -> -398.46182 | G41: =+H23-G23 -> 412.83931 | H41: =+J23-H23 -> -14026.801
B42: Share issue/buyback | C42: =+C41-C39 -> 0 | D42: =+D41-D39 -> 0 | E42: =+E41-E39 -> -40.807821 | F42: =+F41-F39 -> -398.46182 | G42: =+G41-G39 -> 0 | H42: =+H41-H39 -> -14026.801
B44: Noplat=EBIT*(1-t) | C44: =+C33*(1-C25) -> 1599.3537 | D44: =+D33*(1-D25) -> 1828.8537 | E44: =+E33*(1-E25) -> 2018.6037 | F44: =+F33*(1-F25) -> 2194.6037 | G44: =+G33*(1-G25) -> 2313.1686 | H44: =+H33*(1-H25) -> 2437.6025 | I44: =+I33*(1-H25) -> -1441.952
B45: dIC | C45: =+'Individual purchase'!C43 -> 1350 | D45: =+'Individual purchase'!D43 -> 1150 | E45: =+'Individual purchase'!E43 -> 1100 | F45: =+'Individual purchase'!F43 -> 790.4325 | G45: =+'Individual purchase'!G43 -> 829.55891 | H45: =+J21-H21 -> -17219.991
B46: dRentalright | C46: =+D20-C20 -> -250.80782 | D46: =+E20-D20 -> -250.80782 | E46: =+F20-E20 -> -250.80782 | F46: =+G20-F20 -> -250.80782 | G46: =+H20-G20 -> -250.80782 | H46: =+I20-H20 -> -250.80782
B47: FCFF | C47: =+C44-C45-C46 -> 500.16156 | D47: =+D44-D45-D46 -> 929.66156 | E47: =+E44-E45-E46 -> 1169.4116 | F47: =+F44-F45-F46 -> 1654.9791 | G47: =+G44-G45-G46 -> 1734.4175 | H47: =+H44-H45+I44-H46 -> 18466.45
B48: =+B34 -> Interest paid | C48: =+C34 -> 0 | D48: =+D34 -> 46.725 | E48: =+E34 -> 101.5 | F48: =+F34 -> 163.8 | G48: =+G34 -> 229.46606 | H48: =+H34 -> 241.07988
B49: Tax shield | C49: =+C48*C25 -> 0 | D49: =+D48*D25 -> 9.345 | E49: =+E48*E25 -> 20.3 | F49: =+F48*F25 -> 32.76 | G49: =+G48*G25 -> 45.893211 | H49: =+H48*H25 -> 48.215976
B50: dDebt | C50: =+D22-C22 -> 667.5 | D50: =+E22-D22 -> 782.5 | E50: =+F22-E22 -> 890 | F50: =+G22-F22 -> 938.0865 | G50: =+H22-G22 -> 165.91178 | H50: =+J22-H22 -> -3443.9983
B51: FCFE | C51: =+C47-C48+C49+C50 -> 1167.6616 | D51: =+D47-D48+D49+D50 -> 1674.7816 | E51: =+E47-E48+E49+E50 -> 1978.2116 | F51: =+F47-F48+F49+F50 -> 2462.0256 | G51: =+G47-G48+G49+G50 -> 1716.7565 | H51: =+H47-H48+H49+H50 -> 14829.587
...
