Workbook
Name lista: OFFSET([1]DinamicValidation!$B$4,0,0,COUNTA([1]DinamicValidation!$B$4:$B$1048576),1)

Sheet OpeningPage

Sheet Admin
C9: Applied Business Valuation
C12: Date | D12: 45642
C13: Student name | D13: Gao Weijun | I13: Master in Finance
C14: Neptun code | D14: EVMNP2 | I14: Master in Accounting
C16: Study program | D16: Master in Finance
C17: Instructor | D17: Péter Juhász, PhD, CFA
C20: Total points achieved | D20: =+'Task 1'!C9+'Task 4'!C9+'Task 5'!C9+'Task 3'!C9+'Task 2'!C9+'Bonus Task'!C9 -> 0

Sheet Task 1
B2: =+Admin!C12 -> Date | C2: =+Admin!D12 -> 45642
B3: =+Admin!C13 -> Student name | C3: =+Admin!D13 -> Gao Weijun
B4: =+Admin!C14 -> Neptun code | C4: =+Admin!D14 -> EVMNP2
B6: =+Admin!C16 -> Study program | C6: =+Admin!D16 -> Master in Finance
B7: =+Admin!C17 -> Instructor | C7: =+Admin!D17 -> Péter Juhász, PhD, CFA
B9: Points achived:
I17: =+J17-1 -> 2021 | J17: =+K17-1 -> 2022 | K17: =+YEAR(TODAY())-1 -> 2023
D18: =+E18-1 -> 2021 | E18: =+F18-1 -> 2022 | F18: =+YEAR(TODAY())-1 -> 2023 | H18: t effective | J18: =E31/(E30-E25) -> 0.22758621 | K18: =F31/(F30-F25) -> 0.14859438
C19: Sales | D19: 19000 | E19: 22000 | F19: 25000
C20: Other income | D20: 250 | E20: 0 | F20: 300
C21: Material expenses | D21: 10000 | E21: 12000 | F21: 13000 | H21: EBIT | I21: =D24 -> 2250 | J21: =E24 -> 1700 | K21: =F24 -> 2800
C22: Labour expenses | D22: 5000 | E22: 6000 | F22: 7000 | H22: NOPLAT | J22: =J21*(1-J18) -> 1313.1034 | K22: =K21*(1-K18) -> 2383.9357
C23: D&A | D23: 2000 | E23: 2300 | F23: 2500 | H23: D&A | J23: =E23 -> 2300 | K23: =F23 -> 2500
C24: Operational profit | D24: =+D19+D20-D21-D22-D23 -> 2250 | E24: =+E19+E20-E21-E22-E23 -> 1700 | F24: =+F19+F20-F21-F22-F23 -> 2800 | H24: Gross profit | J24: =J22+J23 -> 3613.1034 | K24: =K22+K23 -> 4883.9357
C25: Dividend received | D25: 0 | E25: 0 | F25: 100 | H25: d Inventory | J25: =D40-E40 -> -100 | K25: =E40-F40 -> -100
C26: Interests received | D26: 0 | E26: 20 | F26: 0 | H26: d Receivables | J26: =D39-E39 -> -350 | K26: =E39-F39 -> 50
C27: Interests paid on short term loans | D27: 30 | E27: 20 | F27: 10 | H27: d Operational Cash | J27: =D37-E37 -> -20 | K27: =E37-F37 -> -30
C28: Interests paid on long term loans | D28: 200 | E28: 250 | F28: 300 | H28: d Payables | J28: =E47-D47 -> -60 | K28: =F47-E47 -> 210
C29: Financial profit | D29: =+D25+D26-D27-D28 -> -230 | E29: =+E25+E26-E27-E28 -> -250 | F29: =+F25+F26-F27-F28 -> -210 | H29: d short-term Debt | J29: =E46-D46 -> -100 | K29: =F46-E46 -> 50
C30: Profit before tax | D30: =+D29+D24 -> 2020 | E30: =+E29+E24 -> 1450 | F30: =+F29+F24 -> 2590 | H30: Cash from operation/Operation C-F | J30: =J24+SUM(J25:J29) -> 2983.1034 | K30: =K24+SUM(K25:K29) -> 5063.9357
C31: Corporate tax | D31: 300 | E31: 330 | F31: 370 | H31: d Ivested assets | J31: =SUM(E42:E43)-SUM(D42:D43) -> 5600 | K31: =SUM(F42:F43)-SUM(E42:E43) -> -600
C32: Profit after tax | D32: =+D30-D31 -> 1720 | E32: =+E30-E31 -> 1120 | F32: =+F30-F31 -> 2220 | H32: D&A | J32: =E23 -> 2300 | K32: =F23 -> 2500
C33: Dividend | D33: 1000 | E33: 1200 | F33: 1400 | H33: Dividend received | J33: =E25 -> 0 | K33: =F25 -> 100
C34: Retained earnings | D34: =+D32-D33 -> 720 | E34: =+E32-E33 -> -80 | F34: =+F32-F33 -> 820 | H34: Interests received | J34: =E26 -> 20 | K34: =F26 -> 0
H35: tax on int rec | J35: =J34*J18 -> 4.5517241 | K35: =K34*K18 -> 0
C36: Cash | D36: 500 | E36: 600 | F36: 400 | H36: Investment CF | J36: =-J31-J32+J33+J34-J35 -> -7884.5517 | K36: =-K31-K32+K33+K34-K35 -> -1800
C37: of which operational cash | D37: 200 | E37: 220 | F37: 250 | H37: FCFF | J37: =J30+J36 -> -4901.4483 | K37: =K30+K36 -> 3263.9357
C38: Marketable securities | D38: 0 | E38: 50 | F38: 40 | H38: interest paid | J38: =SUM(E27:E28) -> 270 | K38: =SUM(F27:F28) -> 310
C39: Receivables | D39: 600 | E39: 950 | F39: 900 | H39: tax shield | J39: =J38*J18 -> 61.448276 | K39: =K38*K18 -> 46.064257
C40: Inventory | D40: 400 | E40: 500 | F40: 600 | H40: d long-term Debt | J40: =E50-D50 -> 1000 | K40: =F50-E50 -> 1000
C41: Current assets | D41: =+D36+D38+D39+D40 -> 1500 | E41: =+E36+E38+E39+E40 -> 2100 | F41: =+F36+F38+F39+F40 -> 1940 | H41: FCFE | J41: =J37-J38+J39+J40 -> -4110 | K41: =K37-K38+K39+K40 -> 4000
C42: PP&E | D42: 15000 | E42: 20000 | F42: 19500 | H42: DIV | J42: =E33 -> 1200 | K42: =F33 -> 1400
C43: Intangible assets | D43: 1500 | E43: 2100 | F43: 2000 | H43: dBV E-Ret ear | J43: =E51-D51-E34 -> 5640 | K43: =F51-E51-F34 -> -2640
C44: Total of assests | D44: =+D42+D41+D43 -> 18000 | E44: =+E42+E41+E43 -> 24200 | F44: =+F42+F41+F43 -> 23440 | H44: D Non-operational wealth | J44: =J41-J42+J43 -> 330 | K44: =K41-K42+K43 -> -40
C45: Short term loans | D45: 300 | E45: 200 | F45: 250
C46: of which liquidity debt | D46: 300 | E46: 200 | F46: 250 | H46: of which non-operational cash | I46: =D36-D37 -> 300 | J46: =E36-E37 -> 380 | K46: =F36-F37 -> 150
C47: Payables | D47: 300 | E47: 240 | F47: 450 | H47: Marketable securities | I47: =D38 -> 0 | J47: =E38 -> 50 | K47: =F38 -> 40
C48: Short term liabilities | D48: =+D45+D47 -> 600 | E48: =+E45+E47 -> 440 | F48: =+F45+F47 -> 700 | H48: Non op wealth | I48: =SUM(I46:I47) -> 300 | J48: =SUM(J46:J47) -> 430 | K48: =SUM(K46:K47) -> 190
C49: Bonds outstanding | D49: 1000 | E49: 800 | F49: 600 | H49: dNon-op wealth | J49: =J48-I48 -> 130 | K49: =K48-J48 -> -240
C50: Long term bank loan | D50: 4000 | E50: 5000 | F50: 6000
...

Sheet Task 2
B2: =+Admin!C12 -> Date | C2: =+Admin!D12 -> 45642
B3: =+Admin!C13 -> Student name | C3: =+Admin!D13 -> Gao Weijun
B4: =+Admin!C14 -> Neptun code | C4: =+Admin!D14 -> EVMNP2
B6: =+Admin!C16 -> Study program | C6: =+Admin!D16 -> Master in Finance
B7: =+Admin!C17 -> Instructor | C7: =+Admin!D17 -> Péter Juhász, PhD, CFA
B9: Points achived:
D24: 2025 | E24: =+D24+1 -> 2026 | F24: =+E24+1 -> 2027 | G24: =+F24+1 -> 2028 | H24: =+G24+1 -> 2029 | I24: TV1 | J24: TV2
C25: t | D25: 0.2 | E25: 0.2 | F25: 0.2 | G25: 0.2 | H25: 0.2 | I25: 0.2 | J25: 0.2
C26: rA | D26: 0.12 | E26: 0.12 | F26: 0.12 | G26: 0.12 | H26: 0.12 | I26: 0.12 | J26: 0.12
C27: rD | D27: 0.06 | E27: 0.07 | F27: 0.072 | G27: 0.073 | H27: 0.074 | I27: 0.074 | J27: 0.074
C28: IC boy | D28: 200000
C29: g targeted for the given year | F29: 0.12 | G29: 0.1 | H29: 0.08 | I29: 0.05 | J29: 0.05
C30: K | D30: 0.85 | E30: =F29/F32 -> 0.85714286 | F30: =G29/G32 -> 0.76923077 | G30: =H29/H32 -> 0.66666667 | H30: =I29/I32 -> 0.43828892 | I30: =J29/I32 -> 0.43828892 | J30: =I30 -> 0.43828892
C31: ROIC | D31: 0.11 | E31: 0.115
C32: RONIC | F32: 0.14 | G32: 0.13 | H32: 0.12 | I32: =I35 -> 0.11408 | J32: =J35 -> 0.11408
C33: D/V boy | D33: =D40/D70 -> 0.14590913 | E33: =E40/E70 -> 0.19301007 | F33: =F40/F70 -> 0.24063349 | G33: 0.3 | H33: 0.4 | I33: 0.4 | J33: 0.4
C34: D/IC boy | D34: 0.15 | E34: 0.2 | F34: 0.25
C35: WACC | D35: =D26-D27*D33*D25 -> 0.11824909 | E35: =E26-E27*E33*E25 -> 0.11729786 | F35: =F26-F27*F33*F25 -> 0.11653488 | G35: =G26-G27*G33*G25 -> 0.11562 | H35: =H26-H27*H33*H25 -> 0.11408 | I35: =I26-I27*I33*I25 -> 0.11408 | J35: =J26-J27*J33*J25 -> 0.11408
C39: IC | D39: =D28 -> 200000 | E39: =D39+D46 -> 218700 | F39: =E39+E46 -> 240257.57 | G39: =F39+F46 -> 261925.69 | H39: =G39+G46 -> 282582.64 | I39: =H39+H46 -> 297249.65 | J39: =I39+I46 -> 312650.01
C40: D | D40: =D34*D39 -> 30000 | E40: =E34*E39 -> 43740 | F40: =F34*F39 -> 60064.393 | G40: =G33*G65 -> 81659.167 | H40: =H33*H65 -> 117336.08 | I40: =I33*I65 -> 123202.88 | J40: =J33*J65 -> 129363.03 | K40: =J40*(1+J29) -> 135831.18
C41: E | D41: =D39-D40 -> 170000 | E41: =E39-E40 -> 174960 | F41: =F39-F40 -> 180193.18 | G41: =G39-G40 -> 180266.53 | H41: =H39-H40 -> 165246.56 | I41: =I39-I40 -> 174046.77 | J41: =J39-J40 -> 183286.98
C43: t effective assumed | D43: 0.2 | E43: 0.2 | F43: 0.2 | G43: 0.2 | H43: 0.2 | I43: 0.2 | J43: 0.2
C44: t effective calculated | D44: =D58/D57 -> 0.2 | E44: =E58/E57 -> 0.2 | F44: =F58/F57 -> 0.2 | G44: =G58/G57 -> 0.2 | H44: =H58/H57 -> 0.2 | I44: =I58/I57 -> 0.2 | J44: =J58/J57 -> 0.2
C45: noplat | D45: =D39*D31 -> 22000 | E45: =E39*E31 -> 25150.5 | F45: =E45+E46*F32 -> 28168.56 | G45: =F45+F46*G32 -> 30985.416 | H45: =G45+G46*H32 -> 33464.249 | I45: =H45+H46*I32 -> 35137.462 | J45: =I45+I46*J32 -> 36894.335
C46: dIC | D46: =D45*D30 -> 18700 | E46: =E45*E30 -> 21557.571 | F46: =F45*F30 -> 21668.123 | G46: =G45*G30 -> 20656.944 | H46: =H45*H30 -> 14667.01 | I46: =I45*I30 -> 15400.36 | J46: =J45*J30 -> 16170.378
C47: FCFF | D47: =D45-D46 -> 3300 | E47: =E45-E46 -> 3592.9286 | F47: =F45-F46 -> 6500.4369 | G47: =G45-G46 -> 10328.472 | H47: =H45-H46 -> 18797.24 | I47: =I45-I46 -> 19737.102 | J47: =J45-J46 -> 20723.957
C48: interest = D*rD | D48: =D40*D27 -> 1800 | E48: =E40*E27 -> 3061.8 | F48: =F40*F27 -> 4324.6363 | G48: =G40*G27 -> 5961.1192 | H48: =H40*H27 -> 8682.8697 | I48: =I40*I27 -> 9117.0132 | J48: =J40*J27 -> 9572.8639
C49: TS | D49: =D48*D43 -> 360 | E49: =E48*E43 -> 612.36 | F49: =F48*F43 -> 864.92726 | G49: =G48*G43 -> 1192.2238 | H49: =H48*H43 -> 1736.5739 | I49: =I48*I43 -> 1823.4026 | J49: =J48*J43 -> 1914.5728
C50: dDebt | D50: =E40-D40 -> 13740 | E50: =F40-E40 -> 16324.393 | F50: =G40-F40 -> 21594.774 | G50: =H40-G40 -> 35676.911 | H50: =I40-H40 -> 5866.8039 | I50: =J40-I40 -> 6160.1441 | J50: =K40-J40 -> 6468.1513
C51: FCFE | D51: =D47-D48+D49+D50 -> 15600 | E51: =E47-E48+E49+E50 -> 17467.881 | F51: =F47-F48+F49+F50 -> 24635.502 | G51: =G47-G48+G49+G50 -> 41236.487 | H51: =H47-H48+H49+H50 -> 17717.748 | I51: =I47-I48+I49+I50 -> 18603.635 | J51: =J47-J48+J49+J50 -> 19533.817
C54: P/L
C55: EBIT | D55: =D45/(1-D43) -> 27500 | E55: =E45/(1-E43) -> 31438.125 | F55: =F45/(1-F43) -> 35210.7 | G55: =G45/(1-G43) -> 38731.77 | H55: =H45/(1-H43) -> 41830.312 | I55: =I45/(1-I43) -> 43921.827 | J55: =J45/(1-J43) -> 46117.919
C56: D*rD | D56: =D48 -> 1800 | E56: =E48 -> 3061.8 | F56: =F48 -> 4324.6363 | G56: =G48 -> 5961.1192 | H56: =H48 -> 8682.8697 | I56: =I48 -> 9117.0132 | J56: =J48 -> 9572.8639
C57: Profit before tax | D57: =D55-D56 -> 25700 | E57: =E55-E56 -> 28376.325 | F57: =F55-F56 -> 30886.064 | G57: =G55-G56 -> 32770.651 | H57: =H55-H56 -> 33147.442 | I57: =I55-I56 -> 34804.814 | J57: =J55-J56 -> 36545.055
C58: Tax | D58: =D57*D25 -> 5140 | E58: =E57*E25 -> 5675.265 | F58: =F57*F25 -> 6177.2127 | G58: =G57*G25 -> 6554.1302 | H58: =H57*H25 -> 6629.4884 | I58: =I57*I25 -> 6960.9628 | J58: =J57*J25 -> 7309.0109
C59: Profit after tax | D59: =D57-D58 -> 20560 | E59: =E57-E58 -> 22701.06 | F59: =F57-F58 -> 24708.851 | G59: =G57-G58 -> 26216.521 | H59: =H57-H58 -> 26517.953 | I59: =I57-I58 -> 27843.851 | J59: =J57-J58 -> 29236.044
C62: FCFF // WACC
C63: FCFF | D63: =D47 -> 3300 | E63: =E47 -> 3592.9286 | F63: =F47 -> 6500.4369 | G63: =G47 -> 10328.472 | H63: =H47 -> 18797.24 | I63: =I47 -> 19737.102 | J63: =J47 -> 20723.957
C64: WACC | D64: =D35 -> 0.11824909 | E64: =E35 -> 0.11729786 | F64: =F35 -> 0.11653488 | G64: =G35 -> 0.11562 | H64: =H35 -> 0.11408 | I64: =I35 -> 0.11408 | J64: =J35 -> 0.11408
C65: V boy | D65: =(D63+E65)/(1+D64) -> 205607.41 | E65: =(E63+F65)/(1+E64) -> 226620.3 | F65: =(F63+G65)/(1+F64) -> 249609.45 | G65: =(G63+H65)/(1+G64) -> 272197.22 | H65: =(H63+I65)/(1+H64) -> 293340.19 | I65: =(I63+J65)/(1+I64) -> 308007.2 | J65: =J63/(J64-J29) -> 323407.56
...

Sheet Task 3
B2: =+Admin!C12 -> Date | C2: =+Admin!D12 -> 45642
B3: =+Admin!C13 -> Student name | C3: =+Admin!D13 -> Gao Weijun
B4: =+Admin!C14 -> Neptun code | C4: =+Admin!D14 -> EVMNP2
B6: =+Admin!C16 -> Study program | C6: =+Admin!D16 -> Master in Finance
B7: =+Admin!C17 -> Instructor | C7: =+Admin!D17 -> Péter Juhász, PhD, CFA
B9: Points achived:
D27: Firm A | E27: Firm B | F27: Together
C28: t | D28: 0.2 | E28: 0.2 | F28: 0.2
C29: rA | D29: 0.11 | E29: 0.11 | F29: 0.11
C30: D/V | D30: 0.4 | E30: 0.3 | F30: 0.4
C31: rD | D31: 0.05 | E31: 0.04 | F31: 0.05
C32: Noplat (million) | D32: 840 | E32: 130 | F32: 1000
C33: g | D33: 0.03 | E33: 0.038 | F33: 0.033
C34: RONIC | D34: 0.101 | E34: 0.12 | F34: 0.102
C35: Number of shares | D35: 200000000 | E35: 1000000
C38: WACC | D38: =D29-D31*D30*D28 -> 0.106 | E38: =E29-E31*E30*E28 -> 0.1076 | F38: =F29-F31*F30*F28 -> 0.106
C39: K | D39: =D33/D34 -> 0.2970297 | E39: =E33/E34 -> 0.31666667 | F39: =F33/F34 -> 0.32352941
C40: FCFF | D40: =D32*(1-D39) -> 590.49505 | E40: =E32*(1-E39) -> 88.833333 | F40: =F32*(1-F39) -> 676.47059
C41: V boy | D41: =D40/(D38-D33) -> 7769.6717 | E41: =E40/(E38-E33) -> 1276.341 | F41: =F40/(F38-F33) -> 9266.7204
C42: D | D42: =D41*D30 -> 3107.8687 | E42: =E41*E30 -> 382.9023 | F42: =F41*F30 -> 3706.6882
C43: E | D43: =D41-D42 -> 4661.803 | E43: =E41-E42 -> 893.4387 | F43: =F41-F42 -> 5560.0322
G45: synergy
D46: no transaction | E46: with transaction | G46: =F41-E41-D41 -> 220.70769
C47: Min | D47: =E43 -> 893.4387 | E47: =E43+D50 -> 903.4387
C48: Max | D48: =G46+D47 -> 1114.1464 | E48: =D48-D51 -> 1094.1464
C50: seller transaction | D50: =10 -> 10
C51: buyer | D51: =20 -> 20
C55: price | D55: =D47+G46*40% -> 981.72177
C56: 35% in cash | D56: =D55*35% -> 343.60262
C57: 75% stake | D57: =D55-D56 -> 638.11915
C59: %ownership B | D59: =D57/F43 -> 0.11476897
C61: Old shares | D61: =D35 -> 200000000
C62: Stakeof old owners | D62: =1-D59 -> 0.88523103
C63: Total number shares | D63: =D61/D62 -> 2.2592972e+08
C64: New shares to issue | D64: =D63-D61 -> 25929720

Sheet Task 4
B2: =+Admin!C12 -> Date | C2: =+Admin!D12 -> 45642
B3: =+Admin!C13 -> Student name | C3: =+Admin!D13 -> Gao Weijun
B4: =+Admin!C14 -> Neptun code | C4: =+Admin!D14 -> EVMNP2
B6: =+Admin!C16 -> Study program | C6: =+Admin!D16 -> Master in Finance
B7: =+Admin!C17 -> Instructor | C7: =+Admin!D17 -> Péter Juhász, PhD, CFA
B9: Points achived:
B20: Corporate tax rate | C20: 0.15
B21: Required rate of return on renting | C21: 0.09
B22: Capitalisation rate for EBITDA | C22: 0.07
B23: Average inflation during the last 20 years | C23: 0.02
B25: Age of the building | C25: 20 | D25: years
B26: Useful operational years left over | C26: 25 | D26: years
B27: Accounting life time left over | C27: 20 | D27: years
B29: Total net monthly rental income before D&A | C29: 250
B30: Expected g of rental fees | C30: 0.05
B32: Net book value of the building | C32: 28000
B33: Gross book value of the building | C33: 50000
B35: D&A | C35: =C32/C27 -> 1400
B37: Growing annuity of Rent | C37: =C29/(C21-C30)*(1-((1+C30)^C26)/((1+C21)^C26)) -> 3795.5734
B38: TS of D&A | C38: =C35*C20/C21*(1-1/(1+C21)^C27) -> 1916.9946
B39: Total PV with TS | C39: =+C37+C38 -> 5712.568
B40: Book Value of the Building | C40: =C32 -> 28000
B41: PV in 20 Years | C41: =C39+C40 -> 33712.568
B42: PV Today | C42: =C41/(1+C21)^20 -> 6015.3635
B46: Adjusted historical cost | C46: =+C33*(1+C23)^C25*C32/C33 -> 41606.527
B47: Capitalization | C47: =+C29*12/C22 -> 42857.143
B50: Rental income | C50: =+C29*12*(1-C20)/(C21-C30)*(1-(1+C30)^C26/(1+C21)^C26) -> 38714.849
B51: TS | C51: =+C32/C27*C20/C21*(1-1/(1+C21)^C27) -> 1916.9946
B52: DCF | C52: =+C50+C51 -> 40631.843

Sheet Task 5
B2: =+Admin!C12 -> Date | C2: =+Admin!D12 -> 45642
B3: =+Admin!C13 -> Student name | C3: =+Admin!D13 -> Gao Weijun
B4: =+Admin!C14 -> Neptun code | C4: =+Admin!D14 -> EVMNP2
B6: =+Admin!C16 -> Study program | C6: =+Admin!D16 -> Master in Finance
B7: =+Admin!C17 -> Instructor | C7: =+Admin!D17 -> Péter Juhász, PhD, CFA
B9: Points achived:

Sheet Bonus Task
B2: =+Admin!C12 -> Date | C2: =+Admin!D12 -> 45642
B3: =+Admin!C13 -> Student name | C3: =+Admin!D13 -> Gao Weijun
B4: =+Admin!C14 -> Neptun code | C4: =+Admin!D14 -> EVMNP2
B6: =+Admin!C16 -> Study program | C6: =+Admin!D16 -> Master in Finance
B7: =+Admin!C17 -> Instructor | C7: =+Admin!D17 -> Péter Juhász, PhD, CFA
B9: Points achived:
B20: 1-year forward required returns | C20: 1y | D20: 2y | E20: 3y | F20: 4y | G20: 5y
B21: rD | C21: =C27+C32 -> 0.073 | D21: =D27+D32 -> 0.0785 | E21: =E27+E32 -> 0.084 | F21: =F27+F32 -> 0.0895 | G21: =G27+G32 -> 0.09
B22: rA
B23: rE
B24: WACC
B26: Financials | C26: 1y | D26: 2y | E26: 3y | F26: 4y | G26: 5y
B27: Government bond spot rates | C27: 0.068 | D27: 0.0685 | E27: 0.069 | F27: 0.0695 | G27: 0.07
B28: Expected sport return of the market portfolio | C28: 0.12 | D28: 0.1205 | E28: 0.121 | F28: 0.1215 | G28: 0.122
B29: Nominal tax rate | C29: 0.2 | D29: 0.2 | E29: 0.2 | F29: 0.2 | G29: 0.2
B30: Effective tax rate | C30: 0 | D30: 0.18 | E30: 0.21 | F30: 0.19 | G30: 0.2
B31: D/V boy | C31: 0.1 | D31: 0.2 | E31: 0.3 | F31: 0.4 | G31: 0.4
B32: Debt risk premium | C32: 0.005 | D32: 0.01 | E32: 0.015 | F32: 0.02 | G32: 0.02
B33: Market risk premium | C33: =+C28-C27 -> 0.052 | D33: =+D28-D27 -> 0.052 | E33: =+E28-E27 -> 0.052 | F33: =+F28-F27 -> 0.052 | G33: =+G28-G27 -> 0.052
B35: Competitor's data
C36: EV | D36: Cash | E36: E | F36: D | G36: D/E | H36: D/V | I36: betaE | J36: betaD | K36: rE | L36: rD
B37: Firm AA | C37: 3800 | D37: 200 | F37: 1100 | J37: 0.1 | K37: 0.13
B38: Firm BB | H38: 0.2 | I38: 1.15 | J38: 0.15
B39: Firm CC | G39: 0.6 | I39: 1.3 | L39: 0.08
B40: Firm DD | C40: 4000 | D40: 100 | E40: 4100 | K40: 0.12
