Workbook
Name lista: OFFSET(#REF!,0,0,COUNTA(#REF!),1)

Sheet OpeningPage

Sheet Admin
C9: Applied Business Valuation
C12: Date | D12: 45308
C13: Student name | I13: Master in Finance
C14: Neptun code | I14: Master in Accounting
C16: Study program | D16: Master in Finance
C17: Instructor | D17: Péter Juhász, PhD, CFA
C20: Total points achieved | D20: =+'Task 3'!C9+'Task 4'!C9+'Task 5'!C9+#REF!+'Task 2'!C9 -> #REF!

Sheet Task 1
B2: =+Admin!C12 -> Date | C2: =+Admin!D12 -> 45308
B3: =+Admin!C13 -> Student name | C3: =+Admin!D13 -> 0
B4: =+Admin!C14 -> Neptun code | C4: =+Admin!D14 -> 0
B6: =+Admin!C16 -> Study program | C6: =+Admin!D16 -> Master in Finance
B7: =+Admin!C17 -> Instructor | C7: =+Admin!D17 -> Péter Juhász, PhD, CFA
B9: Points achived:
C27: A before | D27: A after
B28: Number of shares | C28: 3000000
B29: t | C29: 0.15 | D29: 0.15
B30: FCFF | C30: 2000 | D30: 2024
B31: WACC | C31: 0.1 | D31: 0.1
B32: D/V | C32: 0.25 | D32: 0.25
B33: rD | C33: 0.05 | D33: 0.05
B34: g | C34: 0.03 | D34: 0.032
B42: B before | C42: 1 | D42: 2 | E42: 3 | F42: 4 | G42: TV | K42: B after
B43: IC boy | C43: 250 | K43: IC boy | L43: 250
B44: ROIC | C44: 0.12 | D44: 0.12 | E44: 0.12 | F44: 0.12 | K44: ROIC | L44: 0.12
B45: RONIC | G45: 0.1 | K45: RONIC | M45: 0.15 | N45: 0.14 | O45: 0.13 | P45: 0.1
B46: K | C46: 0.2 | D46: 0.2 | E46: 0.2 | F46: 0.2 | K46: K | L46: 0.7 | M46: 0.6 | N46: 0.5 | O46: 0.4
B47: D/V | C47: 0 | D47: 0 | E47: 0 | F47: 0 | G47: 0 | K47: D/V | L47: 0.25 | M47: 0.25 | N47: 0.25 | O47: 0.25 | P47: 0.25
B48: Number of shares | C48: 500000 | K48: rD | L48: 0.04 | M48: 0.04 | N48: 0.04 | O48: 0.04 | P48: 0.04
B49: gTV | G49: 0.05 | K49: gTV | P49: 0.05
B50: rA | C50: 0.1 | D50: 0.1 | E50: 0.1 | F50: 0.1 | G50: 0.1
B51: t | C51: 0.15 | D51: 0.15 | E51: 0.15 | F51: 0.15 | G51: 0.15
B53: WACC | C53: =C50-L48*L48*C51 -> 0.09976 | D53: =D50-M48*M48*D51 -> 0.09976 | E53: =E50-N48*N48*E51 -> 0.09976 | F53: =F50-O48*O48*F51 -> 0.09976 | G53: =G50-P48*P48*G51 -> 0.09976
B54: IC boy | C54: =C43 -> 250 | D54: =C54+C60 -> 256 | E54: =D54+D60 -> 262.144 | F54: =E54+E60 -> 268.43546 | G54: =F54+F60 -> 274.87791
A55: is 0 because D/V = 0 | B55: Debt boy | C55: 0 | D55: 0 | E55: 0 | F55: 0 | G55: 0
B56: BV Equity boy | C56: =C54-C57 -> 250 | D56: =D54-D57 -> 256 | E56: =E54-E57 -> 262.144 | F56: =F54-F57 -> 268.43546 | G56: =G54-G57 -> 274.87791
B58: EBIT
B59: Noplat | C59: =C54*C44 -> 30 | D59: =D54*D44 -> 30.72 | E59: =E54*E44 -> 31.45728 | F59: =F54*F44 -> 32.212255 | G59: =F59+F59*G49 -> 33.822867
B60: dIC | C60: =C59*C46 -> 6 | D60: =D59*D46 -> 6.144 | E60: =E59*E46 -> 6.291456 | F60: =F59*F46 -> 6.4424509 | G60: =(G59-F59)/G45 -> 16.106127
B61: FCFF | C61: =C59-C60 -> 24 | D61: =D59-D60 -> 24.576 | E61: =E59-E60 -> 25.165824 | F61: =F59-F60 -> 25.769804 | G61: =G59-G60 -> 17.71674
B62: V | G62: =G61/(G53-G49) -> 356.04381
C70: B before
B71: WACC | C71: =G53 -> 0.09976
B72: k | C72: =G60/G59 -> 0.47619048
B73: NOPLAT | C73: =G59 -> 33.822867
B75: V | C75: =G62 -> 356.04381
B76: D | C76: =G55 -> 0
B77: E | C77: =G56 -> 274.87791
...

Sheet Task 2
B2: =+Admin!C12 -> Date | C2: =+Admin!D12 -> 45308
B3: =+Admin!C13 -> Student name | C3: =+Admin!D13 -> 0
B4: =+Admin!C14 -> Neptun code | C4: =+Admin!D14 -> 0
B6: =+Admin!C16 -> Study program | C6: =+Admin!D16 -> Master in Finance
B7: =+Admin!C17 -> Instructor | C7: =+Admin!D17 -> Péter Juhász, PhD, CFA
B9: Points achived:
D25: 2024 | E25: =+D25+1 -> 2025 | F25: =+E25+1 -> 2026 | G25: =+F25+1 -> 2027 | H25: =+G25+1 -> 2028 | I25: TV
C26: t | D26: 0.2 | E26: 0.2 | F26: 0.2 | G26: 0.2 | H26: 0.2 | I26: 0.2
C27: RONIC | F27: 0.16 | G27: 0.15 | H27: 0.14 | I27: =I37 -> 0.11416
C28: ROIC | D28: -0.01 | E28: 0.15
C29: rA | D29: 0.12 | E29: 0.12 | F29: 0.12 | G29: 0.12 | H29: 0.12 | I29: 0.12
C30: rD | D30: 0.06 | E30: 0.06 | F30: 0.065 | G30: 0.07 | H30: 0.073 | I30: 0.073
C31: dIC | D31: 2000 | E31: 1000
C32: K | F32: 0.4 | G32: 0.3 | H32: 0.25 | I32: =I35/I27 -> 0.61317449
C33: D/V boy | D33: =D39/D59 -> 0.041886637 | E33: =E39/E59 -> 0.11252635 | F33: =F39/F59 -> 0.18730153 | G33: =G39/G59 -> 0.26472531 | H33: 0.4 | I33: 0.4
C34: D/IC boy | D34: 0.05 | E34: 0.15 | F34: 0.25 | G34: 0.35
C35: g TV period | I35: 0.07
C37: WACC | D37: =D29-D33*D30*D26 -> 0.11949736 | E37: =E29-E33*E30*E26 -> 0.11864968 | F37: =F29-F33*F30*F26 -> 0.11756508 | G37: =G29-G33*G30*G26 -> 0.11629385 | H37: =H29-H33*H30*H26 -> 0.11416 | I37: =I29-I33*I30*I26 -> 0.11416
C38: IC boy | D38: 50000 | E38: =D38+D44 -> 52000 | F38: =E38+E44 -> 53000 | G38: =F38+F44 -> 56184 | H38: =G38+G44 -> 58715.28 | I38: =H38+H44 -> 60913.275
C39: Debt boy | D39: =D38*D34 -> 2500 | E39: =E38*E34 -> 7800 | F39: =F38*F34 -> 13250 | G39: =G38*G34 -> 19664.4 | H39: =H33*H54 -> 30805.814 | I39: =I33*I54 -> 31685.012 | J39: =I39+(I39*I35) -> 33902.962
C40: BV Equity boy | D40: =D38-D39 -> 47500 | E40: =E38-E39 -> 44200 | F40: =F38-F39 -> 39750 | G40: =G38-G39 -> 36519.6 | H40: =H38-H39 -> 27909.466 | I40: =I38-I39 -> 29228.263
C42: EBIT
C43: Noplat | D43: =D28*D38 -> -500 | E43: =E28*E38 -> 7800 | F43: =E44*F27+E43 -> 7960 | G43: =F44*G27+F43 -> 8437.6 | H43: =G44*H27+G43 -> 8791.9792 | I43: =H44*I27+H43 -> 9042.9023
C44: dIC | D44: =D31 -> 2000 | E44: =E31 -> 1000 | F44: =F32*F43 -> 3184 | G44: =G32*G43 -> 2531.28 | H44: =H32*H43 -> 2197.9948 | I44: =I32*I43 -> 5544.877
C45: FCFF | D45: =D43-D44 -> -2500 | E45: =E43-E44 -> 6800 | F45: =F43-F44 -> 4776 | G45: =G43-G44 -> 5906.32 | H45: =H43-H44 -> 6593.9844 | I45: =I43-I44 -> 3498.0253
C46: Interest | D46: =D39*D30 -> 150 | E46: =E39*E30 -> 468 | F46: =F39*F30 -> 861.25 | G46: =G39*G30 -> 1376.508 | H46: =H39*H30 -> 2248.8244 | I46: =I39*I30 -> 2313.0058
C47: Tax shield | D47: =D46*D26 -> 30 | E47: =E46*E26 -> 93.6 | F47: =F46*F26 -> 172.25 | G47: =G46*G26 -> 275.3016 | H47: =H46*H26 -> 449.76488 | I47: =I46*I26 -> 462.60117
C48: d Debt | D48: =E39-D39 -> 5300 | E48: =F39-E39 -> 5450 | F48: =G39-F39 -> 6414.4 | G48: =H39-G39 -> 11141.414 | H48: =I39-H39 -> 879.19792 | I48: =J39-I39 -> 2217.9508
C49: FCFE | D49: =D45-D46+D47+D48 -> 2680 | E49: =E45-E46+E47+E48 -> 11875.6 | F49: =F45-F46+F47+F48 -> 10501.4 | G49: =G45-G46+G47+G48 -> 15946.527 | H49: =H45-H46+H47+H48 -> 5674.1228 | I49: =I45-I46+I47+I48 -> 3865.5714
C52: FCFF | D52: =D45 -> -2500 | E52: =E45 -> 6800 | F52: =F45 -> 4776 | G52: =G45 -> 5906.32 | H52: =H45 -> 6593.9844 | I52: =I45 -> 3498.0253
C53: WACC | D53: =D37 -> 0.11949736 | E53: =E37 -> 0.11864968 | F53: =F37 -> 0.11756508 | G53: =G37 -> 0.11629385 | H53: =H37 -> 0.11416 | I53: =I37 -> 0.11416
C54: V boy | D54: =(D52+E54)/(1+D53) -> 59684.906 | E54: =(E52+F54)/(1+E53) -> 69317.095 | F54: =(F52+G54)/(1+F53) -> 70741.546 | G54: =(G52+H54)/(1+G53) -> 74282.282 | H54: =(H52+I54)/(1+H53) -> 77014.534 | I54: =I52/(I53-I35) -> 79212.529
C57: FCFF+TS | D57: =D45+D47 -> -2470 | E57: =E45+E47 -> 6893.6 | F57: =F45+F47 -> 4948.25 | G57: =G45+G47 -> 6181.6216 | H57: =H45+H47 -> 7043.7493 | I57: =I45+I47 -> 3960.6264
C58: rA | D58: =D29 -> 0.12 | E58: =E29 -> 0.12 | F58: =F29 -> 0.12 | G58: =G29 -> 0.12 | H58: =H29 -> 0.12 | I58: =I29 -> 0.12
C59: V boy | D59: =(D57+E59)/(1+D58) -> 59684.906 | E59: =(E57+F59)/(1+E58) -> 69317.095 | F59: =(F57+G59)/(1+F58) -> 70741.546 | G59: =(G57+H59)/(1+G58) -> 74282.282 | H59: =(H57+I59)/(1+H58) -> 77014.534 | I59: =I57/(I58-I35) -> 79212.529
C60: check
C62: FCFE | D62: =D49 -> 2680 | E62: =E49 -> 11875.6 | F62: =F49 -> 10501.4 | G62: =G49 -> 15946.527 | H62: =H49 -> 5674.1228 | I62: =I49 -> 3865.5714
C63: rE | D63: =(D29-D30*D33)/(1-D33) -> 0.12262307 | E63: =(E29-E30*E33)/(1-E33) -> 0.12760764 | F63: =(F29-F30*F33)/(1-F33) -> 0.13267578 | G63: =(G29-G30*G33)/(1-G33) -> 0.1380018 | H63: =(H29-H30*H33)/(1-H33) -> 0.15133333 | I63: =(I29-I30*I33)/(1-I33) -> 0.15133333
C64: E boy | D64: =(D62+E64)/(1+D63) -> 57184.906 | E64: =(E62+F64)/(1+E63) -> 61517.095 | F64: =(F62+G64)/(1+F63) -> 57491.546 | G64: =(G62+H64)/(1+G63) -> 54617.882 | H64: =(H62+I64)/(1+H63) -> 46208.72 | I64: =I62/(I63-I35) -> 47527.517
C65: D boy | D65: =D39 -> 2500 | E65: =E39 -> 7800 | F65: =F39 -> 13250 | G65: =G39 -> 19664.4 | H65: =H39 -> 30805.814 | I65: =I39 -> 31685.012
...

Sheet Task 3
B2: Date | C2: =+Admin!D12 -> 45308
B3: Student name | C3: =+Admin!D13 -> 0
B4: Neptun code | C4: =+Admin!D14 -> 0
B6: Study program | C6: =+Admin!D16 -> Master in Finance
B7: Instructor | C7: =+Admin!D17 -> Péter Juhász, PhD, CFA
B9: Points achived:
B23: P/E | C23: =C51/C57 -> 12.307692
B24: P/BV | C24: =C53/C46 -> 1.8823529
B25: P/S | C25: =C53/C31 -> 0.64
B26: EV/EBITDA | C26: =(C55-C38)/(C33) -> 13.25
B27: EV/tBV | C27: =(C55-C38)/C58 -> 1.7966102
B30: P/L
B31: Revenue from Sales | C31: 10000000
B32: D&A | C32: 600000
B33: Operational profit | C33: 800000
B34: Profit before tax | C34: 700000
B35: After tax profit | C35: 520000
B37: Balance sheet
B38: Cash | C38: 200000
B39: Receivables | C39: 800000
B40: Inventory | C40: 500000
B41: PP&E | C41: 4000000
B42: Goodwill | C42: 400000
B44: Payables | C44: 500000
B45: Debt (Bonds only) | C45: 2000000
B46: Equity | C46: =SUM(C38:C42)-C44-C45 -> 3400000
B48: Number of bonds | C48: 100000
B49: Closing price of bonds | C49: 24
B50: Number of shares | C50: 2000000
B51: Closing price of shares | C51: 3.2
B53: Equity Market Value | C53: =C50*C51 -> 6400000
B54: Debt Market Value | C54: =C45+C48*C49 -> 4400000
B55: Enterprise Value | C55: =C53+C54 -> 10800000
B57: E | C57: =C35/C50 -> 0.26
B58: IC | C58: =SUM(C44:C46) -> 5900000

Sheet Task 4
B2: Date | C2: =+Admin!D12 -> 45308
B3: Student name | C3: =+Admin!D13 -> 0
B4: Neptun code | C4: =+Admin!D14 -> 0
B6: Study program | C6: =+Admin!D16 -> Master in Finance
B7: Instructor | C7: =+Admin!D17 -> Péter Juhász, PhD, CFA
B9: Points achived:
D20: Today
C21: Book value of equity | D21: 500
C22: Book value of debt | D22: 0
C24: Venture capital contribution | D24: 200
D26: in 8 years time
C27: Debt | D27: 500
C28: rD | D28: 0.05
C29: IC boy | D29: 1500
C30: ROIC | D30: 0.2
C31: Expected EBIT multiple | D31: 20

Sheet Task 4 Sol
B2: Date | C2: =+Admin!D12 -> 45308
B3: Student name | C3: =+Admin!D13 -> 0
B4: Neptun code | C4: =+Admin!D14 -> 0
B6: Study program | C6: =+Admin!D16 -> Master in Finance
B7: Instructor | C7: =+Admin!D17 -> Péter Juhász, PhD, CFA
B9: Points achived:
D20: Today
C21: Book value of equity | D21: 500
C22: Book value of debt | D22: 0
C24: Venture capital contribution | D24: 200
D26: in 8 years time
C27: Debt | D27: 500
C28: rD | D28: 0.05
C29: IC boy | D29: 1500
C30: ROIC | D30: 0.2
C31: Expected EBIT multiple | D31: 20
B33: rFinancing | C33: 0.2
B37: rReinvestment | C37: 0.07
B41: rFinancing | C41: 0.2
N42: Investment sum | O42: Year | P42: Dependance on success
B43: Today | J43: In 8 years | M43: Owner= founders | N43: =C46 -> 200 | O43: 0 | P43: Nope
B44: Total IC | C44: =C46+C49 -> 400 | M44: PE1 = First Invesor | N44: =C49 -> 200 | O44: 0 | P44: Nope
F45: Success (Business will continue) | J45: Success (Business will be sold) | M45: PE2 = 2nd Investor= Loan providor | N45: =G48 -> 100 | O45: 2 | P45: Only in case of the succes in the first 2 years
B46: Equity - Initial | C46: 200
E47: 3) | F47: Equity - Pre Money Value | G47: =G49-G48 -> 119.91519 | J47: Value (Sales Price) | K47: 1500 | M47: Steps
A48: 5) | B48: Equity - Pre Money Value | C48: =C50-C49 -> -143.76563 | F48: Additional IC 2 | G48: 100 | J48: Debt | K48: 500 | M48: 1. Fill out the investments in the noted terms
B49: Additional IC 1 | C49: 200 | E49: 2) | F49: Equity - Post Money Value | G49: =K49/(1+C65)^4 -> 219.91519 | I49: 1) | J49: Equity | K49: =K47-K48 -> 1000 | M49: 2. Put a random PE-1 stake - will use solver later on
A50: 4) | B50: Equity - Post Money Value | C50: =G47/(1+C65)^2 -> 56.234365 | M50: 3.Founder stake 1-PE 1 Stake
F51: PE-2 Stake | G51: =G48/G49 -> 0.45472076 | J51: PE-2 Stake | K51: =G51 -> 0.45472076 | M51: 4. Go to part 6, calculated Liquidation value
F52: Others Stake | G52: =1-G51 -> 0.54527924 | J52: PE-1 Stake | K52: =G53 -> 0.29647049 | M52: 5. Calculated cash inflow for founders and PE 1
F53: >> PE-1 Stake | G53: =C55*G52 -> 0.29647049 | J53: Founders Stake | K53: =G54 -> 0.24880875 | M53: 6. Founder and PE1 invest those inflows, for the next 4 years, calc. FV of their investment
B54: Founders Stake | C54: =1-C55 -> 0.45629602 | F54: >> Founders Stake | G54: =C54*G52 -> 0.24880875 | M54: 7. Goto part 8- Return = FV of PE1 cashflow/Initial investment of PE1^(1/number of years=6)-1
B55: PE-1 Stake | C55: 0.54370398 | F55: Check Total Stakes | G55: =G51+G53+G54 -> 1 | J55: Founders CashInflow after Sale | K55: =+K49*K53 -> 248.80875 | M55: 8. Calc. Yearly returnof success - (1+rfin)^t=Prob fail *(1+r fail)^t+Prob success*(1+rsuccess)^t
B56: PE-1 Stake (Calculated) | C56: =C49/C50 -> 3.5565441 | J56: Founders Yearly Return | K56: =+(K55/C48)^(1/6)-1 -> #NUM! | M56: 9. Go to part 2 - Calc Equity value in year 2 after loan investment=Equity year 6, discounted with yearly return on succes (4 years horizon)
A57: 10) | B57: Diff | C57: =C55-C56 -> -3.0128401 | M57: 10. Calculated pre- money (before loan) eqity = Post money equity - PE2 additional IC (loan)
M58: 11. PE 2 stake= PE2 additional IC (loan)/ Post money equity value in year 2
F59: Failure (Business is liquidited) | J59: Failure (Money from Liquidition was reinvested) | M59: 12. Other stake 1- PE2 stake
M60: 13. PE1 Stake = PE 1 Stake from Year=0 (which was put randomly)* others stake value
B61: Investment horizon | C61: 8 | F61: Liquidition Ratio | G61: 0.9 | J61: rReinvestment | K61: 0.07 | M61: 14. Founder Stake =Founders stake from Year=0 (which was put randomly)* others stake value
B62: Chance of failure | C62: 0.65 | E62: 6) | F62: Liquidition Value | G62: =C44*G61 -> 360 | J62: Liquidition Value | K62: =G62*(1+K61)^4 -> 471.88656 | M62: 15. Go to part 2 - Calc Equity value today (year=0) after PE 1 =Equity value year 2 (post money), discounted with yearly return on succes (2 years horizon)
...

Sheet Task 5
B2: =+Admin!C12 -> Date | C2: =+Admin!D12 -> 45308
B3: =+Admin!C13 -> Student name | C3: =+Admin!D13 -> 0
B4: =+Admin!C14 -> Neptun code | C4: =+Admin!D14 -> 0
B6: =+Admin!C16 -> Study program | C6: =+Admin!D16 -> Master in Finance
B7: =+Admin!C17 -> Instructor | C7: =+Admin!D17 -> Péter Juhász, PhD, CFA
B9: Points achived:
