Workbook
Name lista: OFFSET([1]DinamicValidation!$B$4,0,0,COUNTA([1]DinamicValidation!$B$4:$B$1048576),1)

Sheet OpeningPage

Sheet Admin
C9: Applied Business Valuation
C12: Date | D12: 45294
C13: Student name | I13: Master in Finance
C14: Neptun code | I14: Master in Accounting
C16: Study program | D16: Master in Finance
C17: Instructor | D17: Péter Juhász, PhD, CFA
C20: Total points achieved | D20: =+Theory!C9+PE!C9+'Theory 2'!C9+'M&A'!C9+DCF!C9 -> 0

Sheet M&A
B2: =+Admin!C12 -> Date | C2: =+Admin!D12 -> 45294
B3: =+Admin!C13 -> Student name | C3: =+Admin!D13 -> 0
B4: =+Admin!C14 -> Neptun code | C4: =+Admin!D14 -> 0
B6: =+Admin!C16 -> Study program | C6: =+Admin!D16 -> Master in Finance
B7: =+Admin!C17 -> Instructor | C7: =+Admin!D17 -> Péter Juhász, PhD, CFA
B9: Points achived:
D26: Firm A | E26: Firm B | F26: Together
C27: number of shares | D27: 2000000 | E27: 4000000
C28: t | D28: 0.2 | E28: 0.2 | F28: 0.2
C29: rA | D29: 0.12 | E29: 0.12 | F29: 0.12
C30: g | D30: 0.03 | E30: 0.04 | F30: 0.0325
C31: rD | D31: 0.06 | E31: 0.06 | F31: 0.06
C32: D/V | D32: 0.3 | E32: 0.2 | F32: 0.3
C33: FCFF (M HUF) | D33: 500 | F33: 710
C34: FCFE (M HUF) | E34: 150
C35: E/V | E35: =1-E32 -> 0.8
B37: (rA-rD*D/V)/(1-D/V) | C37: rE | D37: =(D29-D31*D32)/(1-D32) -> 0.14571429 | E37: =(E29-E31*E32)/(1-E32) -> 0.135 | F37: =(F29-F31*F32)/(1-F32) -> 0.14571429
B39: rA-D/V*rD*t | C39: WACC | D39: =D29-D31*D32*D28 -> 0.1164 | E39: =E29-E31*E32*E28 -> 0.1176 | F39: =F29-F31*F32*F28 -> 0.1164
H40: Without synergy | I40: Synergy
B41: FCFF/(wacc-g) OR E/(E/V) | C41: V | D41: =D33/(D39-D30) -> 5787.037 | E41: =E43/E35 -> 1973.6842 | F41: =F33/(F39-F30) -> 8462.4553 | H41: =D41+E41 -> 7760.7212 | I41: =F41-H41 -> 701.73406
C42: D | D42: =D41*D32 -> 1736.1111 | E42: =E41*E32 -> 394.73684 | F42: =F41*F32 -> 2538.7366 | H42: =D42+E42 -> 2130.848
C43: E | D43: =D41-D42 -> 4050.9259 | E43: =E34/(E37-E30) -> 1578.9474 | F43: =F41-F42 -> 5923.7187 | H43: =D43+E43 -> 5629.8733
D45: base | E45: transaction cost (M HUF) | F45: Bargaining range
C46: Min | D46: =E43 -> 1578.9474 | E46: 4 | F46: =D46+E46 -> 1582.9474
C47: Max | D47: =D46+I41 -> 2280.6814 | E47: 8 | F47: =D47-E47 -> 2272.6814
B53: Max price | C53: =F46*(1+25%) -> 1978.6842
B55: Non-operational cash available to A | C55: =C53*30% -> 593.60526
B56: Ownership passed over to B | C56: =C53-C55 -> 1385.0789
B57: Ownership stake for B (in % of merged firm E) | C57: =+C56/F43 -> 0.23381916
B59: Number of initial shares (A + B) | C59: =D27+E27 -> 6000000
B60: == Equivalent to ownership of A (in % of the merged firm E) | C60: =1-C57 -> 0.76618084
B62: Number of new shares to be issued for B | C62: =C59/C60*C57 -> 1831049.4
B64: Total Number of shares (post-merger) | C64: =C62+C59 -> 7831049.4
B65: A stake | C65: =C64*C60 -> 6000000
B66: B stake | C66: =C64*C57 -> 1831049.4
B68: Exchange rate | C68: =C64/C59 -> 1.3051749

Sheet DCF
B2: =+Admin!C12 -> Date | C2: =+Admin!D12 -> 45294
B3: =+Admin!C13 -> Student name | C3: =+Admin!D13 -> 0
B4: =+Admin!C14 -> Neptun code | C4: =+Admin!D14 -> 0
B6: =+Admin!C16 -> Study program | C6: =+Admin!D16 -> Master in Finance
B7: =+Admin!C17 -> Instructor | C7: =+Admin!D17 -> Péter Juhász, PhD, CFA
B9: Points achived:
D24: 2024 | E24: =+D24+1 -> 2025 | F24: =+E24+1 -> 2026 | G24: =+F24+1 -> 2027 | H24: =+G24+1 -> 2028 | I24: TV
C25: g TV period | I25: 0.06
C26: t | D26: 0.15 | E26: 0.15 | F26: 0.15 | G26: 0.15 | H26: 0.15 | I26: 0.15
C27: rA | D27: 0.12 | E27: 0.12 | F27: 0.12 | G27: 0.12 | H27: 0.12 | I27: 0.12
C28: rD | D28: 0.06 | E28: 0.06 | F28: 0.065 | G28: 0.07 | H28: 0.073 | I28: 0.073
C29: D/V boy | D29: =+D39/D59 -> 0.029221703 | E29: =+E39/E59 -> 0.090637461 | F29: =+F39/F59 -> 0.14970657 | G29: =+G39/G59 -> 0.21077396 | H29: =+H39/H59 -> 0.24343437 | I29: 0.4
C30: D/IC boy | D30: 0.05 | E30: 0.15 | F30: 0.25 | G30: 0.35 | H30: 0.4
C31: dIC | D31: 2000
C32: K | E32: 0.6 | F32: 0.4 | G32: 0.3 | H32: 0.25 | I32: =I25/I33 -> 0.51894136
C33: RONIC | F33: 0.15 | G33: 0.14 | H33: 0.13 | I33: =I37 -> 0.11562
C34: ROIC | D34: 0.13 | E34: 0.13
C35: IC boy | D35: 10000
C37: Wacc | D37: =+D27-D28*D26*D29 -> 0.119737 | E37: =+E27-E28*E26*E29 -> 0.11918426 | F37: =+F27-F28*F26*F29 -> 0.11854036 | G37: =+G27-G28*G26*G29 -> 0.11778687 | H37: =+H27-H28*H26*H29 -> 0.11733439 | I37: =+I27-I28*I26*I29 -> 0.11562
C38: IC boy | D38: =D35 -> 10000 | E38: =+D38+D44 -> 12000 | F38: =+E38+E44 -> 12936 | G38: =+F38+F44 -> 13784.64 | H38: =+G38+G44 -> 14522.957 | I38: =+H38+H44 -> 15193.595
C39: Debt boy | D39: =+D30*D38 -> 500 | E39: =+E30*E38 -> 1800 | F39: =+F30*F38 -> 3234 | G39: =+G30*G38 -> 4824.624 | H39: =+H30*H38 -> 5809.1827 | I39: =+I29*I54 -> 9860.614 | J39: =+I39*(1+I25) -> 10452.251
C40: BV Equity boy | D40: =+D38-D39 -> 9500 | E40: =+E38-E39 -> 10200 | F40: =+F38-F39 -> 9702 | G40: =+G38-G39 -> 8960.016 | H40: =+H38-H39 -> 8713.7741 | I40: =+I38-I39 -> 5332.9805
C43: Noplat | D43: =D38*D34 -> 1300 | E43: =+E38*E34 -> 1560 | F43: =+E43+E44*E32 -> 2121.6 | G43: =+F43+F44*F32 -> 2461.056 | H43: =+G43+G44*G32 -> 2682.551 | I43: =+H43+H44*H32 -> 2850.2105
C44: dIC | D44: =+D31 -> 2000 | E44: =+E43*E32 -> 936 | F44: =+F43*F32 -> 848.64 | G44: =+G43*G32 -> 738.3168 | H44: =+H43*H32 -> 670.63776 | I44: =+I43*I32 -> 1479.0921
C45: FCFF | D45: =+D43-D44 -> -700 | E45: =+E43-E44 -> 624 | F45: =+F43-F44 -> 1272.96 | G45: =+G43-G44 -> 1722.7392 | H45: =+H43-H44 -> 2011.9133 | I45: =+I43-I44 -> 1371.1184
C46: Interest | D46: =+D39*D28 -> 30 | E46: =+E39*E28 -> 108 | F46: =+F39*F28 -> 210.21 | G46: =+G39*G28 -> 337.72368 | H46: =+H39*H28 -> 424.07034 | I46: =+I39*I28 -> 719.82482
C47: Tax shield | D47: =+D46*D26 -> 4.5 | E47: =+E46*E26 -> 16.2 | F47: =+F46*F26 -> 31.5315 | G47: =+G46*G26 -> 50.658552 | H47: =+H46*H26 -> 63.610551 | I47: =+I46*I26 -> 107.97372
C48: d Debt | D48: =+E39-D39 -> 1300 | E48: =+F39-E39 -> 1434 | F48: =+G39-F39 -> 1590.624 | G48: =+H39-G39 -> 984.55872 | H48: =+I39-H39 -> 4051.4313 | I48: =+J39-I39 -> 591.63684
C49: FCFE | D49: =+D45-D46+D47+D48 -> 574.5 | E49: =+E45-E46+E47+E48 -> 1966.2 | F49: =+F45-F46+F47+F48 -> 2684.9055 | G49: =+G45-G46+G47+G48 -> 2420.2328 | H49: =+H45-H46+H47+H48 -> 5702.8848 | I49: =+I45-I46+I47+I48 -> 1350.9041
C52: FCFF | D52: =+D45 -> -700 | E52: =+E45 -> 624 | F52: =+F45 -> 1272.96 | G52: =+G45 -> 1722.7392 | H52: =+H45 -> 2011.9133 | I52: =+I45 -> 1371.1184
C53: WACC | D53: =+D37 -> 0.119737 | E53: =+E37 -> 0.11918426 | F53: =+F37 -> 0.11854036 | G53: =+G37 -> 0.11778687 | H53: =+H37 -> 0.11733439 | I53: =+I37 -> 0.11562
C54: V boy | D54: =+(D52+E54)/(1+D53) -> 17110.57 | E54: =+(E52+F54)/(1+E53) -> 19859.338 | F54: =+(F52+G54)/(1+F53) -> 21602.259 | G54: =+(G52+H54)/(1+G53) -> 22890.039 | H54: =+(H52+I54)/(1+H53) -> 23863.445 | I54: =+(I52)/(I53-I25) -> 24651.535
C57: FCFF+TS | D57: =+D45+D47 -> -695.5 | E57: =+E45+E47 -> 640.2 | F57: =+F45+F47 -> 1304.4915 | G57: =+G45+G47 -> 1773.3978 | H57: =+H45+H47 -> 2075.5238 | I57: =+I45+I47 -> 1479.0921
C58: rA | D58: =+D27 -> 0.12 | E58: =+E27 -> 0.12 | F58: =+F27 -> 0.12 | G58: =+G27 -> 0.12 | H58: =+H27 -> 0.12 | I58: =+I27 -> 0.12
C59: V boy | D59: =+(D57+E59)/(1+D58) -> 17110.57 | E59: =+(E57+F59)/(1+E58) -> 19859.338 | F59: =+(F57+G59)/(1+F58) -> 21602.259 | G59: =+(G57+H59)/(1+G58) -> 22890.039 | H59: =+(H57+I59)/(1+H58) -> 23863.445 | I59: =+(I57)/(I58-I25) -> 24651.535
C60: check | D60: =+D54-D59 -> 0 | E60: =+E54-E59 -> 0 | F60: =+F54-F59 -> 0 | G60: =+G54-G59 -> 0 | H60: =+H54-H59 -> 0 | I60: =+I54-I59 -> 0
C62: FCFE | D62: =+D49 -> 574.5 | E62: =+E49 -> 1966.2 | F62: =+F49 -> 2684.9055 | G62: =+G49 -> 2420.2328 | H62: =+H49 -> 5702.8848 | I62: =+I49 -> 1350.9041
C63: rE | D63: =(D27-D29*D28)/(1-D29) -> 0.12180608 | E63: =(E27-E29*E28)/(1-E29) -> 0.12598029 | F63: =(F27-F29*F28)/(1-F29) -> 0.12968355 | G63: =(G27-G29*G28)/(1-G29) -> 0.13335321 | H63: =(H27-H29*H28)/(1-H29) -> 0.13512283 | I63: =(I27-I29*I28)/(1-I29) -> 0.15133333
C64: E boy | D64: =+(D62+E64)/(1+D63) -> 16610.57 | E64: =+(E62+F64)/(1+E63) -> 18059.338 | F64: =+(F62+G64)/(1+F63) -> 18368.259 | G64: =+(G62+H64)/(1+G63) -> 18065.415 | H64: =+(H62+I64)/(1+H63) -> 18054.263 | I64: =+(I62)/(I63-I25) -> 14790.921
C65: D boy | D65: =+D39 -> 500 | E65: =+E39 -> 1800 | F65: =+F39 -> 3234 | G65: =+G39 -> 4824.624 | H65: =+H39 -> 5809.1827 | I65: =+I39 -> 9860.614
...

Sheet PE
B2: Date | C2: =+Admin!D12 -> 45294
B3: Student name | C3: =+Admin!D13 -> 0
B4: Neptun code | C4: =+Admin!D14 -> 0
B6: Study program | C6: =+Admin!D16 -> Master in Finance
B7: Instructor | C7: =+Admin!D17 -> Péter Juhász, PhD, CFA
B9: Points achived:
D20: Today
C21: Book value of equity (M) | D21: 200
C22: Book value of debt (M) | D22: 0 | F22: Solution is on next worksheet
C24: Venture capital contribution (M) | D24: 200
D26: in 3 years time
C27: Venture capital contribution (M) | D27: 300
D29: in 8 years time
C30: Expected Debt (M) | D30: 500
C31: Expected Sales multiple | D31: 4
C32: Expected Sales (M) | D32: 1500

Sheet PE Sol
O4: (1+rFIN)^t=Prob.fail*(1+rFAIL)^t+Prob.success*(1+rSUCCESS)^t
B5: rFinancing | C5: 0.2
B9: rReinvestment | C9: 0.09
P12: Today
O13: Book value of equity (M) | P13: 200
O14: Book value of debt (M) | P14: 0
O16: Venture capital contribution (M) | P16: 200
P18: in 3 years time
O19: Venture capital contribution (M) | P19: 300
F20: Post money value of E | G20: =L24/(1+C36)^5 -> 1096.5481
C21: Today | G21: In 3 years | L21: In 8 years | P21: in 8 years time
B22: Equity | C22: 200 | F22: Capital increase 2 | G22: 300 | K22: Sales price (V) | L22: =1500*4 -> 6000 | O22: Expected Debt (M) | P22: 500
B23: Pre money value | C23: =C26-C24 -> 102.69901 | F23: Pre money value | G23: =+G20-G22 -> 796.5481 | K23: D | L23: 500 | O23: Expected Sales multiple | P23: 4
B24: Capital increase 1 | C24: 200 | F24: Bank loan | G24: 0 | K24: E | L24: =L22-L23 -> 5500 | O24: Expected Sales (M) | P24: 1500
B25: Total investment (IC) | C25: =C22+C24 -> 400 | F25: PE stake (year 3) | G25: =+G22/G20 -> 0.27358581 | H25: % of owner who invested in year 2 | K25: PE stake altogether | L25: =+L26+L27 -> 0.58836516
B26: Post money value | C26: =+G23/(1+C36)^3 -> 302.69901 | E26: 0.25 | F26: 1-PE | G26: =1-G25 -> 0.72641419 | K26: PE stake (year 3) | L26: =G25 -> 0.27358581
F27: PE stake (taking year 1 into consideration) | G27: =G26*C28 -> 0.31477935 | H27: % of owner who invested in year 1 | K27: PE stake (taking year 1 into consideration) | L27: =G27 -> 0.31477935
B28: PE (private equity firm) stake (we guess with a random number and then use solver) | C28: 0.43333315 | F28: Founders stake | G28: =C31*G26 -> 0.41163484 | H28: % of founders | K28: Founders stake | L28: =G28 -> 0.41163484
B29: PE stake guess - market base | C29: 0.43333215
B30: diff | C30: =C29-C28 -> -1e-06 | E30: 0.75 | F30: Liquidation ratio | G30: 0 | K30: Total value with reinvestment in case of failure | L30: =G31*(1+C9)^5 -> 615.44958
B31: Founders stake | C31: =1-C28 -> 0.56666685 | F31: Liquidation | G31: =+P16+P13 -> 400 | K31: PE value out of total | L31: =G32*(1+C9)^5 -> 266.69471
B32: Investment horizon | C32: 8 | D32: years | F32: Inflow for PE | G32: =+C28*G31 -> 173.33326
B33: Chance of failure | C33: 0.75 | F33: Inflow for founders | G33: =G31-G32 -> 226.66674 | K33: Founders cash inflow | L33: =+L24*L28 -> 2263.9916
B34: Yearly return of failure | C34: =+(L31/C24)^(1/8)-1 -> 0.036628274 | F34: founders yearly return | G34: =(G33/C23)^(1/3)-1 -> 0.30198858 | K34: Founders yearly return | L34: =(L33/C23)^(1/8)-1 -> 0.47201951
B35: Chance of success | C35: 0.25
B36: Yearly return of success | C36: =(((1+C5)^C32-C33*(1+C34)^C32)/C35)^(1/C32)-1 -> 0.38059724
F40: Post money value of E | G40: =L44/(1+C56)^5 -> 1226.5743
C41: Today | G41: In 3 years | L41: In 8 years
B42: Equity | C42: 200 | F42: Capital increase 2 | G42: 300 | K42: Sales price (V) | L42: =1500*4 -> 6000
B43: Pre money value | C43: =C46-C44 -> 176.5988 | F43: Pre money value | G43: =+G40-G42 -> 926.57426 | K43: D | L43: 500
B44: Capital increase 1 | C44: 200 | F44: Bank loan | G44: 0 | K44: E | L44: =L42-L43 -> 5500
B45: Total investment (IC) | C45: =C42+C44 -> 400 | F45: PE stake (year 3) | G45: =+G42/G40 -> 0.24458364 | H45: % of owner who invested in year 2 | K45: PE stake altogether if we assume req. Rate of return is 35% for success case | L45: =+L46+L47 -> 0.64576272
B46: Post money value | C46: =+G43/(1+C56)^3 -> 376.5988 | E46: 0.25 | F46: 1-PE | G46: =1-G45 -> 0.75541636 | K46: PE stake (year 3) | L46: =G45 -> 0.24458364
F47: PE stake (taking year 1 into consideration) | G47: =G46*C48 -> 0.40117907 | H47: % of owner who invested in year 1 | K47: PE stake (taking year 1 into consideration) | L47: =G47 -> 0.40117907
B48: PE (private equity firm) stake (we guess with a random number and then use solver) | C48: 0.53107014 | F48: Founders stake | G48: =C51*G46 -> 0.35423728 | H48: % of founders | K48: Founders stake | L48: =G48 -> 0.35423728
B49: PE stake guess - market base | C49: =C44/C46 -> 0.53106914
B50: diff | C50: =C49-C48 -> -1e-06 | E50: 0.75 | F50: Liquidation ratio | G50: 0 | K50: Total value with reinvestment in case of failure | L50: =G51*(1+C9)^5 -> 1077.0368
B51: Founders stake | C51: =1-C48 -> 0.46892986 | F51: Liquidation | G51: =+P19+P16+P13 -> 700 | K51: PE value out of total | L51: =G52*(1+C9)^5 -> 571.98207
B52: Investment horizon | C52: 8 | D52: years | F52: Inflow for PE | G52: =+C48*G51 -> 371.7491
B53: Chance of failure | C53: 0.75 | F53: Inflow for founders | G53: =G51-G52 -> 328.2509 | K53: Founders cash inflow | L53: =+L44*L48 -> 1948.3051
...

Sheet Theory
B2: =+[2]Admin!C12 -> Date | C2: =+Admin!D12 -> 45294
B3: =+[2]Admin!C13 -> Student name | C3: =+Admin!D13 -> 0
B4: =+[2]Admin!C14 -> Neptun code | C4: =+Admin!D14 -> 0
B6: =+[2]Admin!C16 -> Study program | C6: =+Admin!D16 -> Master in Finance
B7: =+[2]Admin!C17 -> Instructor | C7: =+Admin!D17 -> Péter Juhász, PhD, CFA
B9: Points achived:
J19: dcf | K19: 1200 | L19: 1400
J20: mm | K20: 900 | L20: 1100
J21: Ct | K21: 1000 | L21: 1200
J22: AB | K22: 600 | L22: 800

Sheet Theory 2
B2: =+Admin!C12 -> Date | C2: =+Admin!D12 -> 45294
B3: =+Admin!C13 -> Student name | C3: =+Admin!D13 -> 0
B4: =+Admin!C14 -> Neptun code | C4: =+Admin!D14 -> 0
B6: =+Admin!C16 -> Study program | C6: =+Admin!D16 -> Master in Finance
B7: =+Admin!C17 -> Instructor | C7: =+Admin!D17 -> Péter Juhász, PhD, CFA
B9: Points achived:
