Workbook

Sheet Assumptions
A1: Macro assumptions
A3: General | B3: 2024 | C3: =+B3+1 -> 2025 | D3: =+C3+1 -> 2026 | E3: =+D3+1 -> 2027 | F3: =+E3+1 -> 2028 | G3: TV
A4: Inflation (Hungary)
A5: Inflation (Slovakia)
A6: Corporate Tax
A7: Wage contribution
A8: Number of months | B8: 12 | C8: 12 | D8: 12 | E8: 12 | F8: 12 | G8: 12
A10: Assumptions for the balance sheet & income statement
A12: Number of days | B12: =B3 -> 2024 | C12: =+C3 -> 2025 | D12: =+D3 -> 2026 | E12: =+E3 -> 2027 | F12: =+F3 -> 2028 | G12: =+G3 -> TV
A13: Accounts receivables days | B13: 30 | C13: 30 | D13: 30 | E13: 30 | F13: 30
A14: Accounts receivables
A16: Accounts payables days | B16: 30 | C16: 30 | D16: 30 | E16: 30 | F16: 30
A17: Accounts payables
A19: Inventory days | B19: 45 | C19: 45 | D19: 45 | E19: 45 | F19: 45
A20: Inventory
A23: Debt | B23: =+B12 -> 2024 | C23: =+C12 -> 2025 | D23: =+D12 -> 2026 | E23: =+E12 -> 2027 | F23: =+F12 -> 2028 | G23: =+G12 -> TV
A24: Cost of debt | B24: 0.15 | C24: 0.12 | D24: 0.09 | E24: =+D24 -> 0.09 | F24: =+E24 -> 0.09 | G24: =+F24 -> 0.09
A27: Debit | B27: =B3 -> 2024 | C27: =+C23 -> 2025 | D27: =+D23 -> 2026 | E27: =+E23 -> 2027 | F27: =+F23 -> 2028 | G27: =G23 -> TV
A28: debit interest rate | B28: 0.0025 | C28: =+B28 -> 0.0025 | D28: =+C28 -> 0.0025 | E28: =+D28 -> 0.0025 | F28: =+E28 -> 0.0025 | G28: =+F28 -> 0.0025
A31: Costs | B31: =B3 -> 2024
A32: Monthly operating costs | B32: 700
A33: Monthly rent | B33: 6000
A35: Growth | B35: =B3 -> 2024 | C35: =C3 -> 2025 | D35: =D3 -> 2026 | E35: =E3 -> 2027 | F35: =F3 -> 2028
A36: paprika | C36: 0.25 | D36: 0.2 | E36: 0.12 | F36: 0.05
A37: pepper | C37: 0.25 | D37: 0.15 | E37: 0.08 | F37: 0.05
A38: herbs | C38: 0.2 | D38: 0.1 | E38: 0.05 | F38: 0.03
A39: export | C39: 0.1 | D39: 0.08 | E39: 0.06 | F39: 0.04
A41: net investment in the ratio of the sales | C41: 0.02 | D41: 0.02 | E41: 0.02 | F41: 0.02
A43: Depreciation & amortization | B43: =B3 -> 2024 | C43: =C3 -> 2025 | D43: =D3 -> 2026 | E43: =E3 -> 2027 | F43: =F3 -> 2028
A44: DD&A | B44: 0.05 | C44: 0.05 | D44: 0.05 | E44: 0.05 | F44: 0.05
A46: Wages | B46: =B3 -> 2024 | C46: =C3 -> 2025 | D46: =D3 -> 2026 | E46: =E3 -> 2027 | F46: =F3 -> 2028 | G46: =G3 -> TV
A47: one month wage | B47: 3200
A48: New employees gross wage per month | B48: 232
A49: new employers capacity in sales | B49: 45000
A51: Premium over COGS (per ton) | B51: =B46 -> 2024
A52: paprika | B52: 525
A53: pepper | B53: 500
A54: herbs | B54: 450
A55: export (paprika) | B55: =B52*1.2 -> 630
A57: Sales (ton) | B57: =B51 -> 2024
...

Sheet Business plan
B2: Income Statement | C2: eFT
C3: =Assumptions!B3 -> 2024 | D3: =Assumptions!C3 -> 2025 | E3: =Assumptions!D3 -> 2026 | F3: =Assumptions!E3 -> 2027 | G3: =Assumptions!F3 -> 2028
B4: Net sales
B5: Cost of sales
B6: Gross profit
B7: Selling, general and administrative
B8: operating costs
B9: wages
B10: wage contribution
B11: Increase in the number of employees compared to 2023 | J11: Sales (ton)
B12: Research and development | J12: Sales (ton) | K12: =C3 -> 2024 | L12: =D3 -> 2025 | M12: =E3 -> 2026 | N12: =F3 -> 2027 | O12: =G3 -> 2028
B13: Depreciation & Amortization | C13: 33000 | J13: paprika | K13: =Assumptions!B58 -> 180 | L13: … | M13: … | N13: … | O13: …
B14: Operating income | J14: pepper | K14: =Assumptions!B59 -> 55 | L14: … | M14: … | N14: … | O14: …
B15: Other income/expenses | J15: herbs | K15: =Assumptions!B60 -> 37 | L15: … | M15: … | N15: … | O15: …
B16: Earning before interest and taxes | J16: export paprika | K16: =Assumptions!B61 -> 110 | L16: … | M16: … | N16: … | O16: …
B17: Interest income | C17: 3000
B18: interest expense | C18: 40000 | J18: Cost of sales/ton
B19: Pretax income | J19: paprika | K19: =Assumptions!B64 -> 1352 | L19: … | M19: … | N19: … | O19: …
B20: Taxes | J20: pepper | K20: =Assumptions!B65 -> 1361 | L20: … | M20: … | N20: … | O20: …
B21: Net income | J21: herbs | K21: =Assumptions!B66 -> 1487 | L21: … | M21: … | N21: … | O21: …
J22: export paprika | K22: =Assumptions!B67 -> 1352 | L22: … | M22: … | N22: … | O22: …
B24: Dividend | C24: =C21-C25 -> 0 | D24: =D21-D25 -> 0 | E24: =E21-E25 -> 0 | F24: =F21-F25 -> 0 | G24: =G21-G25 -> 0 | J24: Net sales/ton
B25: Retained earning | C25: =IF(C21<0,C21,MAX(0,MIN(C27,C21))) -> 0 | D25: =IF(D21<0,D21,MAX(0,MIN(D27,D21))) -> 0 | E25: =IF(E21<0,E21,MAX(0,MIN(E27,E21))) -> 0 | F25: =IF(F21<0,F21,MAX(0,MIN(F27,F21))) -> 0 | G25: =IF(G21<0,G21,MAX(0,MIN(G27,G21))) -> 0 | J25: paprika | K25: … | L25: … | M25: … | N25: … | O25: …
J26: pepper | K26: … | L26: … | M26: … | N26: … | O26: …
B27: Stockholders' equity change needed | C27: =C45-C46-C49 -> -560000 | D27: =D45-C45 -> 0 | E27: =E45-D45 -> 0 | F27: =F45-E45 -> 0 | G27: =G45-F45 -> 0 | J27: herbs | K27: … | L27: … | M27: … | N27: … | O27: …
B28: Common stock repurchase/issue | C28: =C27-C25 -> -560000 | D28: =D27-D25 -> 0 | E28: =E27-E25 -> 0 | F28: =F27-F25 -> 0 | G28: =G27-G25 -> 0 | J28: export paprika | K28: … | L28: … | M28: … | N28: … | O28: …
J29: Net sales - Hungary | K29: … | L29: … | M29: … | N29: … | O29: …
B30: Balance sheet | C30: eFt | E30: eFt | J30: Net sales - Slovakia | K30: … | L30: … | M30: … | N30: … | O30: …
C31: =+C3 -> 2024 | D31: =+D3 -> 2025 | E31: =+E3 -> 2026 | F31: =+F3 -> 2027 | G31: =+G3 -> 2028 | J31: Cost of sales - Hungary | K31: … | L31: … | M31: … | N31: … | O31: …
B32: Current assets | J32: Cost of sales - Slovakia | K32: … | L32: … | M32: … | N32: … | O32: …
B33: Cash (operation)
B34: Accounts receivables
B35: Inventories
B36: Long-term assets
B37: Intangible assets | C37: 80000
B38: Net property land and equipement | C38: 663468
B39: Total assets | C39: =+C32+C36 -> 0 | D39: =+D32+D36 -> 0 | E39: =+E32+E36 -> 0 | F39: =+F32+F36 -> 0 | G39: =+G32+G36 -> 0
B40: Current liablities
B41: Accounts payables
B42: Notes payable/short-term debt
...
