Workbook

Sheet WhichIsBetter
G4: NPV | H4: PI
D5: V | E5: E | F5: BV E | G5: SVA | H5: SVA/BV E
C6: ModelAStandard | D6: =+ModelAStandard!C95 -> 33295.68 | E6: =+ModelAStandard!C93 -> 25057.285 | F6: =+ModelAStandard!C52 -> 12000 | G6: =+E6-F6 -> 13057.285 | H6: =+G6/F6 -> 1.0881071
C7: ModelAFairValue | D7: =+ModelAFairValue!C95 -> 33295.68 | E7: =+ModelAFairValue!$C$93 -> 25057.285 | F7: =+ModelAFairValue!$C$52 -> 11761.605 | G7: =+E7-F7 -> 13295.68 | H7: =+G7/F7 -> 1.1304307
C8: ModelBStandard | D8: =+ModelBStandard!C97 -> 33258.012 | E8: =+ModelBFair!C95 -> 24976.854 | F8: =+ModelBStandard!C53 -> 11030 | G8: =+E8-F8 -> 13946.854 | H8: =+G8/F8 -> 1.2644473
C9: ModelBFair | D9: =+ModelBFair!C97 -> 33258.012 | E9: =+ModelBFair!C95 -> 24976.854 | F9: =+ModelBFair!C53 -> 11718.842 | G9: =+E9-F9 -> 13258.012 | H9: =+G9/F9 -> 1.1313416

Sheet ModelAStandard
C26: 2025 | D26: =+C26+1 -> 2026 | E26: =+D26+1 -> 2027 | F26: =+E26+1 -> 2028 | G26: =+F26+1 -> 2029 | H26: =+G26+1 -> 2030 | I26: TV1 | J26: TV2
B27: IC boy | C27: 20000 | I27: RONIC=WACC
B28: ROIC | C28: 0.15
B29: RONIC | D29: 0.14 | E29: 0.13 | F29: 0.12 | G29: 0.11 | H29: 0.1 | I29: =+I38 -> 0.0952 | J29: =+J38 -> 0.0952 | K29: =+K38 -> 0.0952
B30: K | C30: 0.6 | D30: 0.6 | E30: 0.6 | F30: 0.6 | G30: 0.6 | H30: 0.6 | I30: =+J31/J29 -> 0.6302521 | J30: =+K31/K29 -> 0.6302521
B31: g | J31: 0.06 | K31: 0.06
B32: rA | C32: 0.1 | D32: 0.1 | E32: 0.1 | F32: 0.1 | G32: 0.1 | H32: 0.1 | I32: 0.1 | J32: 0.1 | K32: 0.1
B33: t nominal | C33: 0.2 | D33: 0.2 | E33: 0.2 | F33: 0.2 | G33: 0.2 | H33: 0.2 | I33: 0.2 | J33: 0.2 | K33: 0.2
B34: Debt/V boy | C34: =+C46/C86 -> 0.24743135 | D34: =+D46/D86 -> 0.2316068 | E34: =+E46/E86 -> 0.16330579 | F34: =+F46/F86 -> 0.10229263 | G34: =+G46/G86 -> 0.048022381 | H34: 0.4 | I34: 0.4 | J34: 0.4 | K34: 0.4
B35: rD* for WACC | C35: =+C42/C46 -> 0.077685036 | D35: =+D42/D46 -> 0.078286672 | E35: =+E42/E46 -> 0.078593976 | F35: =+F42/F46 -> 0.078917801 | G35: =+G42/G46 -> 0.079259259 | H35: 0.06 | I35: 0.06 | J35: 0.06 | K35: 0.06
B36: t effective assumed | C36: 0.2 | D36: 0.2 | E36: 0.2 | F36: 0.2 | G36: 0.2 | H36: 0.2 | I36: 0.2 | J36: 0.2 | K36: 0.2
B37: t effective calculated | C37: =+C58/C57 -> 0.2 | D37: =+D58/D57 -> 0.2 | E37: =+E58/E57 -> 0.2 | F37: =+F58/F57 -> 0.2 | G37: =+G58/G57 -> 0.2 | H37: =+H58/H57 -> 0.2 | I37: =+I58/I57 -> 0.2 | J37: =+J58/J57 -> 0.2 | K37: =+K58/K57 -> #DIV/0!
B38: WACC | C38: =+C32-C35*C34*C36 -> 0.096155657 | D38: =+D32-D35*D34*D36 -> 0.096373655 | E38: =+E32-E35*E34*E36 -> 0.09743303 | F38: =+F32-F35*F34*F36 -> 0.098385458 | G38: =+G32-G35*G34*G36 -> 0.099238756 | H38: =+H32-H35*H34*H36 -> 0.0952 | I38: =+I32-I35*I34*I36 -> 0.0952 | J38: =+J32-J35*J34*J36 -> 0.0952 | K38: =+K32-K35*K34*K36 -> 0.0952
B40: Principal boy | C40: 8000 | D40: 8000 | E40: 6000 | F40: 4000 | G40: 2000 | H40: 0
B41: interest | C41: 0.08 | D41: 0.08 | E41: 0.08 | F41: 0.08 | G41: 0.08 | H41: 0.08
B42: Interest payment | C42: =+C40*C41 -> 640 | D42: =+D40*D41 -> 640 | E42: =+E40*E41 -> 480 | F42: =+F40*F41 -> 320 | G42: =+G40*G41 -> 160
B43: Principal payment | C43: =+C40-D40 -> 0 | D43: =+D40-E40 -> 2000 | E43: =+E40-F40 -> 2000 | F43: =+F40-G40 -> 2000 | G43: =+G40-H40 -> 2000
B44: Total CF | C44: =+C42+C43 -> 640 | D44: =+D42+D43 -> 2640 | E44: =+E42+E43 -> 2480 | F44: =+F42+F43 -> 2320 | G44: =+G42+G43 -> 2160
B45: rD | C45: 0.07 | D45: 0.07 | E45: 0.07 | F45: 0.07 | G45: 0.07 | H45: =+H35 -> 0.06 | I45: =+I35 -> 0.06 | J45: =+J35 -> 0.06 | K45: =+K35 -> 0.06
B46: D boy | C46: =+(C44+D46)/(1+C45) -> 8238.3949 | D46: =+(D44+E46)/(1+D45) -> 8175.0825 | E46: =+(E44+F46)/(1+E45) -> 6107.3383 | F46: =+(F44+G46)/(1+F45) -> 4054.852 | G46: =+(G44+H46)/(1+G45) -> 2018.6916 | H46: 0
B50: =+B27 -> IC boy | C50: =+C27 -> 20000 | D50: =+C50+C67 -> 21800 | E50: =+D50+D67 -> 23751.2 | F50: =+E50+E67 -> 25854.594 | G50: =+F50+F67 -> 28109.432 | H50: =+G50+G67 -> 30513.089 | I50: =+H50+H67 -> 33060.965 | J50: =+I50+I67 -> 35890.179
B51: BV D boy | C51: =+C40 -> 8000 | D51: =+D40 -> 8000 | E51: =+E40 -> 6000 | F51: =+F40 -> 4000 | G51: =+G40 -> 2000 | H51: =+H34*H80 -> 17842.274 | I51: =+I34*I80 -> 18861.424 | J51: =+J34*J80 -> 19993.11
B52: BV E boy | C52: =+C50-C51 -> 12000 | D52: =+D50-D51 -> 13800 | E52: =+E50-E51 -> 17751.2 | F52: =+F50-F51 -> 21854.594 | G52: =+G50-G51 -> 26109.432 | H52: =+H50-H51 -> 12670.815 | I52: =+I50-I51 -> 14199.541 | J52: =+J50-J51 -> 15897.069
B55: EBIT | C55: =+C66/(1-C36) -> 3750 | D55: =+D66/(1-D36) -> 4065 | E55: =+E66/(1-E36) -> 4382.07 | F55: =+F66/(1-F36) -> 4697.579 | G55: =+G66/(1-G36) -> 5007.6193 | H55: =+H66/(1-H36) -> 5308.0764 | I55: =+I66/(1-I36) -> 5611.2737 | J55: =+J66/(1-J36) -> 5947.9502
B56: Interest payment | C56: =+C42 -> 640 | D56: =+D42 -> 640 | E56: =+E42 -> 480 | F56: =+F42 -> 320 | G56: =+G42 -> 160 | H56: =+H51*H35 -> 1070.5364 | I56: =+I51*I35 -> 1131.6855 | J56: =+J51*J35 -> 1199.5866
B57: PBT | C57: =+C55-C56 -> 3110 | D57: =+D55-D56 -> 3425 | E57: =+E55-E56 -> 3902.07 | F57: =+F55-F56 -> 4377.579 | G57: =+G55-G56 -> 4847.6193 | H57: =+H55-H56 -> 4237.54 | I57: =+I55-I56 -> 4479.5883 | J57: =+J55-J56 -> 4748.3636
B58: Tax | C58: =+IF(C57<0,0,C57*C33) -> 622 | D58: =+IF(D57<0,0,D57*D33) -> 685 | E58: =+IF(E57<0,0,E57*E33) -> 780.414 | F58: =+IF(F57<0,0,F57*F33) -> 875.51581 | G58: =+IF(G57<0,0,G57*G33) -> 969.52385 | H58: =+IF(H57<0,0,H57*H33) -> 847.508 | I58: =+IF(I57<0,0,I57*I33) -> 895.91766 | J58: =+IF(J57<0,0,J57*J33) -> 949.67271
B59: PAT | C59: =+C57-C58 -> 2488 | D59: =+D57-D58 -> 2740 | E59: =+E57-E58 -> 3121.656 | F59: =+F57-F58 -> 3502.0632 | G59: =+G57-G58 -> 3878.0954 | H59: =+H57-H58 -> 3390.032 | I59: =+I57-I58 -> 3583.6706 | J59: =+J57-J58 -> 3798.6909
B60: Dividend | C60: =+C59-C61 -> 688 | D60: =+D59-D61 -> 0 | E60: =+E59-E61 -> 0 | F60: =+F59-F61 -> 0 | G60: =+G59-G61 -> 3878.0954 | H60: =+H59-H61 -> 1861.306 | I60: =+I59-I61 -> 1886.1424 | J60: =+J59-J61 -> 0
B61: Retained Earnings | C61: =+IF(C59<0,C59,MAX(0,MIN(C59,C63))) -> 1800 | D61: =+IF(D59<0,D59,MAX(0,MIN(D59,D63))) -> 2740 | E61: =+IF(E59<0,E59,MAX(0,MIN(E59,E63))) -> 3121.656 | F61: =+IF(F59<0,F59,MAX(0,MIN(F59,F63))) -> 3502.0632 | G61: =+IF(G59<0,G59,MAX(0,MIN(G59,G63))) -> 0 | H61: =+IF(H59<0,H59,MAX(0,MIN(H59,H63))) -> 1528.726 | I61: =+IF(I59<0,I59,MAX(0,MIN(I59,I63))) -> 1697.5282 | J61: =+IF(J59<0,J59,MAX(0,MIN(J59,J63))) -> 3798.6909
B63: dBVEquity needed | C63: =+D52-C52 -> 1800 | D63: =+E52-D52 -> 3951.2 | E63: =+F52-E52 -> 4103.3936 | F63: =+G52-F52 -> 4254.8379 | G63: =+H52-G52 -> -13438.616 | H63: =+I52-H52 -> 1528.726 | I63: =+J52-I52 -> 1697.5282
B64: Share issue/buyback | C64: =+C63-C61 -> 0 | D64: =+D63-D61 -> 1211.2 | E64: =+E63-E61 -> 981.7376 | F64: =+F63-F61 -> 752.77471 | G64: =+G63-G61 -> -13438.616 | H64: =+H63-H61 -> 0 | I64: =+I63-I61 -> 0
B66: Noplat | C66: =+C50*C28 -> 3000 | D66: =+C66+C67*D29 -> 3252 | E66: =+D66+D67*E29 -> 3505.656 | F66: =+E66+E67*F29 -> 3758.0632 | G66: =+F66+F67*G29 -> 4006.0954 | H66: =+G66+G67*H29 -> 4246.4611 | I66: =+H66+H67*I29 -> 4489.019 | J66: =+I66+I67*J29 -> 4758.3601
B67: dIC | C67: =+C66*C30 -> 1800 | D67: =+D66*D30 -> 1951.2 | E67: =+E66*E30 -> 2103.3936 | F67: =+F66*F30 -> 2254.8379 | G67: =+G66*G30 -> 2403.6572 | H67: =+H66*H30 -> 2547.8767 | I67: =+I66*I30 -> 2829.2136 | J67: =+J66*J30 -> 2998.9665
B68: FCFF | C68: =+C66-C67 -> 1200 | D68: =+D66-D67 -> 1300.8 | E68: =+E66-E67 -> 1402.2624 | F68: =+F66-F67 -> 1503.2253 | G68: =+G66-G67 -> 1602.4382 | H68: =+H66-H67 -> 1698.5845 | I68: =+I66-I67 -> 1659.8053 | J68: =+J66-J67 -> 1759.3937
B69: =+B56 -> Interest payment | C69: =+C56 -> 640 | D69: =+D56 -> 640 | E69: =+E56 -> 480 | F69: =+F56 -> 320 | G69: =+G56 -> 160 | H69: =+H56 -> 1070.5364 | I69: =+I56 -> 1131.6855
B70: TS | C70: =+C69*C36 -> 128 | D70: =+D69*D36 -> 128 | E70: =+E69*E36 -> 96 | F70: =+F69*F36 -> 64 | G70: =+G69*G36 -> 32 | H70: =+H69*H36 -> 214.10728 | I70: =+I69*I36 -> 226.33709
B71: dD | C71: =+D51-C51 -> 0 | D71: =+E51-D51 -> -2000 | E71: =+F51-E51 -> -2000 | F71: =+G51-F51 -> -2000 | G71: =+H51-G51 -> 15842.274 | H71: =+I51-H51 -> 1019.1507 | I71: =+J51-I51 -> 1131.6855
B72: FCFE | C72: =+C68-C69+C70+C71 -> 688 | D72: =+D68-D69+D70+D71 -> -1211.2 | E72: =+E68-E69+E70+E71 -> -981.7376 | F72: =+F68-F69+F70+F71 -> -752.77471 | G72: =+G68-G69+G70+G71 -> 17316.712 | H72: =+H68-H69+H70+H71 -> 1861.306 | I72: =+I68-I69+I70+I71 -> 1886.1424
B73: =+B60 -> Dividend | C73: =+C60 -> 688 | D73: =+D60 -> 0 | E73: =+E60 -> 0 | F73: =+F60 -> 0 | G73: =+G60 -> 3878.0954 | H73: =+H60 -> 1861.306 | I73: =+I60 -> 1886.1424
...

Sheet ModelAFairValue
C26: 2025 | D26: =+C26+1 -> 2026 | E26: =+D26+1 -> 2027 | F26: =+E26+1 -> 2028 | G26: =+F26+1 -> 2029 | H26: =+G26+1 -> 2030 | I26: TV1 | J26: TV2
B27: IC boy | C27: 20000 | I27: RONIC=WACC
B28: ROIC | C28: 0.15
B29: RONIC | D29: 0.14 | E29: 0.13 | F29: 0.12 | G29: 0.11 | H29: 0.1 | I29: =+I38 -> 0.0952 | J29: =+J38 -> 0.0952 | K29: =+K38 -> 0.0952
B30: K | C30: 0.6 | D30: 0.6 | E30: 0.6 | F30: 0.6 | G30: 0.6 | H30: 0.6 | I30: =+J31/J29 -> 0.6302521 | J30: =+K31/K29 -> 0.6302521
B31: g | J31: 0.06 | K31: 0.06
B32: rA | C32: 0.1 | D32: 0.1 | E32: 0.1 | F32: 0.1 | G32: 0.1 | H32: 0.1 | I32: 0.1 | J32: 0.1 | K32: 0.1
B33: t nominal | C33: 0.2 | D33: 0.2 | E33: 0.2 | F33: 0.2 | G33: 0.2 | H33: 0.2 | I33: 0.2 | J33: 0.2 | K33: 0.2
B34: Debt/V boy | C34: =+C46/C86 -> 0.24743135 | D34: =+D46/D86 -> 0.2316068 | E34: =+E46/E86 -> 0.16330579 | F34: =+F46/F86 -> 0.10229263 | G34: =+G46/G86 -> 0.048022381 | H34: 0.4 | I34: 0.4 | J34: 0.4 | K34: 0.4
B35: rD* for WACC | C35: =+C42/C46 -> 0.077685036 | D35: =+D42/D46 -> 0.078286672 | E35: =+E42/E46 -> 0.078593976 | F35: =+F42/F46 -> 0.078917801 | G35: =+G42/G46 -> 0.079259259 | H35: 0.06 | I35: 0.06 | J35: 0.06 | K35: 0.06
B36: t effective assumed | C36: 0.2 | D36: 0.2 | E36: 0.2 | F36: 0.2 | G36: 0.2 | H36: 0.2 | I36: 0.2 | J36: 0.2 | K36: 0.2
B37: t effective calculated | C37: =+C58/C57 -> 0.2 | D37: =+D58/D57 -> 0.2 | E37: =+E58/E57 -> 0.2 | F37: =+F58/F57 -> 0.2 | G37: =+G58/G57 -> 0.2 | H37: =+H58/H57 -> 0.2 | I37: =+I58/I57 -> 0.2 | J37: =+J58/J57 -> 0.2 | K37: =+K58/K57 -> #DIV/0!
B38: WACC | C38: =+C32-C35*C34*C36 -> 0.096155657 | D38: =+D32-D35*D34*D36 -> 0.096373655 | E38: =+E32-E35*E34*E36 -> 0.09743303 | F38: =+F32-F35*F34*F36 -> 0.098385458 | G38: =+G32-G35*G34*G36 -> 0.099238756 | H38: =+H32-H35*H34*H36 -> 0.0952 | I38: =+I32-I35*I34*I36 -> 0.0952 | J38: =+J32-J35*J34*J36 -> 0.0952 | K38: =+K32-K35*K34*K36 -> 0.0952
B40: Principal boy | C40: 8000 | D40: 8000 | E40: 6000 | F40: 4000 | G40: 2000 | H40: 0
B41: interest | C41: 0.08 | D41: 0.08 | E41: 0.08 | F41: 0.08 | G41: 0.08 | H41: 0.08
B42: Interest payment | C42: =+C40*C41 -> 640 | D42: =+D40*D41 -> 640 | E42: =+E40*E41 -> 480 | F42: =+F40*F41 -> 320 | G42: =+G40*G41 -> 160
B43: Principal payment | C43: =+C40-D40 -> 0 | D43: =+D40-E40 -> 2000 | E43: =+E40-F40 -> 2000 | F43: =+F40-G40 -> 2000 | G43: =+G40-H40 -> 2000
B44: Total CF | C44: =+C42+C43 -> 640 | D44: =+D42+D43 -> 2640 | E44: =+E42+E43 -> 2480 | F44: =+F42+F43 -> 2320 | G44: =+G42+G43 -> 2160
B45: rD | C45: 0.07 | D45: 0.07 | E45: 0.07 | F45: 0.07 | G45: 0.07 | H45: =+H35 -> 0.06 | I45: =+I35 -> 0.06 | J45: =+J35 -> 0.06 | K45: =+K35 -> 0.06
B46: D boy | C46: =+(C44+D46)/(1+C45) -> 8238.3949 | D46: =+(D44+E46)/(1+D45) -> 8175.0825 | E46: =+(E44+F46)/(1+E45) -> 6107.3383 | F46: =+(F44+G46)/(1+F45) -> 4054.852 | G46: =+(G44+H46)/(1+G45) -> 2018.6916 | H46: 0
B50: =+B27 -> IC boy | C50: =+C27 -> 20000 | D50: =+C50+C67 -> 21800 | E50: =+D50+D67 -> 23751.2 | F50: =+E50+E67 -> 25854.594 | G50: =+F50+F67 -> 28109.432 | H50: =+G50+G67 -> 30513.089 | I50: =+H50+H67 -> 33060.965 | J50: =+I50+I67 -> 35890.179
B51: BV D boy | C51: =+C46 -> 8238.3949 | D51: =+D46 -> 8175.0825 | E51: =+E46 -> 6107.3383 | F51: =+F46 -> 4054.852 | G51: =+G46 -> 2018.6916 | H51: =+H34*H80 -> 17842.274 | I51: =+I34*I80 -> 18861.424 | J51: =+J34*J80 -> 19993.11
B52: BV E boy | C52: =+C50-C51 -> 11761.605 | D52: =+D50-D51 -> 13624.918 | E52: =+E50-E51 -> 17643.862 | F52: =+F50-F51 -> 21799.742 | G52: =+G50-G51 -> 26090.74 | H52: =+H50-H51 -> 12670.815 | I52: =+I50-I51 -> 14199.541 | J52: =+J50-J51 -> 15897.069
B55: EBIT | C55: =+C66/(1-C36) -> 3750 | D55: =+D66/(1-D36) -> 4065 | E55: =+E66/(1-E36) -> 4382.07 | F55: =+F66/(1-F36) -> 4697.579 | G55: =+G66/(1-G36) -> 5007.6193 | H55: =+H66/(1-H36) -> 5308.0764 | I55: =+I66/(1-I36) -> 5611.2737 | J55: =+J66/(1-J36) -> 5947.9502
B56: Interest payment | C56: =+C42 -> 640 | D56: =+D42 -> 640 | E56: =+E42 -> 480 | F56: =+F42 -> 320 | G56: =+G42 -> 160 | H56: =+H51*H35 -> 1070.5364 | I56: =+I51*I35 -> 1131.6855 | J56: =+J51*J35 -> 1199.5866
B57: PBT | C57: =+C55-C56 -> 3110 | D57: =+D55-D56 -> 3425 | E57: =+E55-E56 -> 3902.07 | F57: =+F55-F56 -> 4377.579 | G57: =+G55-G56 -> 4847.6193 | H57: =+H55-H56 -> 4237.54 | I57: =+I55-I56 -> 4479.5883 | J57: =+J55-J56 -> 4748.3636
B58: Tax | C58: =+IF(C57<0,0,C57*C33) -> 622 | D58: =+IF(D57<0,0,D57*D33) -> 685 | E58: =+IF(E57<0,0,E57*E33) -> 780.414 | F58: =+IF(F57<0,0,F57*F33) -> 875.51581 | G58: =+IF(G57<0,0,G57*G33) -> 969.52385 | H58: =+IF(H57<0,0,H57*H33) -> 847.508 | I58: =+IF(I57<0,0,I57*I33) -> 895.91766 | J58: =+IF(J57<0,0,J57*J33) -> 949.67271
B59: PAT | C59: =+C57-C58 -> 2488 | D59: =+D57-D58 -> 2740 | E59: =+E57-E58 -> 3121.656 | F59: =+F57-F58 -> 3502.0632 | G59: =+G57-G58 -> 3878.0954 | H59: =+H57-H58 -> 3390.032 | I59: =+I57-I58 -> 3583.6706 | J59: =+J57-J58 -> 3798.6909
B60: Dividend | C60: =+C59-C61 -> 624.68764 | D60: =+D59-D61 -> 0 | E60: =+E59-E61 -> 0 | F60: =+F59-F61 -> 0 | G60: =+G59-G61 -> 3878.0954 | H60: =+H59-H61 -> 1861.306 | I60: =+I59-I61 -> 1886.1424 | J60: =+J59-J61 -> 0
B61: Retained Earnings | C61: =+IF(C59<0,C59,MAX(0,MIN(C59,C63))) -> 1863.3124 | D61: =+IF(D59<0,D59,MAX(0,MIN(D59,D63))) -> 2740 | E61: =+IF(E59<0,E59,MAX(0,MIN(E59,E63))) -> 3121.656 | F61: =+IF(F59<0,F59,MAX(0,MIN(F59,F63))) -> 3502.0632 | G61: =+IF(G59<0,G59,MAX(0,MIN(G59,G63))) -> 0 | H61: =+IF(H59<0,H59,MAX(0,MIN(H59,H63))) -> 1528.726 | I61: =+IF(I59<0,I59,MAX(0,MIN(I59,I63))) -> 1697.5282 | J61: =+IF(J59<0,J59,MAX(0,MIN(J59,J63))) -> 3798.6909
B63: dBVEquity needed | C63: =+D52-C52 -> 1863.3124 | D63: =+E52-D52 -> 4018.9442 | E63: =+F52-E52 -> 4155.8799 | F63: =+G52-F52 -> 4290.9983 | G63: =+H52-G52 -> -13419.925 | H63: =+I52-H52 -> 1528.726 | I63: =+J52-I52 -> 1697.5282
B64: Share issue/buyback | C64: =+C63-C61 -> 0 | D64: =+D63-D61 -> 1278.9442 | E64: =+E63-E61 -> 1034.2239 | F64: =+F63-F61 -> 788.93507 | G64: =+G63-G61 -> -13419.925 | H64: =+H63-H61 -> 0 | I64: =+I63-I61 -> 0
B66: Noplat | C66: =+C50*C28 -> 3000 | D66: =+C66+C67*D29 -> 3252 | E66: =+D66+D67*E29 -> 3505.656 | F66: =+E66+E67*F29 -> 3758.0632 | G66: =+F66+F67*G29 -> 4006.0954 | H66: =+G66+G67*H29 -> 4246.4611 | I66: =+H66+H67*I29 -> 4489.019 | J66: =+I66+I67*J29 -> 4758.3601
B67: dIC | C67: =+C66*C30 -> 1800 | D67: =+D66*D30 -> 1951.2 | E67: =+E66*E30 -> 2103.3936 | F67: =+F66*F30 -> 2254.8379 | G67: =+G66*G30 -> 2403.6572 | H67: =+H66*H30 -> 2547.8767 | I67: =+I66*I30 -> 2829.2136 | J67: =+J66*J30 -> 2998.9665
B68: FCFF | C68: =+C66-C67 -> 1200 | D68: =+D66-D67 -> 1300.8 | E68: =+E66-E67 -> 1402.2624 | F68: =+F66-F67 -> 1503.2253 | G68: =+G66-G67 -> 1602.4382 | H68: =+H66-H67 -> 1698.5845 | I68: =+I66-I67 -> 1659.8053 | J68: =+J66-J67 -> 1759.3937
B69: =+B56 -> Interest payment | C69: =+C56 -> 640 | D69: =+D56 -> 640 | E69: =+E56 -> 480 | F69: =+F56 -> 320 | G69: =+G56 -> 160 | H69: =+H56 -> 1070.5364 | I69: =+I56 -> 1131.6855
B70: TS | C70: =+C69*C36 -> 128 | D70: =+D69*D36 -> 128 | E70: =+E69*E36 -> 96 | F70: =+F69*F36 -> 64 | G70: =+G69*G36 -> 32 | H70: =+H69*H36 -> 214.10728 | I70: =+I69*I36 -> 226.33709
B71: dD | C71: =+D51-C51 -> -63.31236 | D71: =+E51-D51 -> -2067.7442 | E71: =+F51-E51 -> -2052.4863 | F71: =+G51-F51 -> -2036.1604 | G71: =+H51-G51 -> 15823.582 | H71: =+I51-H51 -> 1019.1507 | I71: =+J51-I51 -> 1131.6855
B72: FCFE | C72: =+C68-C69+C70+C71 -> 624.68764 | D72: =+D68-D69+D70+D71 -> -1278.9442 | E72: =+E68-E69+E70+E71 -> -1034.2239 | F72: =+F68-F69+F70+F71 -> -788.93507 | G72: =+G68-G69+G70+G71 -> 17298.02 | H72: =+H68-H69+H70+H71 -> 1861.306 | I72: =+I68-I69+I70+I71 -> 1886.1424
B73: =+B60 -> Dividend | C73: =+C60 -> 624.68764 | D73: =+D60 -> 0 | E73: =+E60 -> 0 | F73: =+F60 -> 0 | G73: =+G60 -> 3878.0954 | H73: =+H60 -> 1861.306 | I73: =+I60 -> 1886.1424
...

Sheet ModelBStandard
C26: 2025 | D26: =+C26+1 -> 2026 | E26: =+D26+1 -> 2027 | F26: =+E26+1 -> 2028 | G26: =+F26+1 -> 2029 | H26: =+G26+1 -> 2030 | I26: TV1 | J26: TV2
B27: IC boy | C27: 20000 | I27: RONIC=WACC
B28: ROIC | C28: 0.15
B29: RONIC | D29: 0.14 | E29: 0.13 | F29: 0.12 | G29: 0.11 | H29: 0.1 | I29: =+I38 -> 0.0952 | J29: =+J38 -> 0.0952 | K29: =+K38 -> 0.0952
B30: K | C30: 0.6 | D30: 0.6 | E30: 0.6 | F30: 0.6 | G30: 0.6 | H30: 0.6 | I30: =+J31/J29 -> 0.6302521 | J30: =+K31/K29 -> 0.6302521
B31: g | J31: 0.06 | K31: 0.06
B32: rA | C32: 0.1 | D32: 0.1 | E32: 0.1 | F32: 0.1 | G32: 0.1 | H32: 0.1 | I32: 0.1 | J32: 0.1 | K32: 0.1
B33: t nominal | C33: 0.2 | D33: 0.2 | E33: 0.2 | F33: 0.2 | G33: 0.2 | H33: 0.2 | I33: 0.2 | J33: 0.2 | K33: 0.2
B34: Debt/V boy | C34: =+C46/C88 -> 0.63841617 | D34: =+D46/D88 -> 0.63070504 | E34: =+E46/E88 -> 0.62404386 | F34: =+F46/F88 -> 0.61829188 | G34: =+G46/G88 -> 0.50391065 | H34: 0.4 | I34: 0.4 | J34: 0.4 | K34: 0.4
B35: rD* for WACC | C35: =+C42/C47 -> 0.021902204 | D35: =+D42/D47 -> 0.020881826 | E35: =+E42/E47 -> 0.019890313 | F35: =+F42/F47 -> 0.020907367 | G35: =+G42/G47 -> 0.012250959 | H35: 0.06 | I35: 0.06 | J35: 0.06 | K35: 0.06
B36: t effective assumed | C36: 0.2 | D36: 0.2 | E36: 0.2 | F36: 0.2 | G36: 0.2 | H36: 0.2 | I36: 0.2 | J36: 0.2 | K36: 0.2
B37: t effective calculated | C37: =+C59/C58 -> 0.2 | D37: =+D59/D58 -> 0.2 | E37: =+E59/E58 -> 0.2 | F37: =+F59/F58 -> 0.2 | G37: =+G59/G58 -> 0.2 | H37: =+H59/H58 -> 0.2 | I37: =+I59/I58 -> 0.2 | J37: =+J59/J58 -> 0.2 | K37: =+K59/K58 -> #DIV/0!
B38: WACC | C38: =+C32-C35*C48*C36 -> 0.097233749 | D38: =+D32-D35*D48*D36 -> 0.097393163 | E38: =+E32-E35*E48*E36 -> 0.09754196 | F38: =+F32-F35*F48*F36 -> 0.097681262 | G38: =+G32-G35*G48*G36 -> 0.098906043 | H38: =+H32-H35*H34*H36 -> 0.0952 | I38: =+I32-I35*I34*I36 -> 0.0952 | J38: =+J32-J35*J34*J36 -> 0.0952 | K38: =+K32-K35*K34*K36 -> 0.0952
B40: Principal boy | C40: 9200 | D40: 9200 | E40: 9200 | F40: 9200 | G40: =+F40/2 -> 4600 | H40: 0
B41: interest | C41: 0.05 | D41: 0.05 | E41: 0.05 | F41: 0.05 | G41: 0.05
B42: Interest payment | C42: =+C40*C41 -> 460 | D42: =+D40*D41 -> 460 | E42: =+E40*E41 -> 460 | F42: =+F40*F41 -> 460 | G42: =+G40*G41 -> 230
B43: Principal payment | C43: =+C40-D40 -> 0 | D43: =+D40-E40 -> 0 | E43: =+E40-F40 -> 0 | F43: =+F40-G40 -> 4600 | G43: =+G40-H40 -> 4600
B44: Total CF = Debt Service | C44: =+C42+C43 -> 460 | D44: =+D42+D43 -> 460 | E44: =+E42+E43 -> 460 | F44: =+F42+F43 -> 5060 | G44: =+G42+G43 -> 4830
B45: rD | C45: 0.07 | D45: 0.07 | E45: 0.07 | F45: 0.07 | G45: 0.07 | H45: =+H35 -> 0.06 | I45: =+I35 -> 0.06 | J45: =+J35 -> 0.06 | K45: =+K35 -> 0.06
B46: D boy | C46: =+(C44+D46)/(1+C45) -> 21232.453 | D46: =+(D44+E46)/(1+D45) -> 22258.725 | E46: =+(E44+F46)/(1+E45) -> 23356.835 | F46: =+(F44+G46)/(1+F45) -> 24531.814 | G46: =+(G44+H46)/(1+G45) -> 21189.041 | H46: =+H52 -> 17842.274
B47: net D boy | C47: =+C46-C50 -> 21002.453 | D47: =+D46-D50 -> 22028.725 | E47: =+E46-E50 -> 23126.835 | F47: =+F46-F50 -> 22001.814 | G47: =+G46-G50 -> 18774.041
B48: Net D/V | C48: =+C47/C88 -> 0.63150054 | D48: =+D47/D88 -> 0.62418794 | E48: =+E47/E88 -> 0.61789876 | F48: =+F47/F88 -> 0.55452658 | G48: =+G47/G88 -> 0.44647793
B50: DSRA | C50: =+C44/2 -> 230 | D50: =+D44/2 -> 230 | E50: =+E44/2 -> 230 | F50: =+F44/2 -> 2530 | G50: =+G44/2 -> 2415 | H50: 0 | I50: 0 | J50: 0
B51: =+B27 -> IC boy | C51: =+C27 -> 20000 | D51: =+C51+C68 -> 21800 | E51: =+D51+D68 -> 23751.2 | F51: =+E51+E68 -> 25854.594 | G51: =+F51+F68 -> 28109.432 | H51: =+G51+G68 -> 30513.089 | I51: =+H51+H68 -> 33060.965 | J51: =+I51+I68 -> 35890.179
B52: BV D boy | C52: =+C40 -> 9200 | D52: =+D40 -> 9200 | E52: =+E40 -> 9200 | F52: =+F40 -> 9200 | G52: =+G40 -> 4600 | H52: =+H34*H82 -> 17842.274 | I52: =+I34*I82 -> 18861.424 | J52: =+J34*J82 -> 19993.11
B53: BV E boy | C53: =+C50+C51-C52 -> 11030 | D53: =+D50+D51-D52 -> 12830 | E53: =+E50+E51-E52 -> 14781.2 | F53: =+F50+F51-F52 -> 19184.594 | G53: =+G50+G51-G52 -> 25924.432 | H53: =+H50+H51-H52 -> 12670.815 | I53: =+I50+I51-I52 -> 14199.541 | J53: =+J50+J51-J52 -> 15897.069
B56: EBIT | C56: =+C67/(1-C36) -> 3750 | D56: =+D67/(1-D36) -> 4065 | E56: =+E67/(1-E36) -> 4382.07 | F56: =+F67/(1-F36) -> 4697.579 | G56: =+G67/(1-G36) -> 5007.6193 | H56: =+H67/(1-H36) -> 5308.0764 | I56: =+I67/(1-I36) -> 5611.2737 | J56: =+J67/(1-J36) -> 5947.9502
B57: Interest payment | C57: =+C42 -> 460 | D57: =+D42 -> 460 | E57: =+E42 -> 460 | F57: =+F42 -> 460 | G57: =+G42 -> 230 | H57: =+H52*H35 -> 1070.5364 | I57: =+I52*I35 -> 1131.6855 | J57: =+J52*J35 -> 1199.5866
B58: PBT | C58: =+C56-C57 -> 3290 | D58: =+D56-D57 -> 3605 | E58: =+E56-E57 -> 3922.07 | F58: =+F56-F57 -> 4237.579 | G58: =+G56-G57 -> 4777.6193 | H58: =+H56-H57 -> 4237.54 | I58: =+I56-I57 -> 4479.5883 | J58: =+J56-J57 -> 4748.3636
B59: Tax | C59: =+IF(C58<0,0,C58*C33) -> 658 | D59: =+IF(D58<0,0,D58*D33) -> 721 | E59: =+IF(E58<0,0,E58*E33) -> 784.414 | F59: =+IF(F58<0,0,F58*F33) -> 847.51581 | G59: =+IF(G58<0,0,G58*G33) -> 955.52385 | H59: =+IF(H58<0,0,H58*H33) -> 847.508 | I59: =+IF(I58<0,0,I58*I33) -> 895.91766 | J59: =+IF(J58<0,0,J58*J33) -> 949.67271
B60: PAT | C60: =+C58-C59 -> 2632 | D60: =+D58-D59 -> 2884 | E60: =+E58-E59 -> 3137.656 | F60: =+F58-F59 -> 3390.0632 | G60: =+G58-G59 -> 3822.0954 | H60: =+H58-H59 -> 3390.032 | I60: =+I58-I59 -> 3583.6706 | J60: =+J58-J59 -> 3798.6909
B61: Dividend | C61: =+C60-C62 -> 832 | D61: =+D60-D62 -> 932.8 | E61: =+E60-E62 -> 0 | F61: =+F60-F62 -> 0 | G61: =+G60-G62 -> 3822.0954 | H61: =+H60-H62 -> 1861.306 | I61: =+I60-I62 -> 1886.1424 | J61: =+J60-J62 -> 0
B62: Retained Earnings | C62: =+IF(C60<0,C60,MAX(0,MIN(C60,C64))) -> 1800 | D62: =+IF(D60<0,D60,MAX(0,MIN(D60,D64))) -> 1951.2 | E62: =+IF(E60<0,E60,MAX(0,MIN(E60,E64))) -> 3137.656 | F62: =+IF(F60<0,F60,MAX(0,MIN(F60,F64))) -> 3390.0632 | G62: =+IF(G60<0,G60,MAX(0,MIN(G60,G64))) -> 0 | H62: =+IF(H60<0,H60,MAX(0,MIN(H60,H64))) -> 1528.726 | I62: =+IF(I60<0,I60,MAX(0,MIN(I60,I64))) -> 1697.5282 | J62: =+IF(J60<0,J60,MAX(0,MIN(J60,J64))) -> 3798.6909
B64: dBVEquity needed | C64: =+D53-C53 -> 1800 | D64: =+E53-D53 -> 1951.2 | E64: =+F53-E53 -> 4403.3936 | F64: =+G53-F53 -> 6739.8379 | G64: =+H53-G53 -> -13253.616 | H64: =+I53-H53 -> 1528.726 | I64: =+J53-I53 -> 1697.5282
B65: Share issue/buyback | C65: =+C64-C62 -> 0 | D65: =+D64-D62 -> 0 | E65: =+E64-E62 -> 1265.7376 | F65: =+F64-F62 -> 3349.7747 | G65: =+G64-G62 -> -13253.616 | H65: =+H64-H62 -> 0 | I65: =+I64-I62 -> 0
B67: Noplat | C67: =+C51*C28 -> 3000 | D67: =+C67+C68*D29 -> 3252 | E67: =+D67+D68*E29 -> 3505.656 | F67: =+E67+E68*F29 -> 3758.0632 | G67: =+F67+F68*G29 -> 4006.0954 | H67: =+G67+G68*H29 -> 4246.4611 | I67: =+H67+H68*I29 -> 4489.019 | J67: =+I67+I68*J29 -> 4758.3601
B68: dIC | C68: =+C67*C30 -> 1800 | D68: =+D67*D30 -> 1951.2 | E68: =+E67*E30 -> 2103.3936 | F68: =+F67*F30 -> 2254.8379 | G68: =+G67*G30 -> 2403.6572 | H68: =+H67*H30 -> 2547.8767 | I68: =+I67*I30 -> 2829.2136 | J68: =+J67*J30 -> 2998.9665
B69: FCFF | C69: =+C67-C68 -> 1200 | D69: =+D67-D68 -> 1300.8 | E69: =+E67-E68 -> 1402.2624 | F69: =+F67-F68 -> 1503.2253 | G69: =+G67-G68 -> 1602.4382 | H69: =+H67-H68 -> 1698.5845 | I69: =+I67-I68 -> 1659.8053 | J69: =+J67-J68 -> 1759.3937
B70: =+B57 -> Interest payment | C70: =+C57 -> 460 | D70: =+D57 -> 460 | E70: =+E57 -> 460 | F70: =+F57 -> 460 | G70: =+G57 -> 230 | H70: =+H57 -> 1070.5364 | I70: =+I57 -> 1131.6855
B71: TS | C71: =+C70*C36 -> 92 | D71: =+D70*D36 -> 92 | E71: =+E70*E36 -> 92 | F71: =+F70*F36 -> 92 | G71: =+G70*G36 -> 46 | H71: =+H70*H36 -> 214.10728 | I71: =+I70*I36 -> 226.33709
...

Sheet ModelBFair
C26: 2025 | D26: =+C26+1 -> 2026 | E26: =+D26+1 -> 2027 | F26: =+E26+1 -> 2028 | G26: =+F26+1 -> 2029 | H26: =+G26+1 -> 2030 | I26: TV1 | J26: TV2
B27: IC boy | C27: 20000 | I27: RONIC=WACC
B28: ROIC | C28: 0.15
B29: RONIC | D29: 0.14 | E29: 0.13 | F29: 0.12 | G29: 0.11 | H29: 0.1 | I29: =+I38 -> 0.0952 | J29: =+J38 -> 0.0952 | K29: =+K38 -> 0.0952
B30: K | C30: 0.6 | D30: 0.6 | E30: 0.6 | F30: 0.6 | G30: 0.6 | H30: 0.6 | I30: =+J31/J29 -> 0.6302521 | J30: =+K31/K29 -> 0.6302521
B31: g | J31: 0.06 | K31: 0.06
B32: rA | C32: 0.1 | D32: 0.1 | E32: 0.1 | F32: 0.1 | G32: 0.1 | H32: 0.1 | I32: 0.1 | J32: 0.1 | K32: 0.1
B33: t nominal | C33: 0.2 | D33: 0.2 | E33: 0.2 | F33: 0.2 | G33: 0.2 | H33: 0.2 | I33: 0.2 | J33: 0.2 | K33: 0.2
B34: Debt/V boy | C34: =+C46/C88 -> 0.25591302 | D34: =+D46/D88 -> 0.24501261 | E34: =+E46/E88 -> 0.23490914 | F34: =+F46/F88 -> 0.22551445 | G34: =+G46/G88 -> 0.10735088 | H34: 0.4 | I34: 0.4 | J34: 0.4 | K34: 0.4
B35: rD* for WACC | C35: =+C42/C47 -> 0.055547784 | D35: =+D42/D47 -> 0.054651694 | E35: =+E42/E47 -> 0.053724352 | F35: =+F42/F47 -> 0.071676981 | G35: =+G42/G47 -> 0.10957501 | H35: 0.06 | I35: 0.06 | J35: 0.06 | K35: 0.06
B36: t effective assumed | C36: 0.2 | D36: 0.2 | E36: 0.2 | F36: 0.2 | G36: 0.2 | H36: 0.2 | I36: 0.2 | J36: 0.2 | K36: 0.2
B37: t effective calculated | C37: =+C59/C58 -> 0.2 | D37: =+D59/D58 -> 0.2 | E37: =+E59/E58 -> 0.2 | F37: =+F59/F58 -> 0.2 | G37: =+G59/G58 -> 0.2 | H37: =+H59/H58 -> 0.2 | I37: =+I59/I58 -> 0.2 | J37: =+J59/J58 -> 0.2 | K37: =+K59/K58 -> #DIV/0!
B38: WACC | C38: =+C32-C35*C48*C36 -> 0.097233749 | D38: =+D32-D35*D48*D36 -> 0.097393163 | E38: =+E32-E35*E48*E36 -> 0.09754196 | F38: =+F32-F35*F48*F36 -> 0.097681262 | G38: =+G32-G35*G48*G36 -> 0.098906043 | H38: =+H32-H35*H34*H36 -> 0.0952 | I38: =+I32-I35*I34*I36 -> 0.0952 | J38: =+J32-J35*J34*J36 -> 0.0952 | K38: =+K32-K35*K34*K36 -> 0.0952
B40: Principal boy | C40: 9200 | D40: 9200 | E40: 9200 | F40: 9200 | G40: =+F40/2 -> 4600 | H40: 0
B41: interest | C41: 0.05 | D41: 0.05 | E41: 0.05 | F41: 0.05 | G41: 0.05
B42: Interest payment | C42: =+C40*C41 -> 460 | D42: =+D40*D41 -> 460 | E42: =+E40*E41 -> 460 | F42: =+F40*F41 -> 460 | G42: =+G40*G41 -> 230
B43: Principal payment | C43: =+C40-D40 -> 0 | D43: =+D40-E40 -> 0 | E43: =+E40-F40 -> 0 | F43: =+F40-G40 -> 4600 | G43: =+G40-H40 -> 4600
B44: Total CF = Debt Service | C44: =+C42+C43 -> 460 | D44: =+D42+D43 -> 460 | E44: =+E42+E43 -> 460 | F44: =+F42+F43 -> 5060 | G44: =+G42+G43 -> 4830
B45: rD | C45: 0.07 | D45: 0.07 | E45: 0.07 | F45: 0.07 | G45: 0.07 | H45: =+H35 -> 0.06 | I45: =+I35 -> 0.06 | J45: =+J35 -> 0.06 | K45: =+K35 -> 0.06
B46: D boy | C46: =+(C44+D46)/(1+C45) -> 8511.1584 | D46: =+(D44+E46)/(1+D45) -> 8646.9395 | E46: =+(E44+F46)/(1+E45) -> 8792.2253 | F46: =+(F44+G46)/(1+F45) -> 8947.681 | G46: =+(G44+H46)/(1+G45) -> 4514.0187 | H46: 0
B47: net D boy | C47: =+C46-C50 -> 8281.1584 | D47: =+D46-D50 -> 8416.9395 | E47: =+E46-E50 -> 8562.2253 | F47: =+F46-F50 -> 6417.681 | G47: =+G46-G50 -> 2099.0187
B48: Net D/V | C48: =+C47/C88 -> 0.24899739 | D48: =+D47/D88 -> 0.23849552 | E48: =+E47/E88 -> 0.22876404 | F48: =+F47/F88 -> 0.16174915 | G48: =+G47/G88 -> 0.049918157
B50: DSRA | C50: =+C44/2 -> 230 | D50: =+D44/2 -> 230 | E50: =+E44/2 -> 230 | F50: =+F44/2 -> 2530 | G50: =+G44/2 -> 2415 | H50: 0 | I50: 0 | J50: 0
B51: =+B27 -> IC boy | C51: =+C27 -> 20000 | D51: =+C51+C68 -> 21800 | E51: =+D51+D68 -> 23751.2 | F51: =+E51+E68 -> 25854.594 | G51: =+F51+F68 -> 28109.432 | H51: =+G51+G68 -> 30513.089 | I51: =+H51+H68 -> 33060.965 | J51: =+I51+I68 -> 35890.179
B52: BV D boy | C52: =+C46 -> 8511.1584 | D52: =+D46 -> 8646.9395 | E52: =+E46 -> 8792.2253 | F52: =+F46 -> 8947.681 | G52: =+G46 -> 4514.0187 | H52: =+H34*H82 -> 17842.274 | I52: =+I34*I82 -> 18861.424 | J52: =+J34*J82 -> 19993.11
B53: BV E boy | C53: =+C50+C51-C52 -> 11718.842 | D53: =+D50+D51-D52 -> 13383.061 | E53: =+E50+E51-E52 -> 15188.975 | F53: =+F50+F51-F52 -> 19436.913 | G53: =+G50+G51-G52 -> 26010.413 | H53: =+H50+H51-H52 -> 12670.815 | I53: =+I50+I51-I52 -> 14199.541 | J53: =+J50+J51-J52 -> 15897.069
B56: EBIT | C56: =+C67/(1-C36) -> 3750 | D56: =+D67/(1-D36) -> 4065 | E56: =+E67/(1-E36) -> 4382.07 | F56: =+F67/(1-F36) -> 4697.579 | G56: =+G67/(1-G36) -> 5007.6193 | H56: =+H67/(1-H36) -> 5308.0764 | I56: =+I67/(1-I36) -> 5611.2737 | J56: =+J67/(1-J36) -> 5947.9502
B57: Interest payment | C57: =+C42 -> 460 | D57: =+D42 -> 460 | E57: =+E42 -> 460 | F57: =+F42 -> 460 | G57: =+G42 -> 230 | H57: =+H52*H35 -> 1070.5364 | I57: =+I52*I35 -> 1131.6855 | J57: =+J52*J35 -> 1199.5866
B58: PBT | C58: =+C56-C57 -> 3290 | D58: =+D56-D57 -> 3605 | E58: =+E56-E57 -> 3922.07 | F58: =+F56-F57 -> 4237.579 | G58: =+G56-G57 -> 4777.6193 | H58: =+H56-H57 -> 4237.54 | I58: =+I56-I57 -> 4479.5883 | J58: =+J56-J57 -> 4748.3636
B59: Tax | C59: =+IF(C58<0,0,C58*C33) -> 658 | D59: =+IF(D58<0,0,D58*D33) -> 721 | E59: =+IF(E58<0,0,E58*E33) -> 784.414 | F59: =+IF(F58<0,0,F58*F33) -> 847.51581 | G59: =+IF(G58<0,0,G58*G33) -> 955.52385 | H59: =+IF(H58<0,0,H58*H33) -> 847.508 | I59: =+IF(I58<0,0,I58*I33) -> 895.91766 | J59: =+IF(J58<0,0,J58*J33) -> 949.67271
B60: PAT | C60: =+C58-C59 -> 2632 | D60: =+D58-D59 -> 2884 | E60: =+E58-E59 -> 3137.656 | F60: =+F58-F59 -> 3390.0632 | G60: =+G58-G59 -> 3822.0954 | H60: =+H58-H59 -> 3390.032 | I60: =+I58-I59 -> 3583.6706 | J60: =+J58-J59 -> 3798.6909
B61: Dividend | C61: =+C60-C62 -> 967.78109 | D61: =+D60-D62 -> 1078.0858 | E61: =+E60-E62 -> 0 | F61: =+F60-F62 -> 0 | G61: =+G60-G62 -> 3822.0954 | H61: =+H60-H62 -> 1861.306 | I61: =+I60-I62 -> 1886.1424 | J61: =+J60-J62 -> 0
B62: Retained Earnings | C62: =+IF(C60<0,C60,MAX(0,MIN(C60,C64))) -> 1664.2189 | D62: =+IF(D60<0,D60,MAX(0,MIN(D60,D64))) -> 1805.9142 | E62: =+IF(E60<0,E60,MAX(0,MIN(E60,E64))) -> 3137.656 | F62: =+IF(F60<0,F60,MAX(0,MIN(F60,F64))) -> 3390.0632 | G62: =+IF(G60<0,G60,MAX(0,MIN(G60,G64))) -> 0 | H62: =+IF(H60<0,H60,MAX(0,MIN(H60,H64))) -> 1528.726 | I62: =+IF(I60<0,I60,MAX(0,MIN(I60,I64))) -> 1697.5282 | J62: =+IF(J60<0,J60,MAX(0,MIN(J60,J64))) -> 3798.6909
B64: dBVEquity needed | C64: =+D53-C53 -> 1664.2189 | D64: =+E53-D53 -> 1805.9142 | E64: =+F53-E53 -> 4247.9378 | F64: =+G53-F53 -> 6573.5003 | G64: =+H53-G53 -> -13339.598 | H64: =+I53-H53 -> 1528.726 | I64: =+J53-I53 -> 1697.5282
B65: Share issue/buyback | C65: =+C64-C62 -> 0 | D65: =+D64-D62 -> 0 | E65: =+E64-E62 -> 1110.2818 | F65: =+F64-F62 -> 3183.437 | G65: =+G64-G62 -> -13339.598 | H65: =+H64-H62 -> 0 | I65: =+I64-I62 -> 0
B67: Noplat | C67: =+C51*C28 -> 3000 | D67: =+C67+C68*D29 -> 3252 | E67: =+D67+D68*E29 -> 3505.656 | F67: =+E67+E68*F29 -> 3758.0632 | G67: =+F67+F68*G29 -> 4006.0954 | H67: =+G67+G68*H29 -> 4246.4611 | I67: =+H67+H68*I29 -> 4489.019 | J67: =+I67+I68*J29 -> 4758.3601
B68: dIC | C68: =+C67*C30 -> 1800 | D68: =+D67*D30 -> 1951.2 | E68: =+E67*E30 -> 2103.3936 | F68: =+F67*F30 -> 2254.8379 | G68: =+G67*G30 -> 2403.6572 | H68: =+H67*H30 -> 2547.8767 | I68: =+I67*I30 -> 2829.2136 | J68: =+J67*J30 -> 2998.9665
B69: FCFF | C69: =+C67-C68 -> 1200 | D69: =+D67-D68 -> 1300.8 | E69: =+E67-E68 -> 1402.2624 | F69: =+F67-F68 -> 1503.2253 | G69: =+G67-G68 -> 1602.4382 | H69: =+H67-H68 -> 1698.5845 | I69: =+I67-I68 -> 1659.8053 | J69: =+J67-J68 -> 1759.3937
B70: =+B57 -> Interest payment | C70: =+C57 -> 460 | D70: =+D57 -> 460 | E70: =+E57 -> 460 | F70: =+F57 -> 460 | G70: =+G57 -> 230 | H70: =+H57 -> 1070.5364 | I70: =+I57 -> 1131.6855
B71: TS | C71: =+C70*C36 -> 92 | D71: =+D70*D36 -> 92 | E71: =+E70*E36 -> 92 | F71: =+F70*F36 -> 92 | G71: =+G70*G36 -> 46 | H71: =+H70*H36 -> 214.10728 | I71: =+I70*I36 -> 226.33709
...

Sheet ModelBFair (80%)
C26: 2025 | D26: =+C26+1 -> 2026 | E26: =+D26+1 -> 2027 | F26: =+E26+1 -> 2028 | G26: =+F26+1 -> 2029 | H26: =+G26+1 -> 2030 | I26: TV1 | J26: TV2
B27: IC boy | C27: 20000 | I27: RONIC=WACC
B28: ROIC | C28: 0.15
B29: RONIC | D29: 0.14 | E29: 0.13 | F29: 0.12 | G29: 0.11 | H29: 0.1 | I29: =+I38 -> 0.0952 | J29: =+J38 -> 0.0952 | K29: =+K38 -> 0.0952
B30: K | C30: 0.6 | D30: 0.6 | E30: 0.6 | F30: 0.6 | G30: 0.6 | H30: 0.6 | I30: =+J31/J29 -> 0.6302521 | J30: =+K31/K29 -> 0.6302521
B31: g | J31: 0.06 | K31: 0.06
B32: rA | C32: 0.1 | D32: 0.1 | E32: 0.1 | F32: 0.1 | G32: 0.1 | H32: 0.1 | I32: 0.1 | J32: 0.1 | K32: 0.1
B33: t nominal | C33: 0.2 | D33: 0.2 | E33: 0.2 | F33: 0.2 | G33: 0.2 | H33: 0.2 | I33: 0.2 | J33: 0.2 | K33: 0.2
B34: Debt/V boy | C34: =+C47/C91 -> 0.25585502 | D34: =+D47/D91 -> 0.2449729 | E34: =+E47/E91 -> 0.23488438 | F34: =+F47/F91 -> 0.22550205 | G34: =+G47/G91 -> 0.10734985 | H34: 0.4 | I34: 0.4 | J34: 0.4 | K34: 0.4
B35: rD* for WACC | C35: =+C43/C48 -> 0.055547784 | D35: =+D43/D48 -> 0.054651694 | E35: =+E43/E48 -> 0.053724352 | F35: =+F43/F48 -> 0.071676981 | G35: =+G43/G48 -> 0.10957501 | H35: 0.06 | I35: 0.06 | J35: 0.06 | K35: 0.06
B36: t effective assumed | C36: 0.20559271 | D36: 0.20510402 | E36: 0.2046914 | F36: 0.2043421 | G36: 0.20192565 | H36: 0.2 | I36: 0.2 | J36: 0.2 | K36: 0.2
B37: t effective calculated | C37: =+C62/C60 -> 0.20554818 | D37: =+D62/D60 -> 0.20506733 | E37: =+E62/E60 -> 0.20466068 | F37: =+F62/F60 -> 0.20431599 | G37: =+G62/G60 -> 0.20192079 | H37: =+H62/H60 -> 0.2 | I37: =+I62/I60 -> 0.2 | J37: =+J62/J60 -> 0.2 | K37: =+K62/K60 -> #DIV/0!
B38: WACC | C38: =+C32-C35*C49*C36 -> 0.09715704 | D38: =+D32-D35*D49*D36 -> 0.09732707 | E38: =+E32-E35*E49*E36 -> 0.097484567 | F38: =+F32-F35*F49*F36 -> 0.097631051 | G38: =+G32-G35*G49*G36 -> 0.098895521 | H38: =+H32-H35*H34*H36 -> 0.0952 | I38: =+I32-I35*I34*I36 -> 0.0952 | J38: =+J32-J35*J34*J36 -> 0.0952 | K38: =+K32-K35*K34*K36 -> 0.0952
B39: Tax deductible interest % | C39: 0.8 | D39: 0.8 | E39: 0.8 | F39: 0.8 | G39: 0.8 | H39: 1 | I39: 1 | J39: 1 | K39: 1
B41: Principal boy | C41: 9200 | D41: 9200 | E41: 9200 | F41: 9200 | G41: =+F41/2 -> 4600 | H41: 0
B42: interest | C42: 0.05 | D42: 0.05 | E42: 0.05 | F42: 0.05 | G42: 0.05
B43: Interest payment | C43: =+C41*C42 -> 460 | D43: =+D41*D42 -> 460 | E43: =+E41*E42 -> 460 | F43: =+F41*F42 -> 460 | G43: =+G41*G42 -> 230
B44: Principal payment | C44: =+C41-D41 -> 0 | D44: =+D41-E41 -> 0 | E44: =+E41-F41 -> 0 | F44: =+F41-G41 -> 4600 | G44: =+G41-H41 -> 4600
B45: Total CF = Debt Service | C45: =+C43+C44 -> 460 | D45: =+D43+D44 -> 460 | E45: =+E43+E44 -> 460 | F45: =+F43+F44 -> 5060 | G45: =+G43+G44 -> 4830
B46: rD | C46: 0.07 | D46: 0.07 | E46: 0.07 | F46: 0.07 | G46: 0.07 | H46: =+H35 -> 0.06 | I46: =+I35 -> 0.06 | J46: =+J35 -> 0.06 | K46: =+K35 -> 0.06
B47: D boy | C47: =+(C45+D47)/(1+C46) -> 8511.1584 | D47: =+(D45+E47)/(1+D46) -> 8646.9395 | E47: =+(E45+F47)/(1+E46) -> 8792.2253 | F47: =+(F45+G47)/(1+F46) -> 8947.681 | G47: =+(G45+H47)/(1+G46) -> 4514.0187 | H47: 0
B48: net D boy | C48: =+C47-C51 -> 8281.1584 | D48: =+D47-D51 -> 8416.9395 | E48: =+E47-E51 -> 8562.2253 | F48: =+F47-F51 -> 6417.681 | G48: =+G47-G51 -> 2099.0187
B49: Net D/V | C49: =+C48/C91 -> 0.24894096 | D49: =+D48/D91 -> 0.23845687 | E49: =+E48/E91 -> 0.22873993 | F49: =+F48/F91 -> 0.16174026 | G49: =+G48/G91 -> 0.049917679
B51: DSRA | C51: =+C45/2 -> 230 | D51: =+D45/2 -> 230 | E51: =+E45/2 -> 230 | F51: =+F45/2 -> 2530 | G51: =+G45/2 -> 2415 | H51: 0 | I51: 0 | J51: 0
B52: =+B27 -> IC boy | C52: =+C27 -> 20000 | D52: =+C52+C71 -> 21800 | E52: =+D52+D71 -> 23751.2 | F52: =+E52+E71 -> 25854.594 | G52: =+F52+F71 -> 28109.432 | H52: =+G52+G71 -> 30513.089 | I52: =+H52+H71 -> 33060.965 | J52: =+I52+I71 -> 35890.179
B53: BV D boy | C53: =+C47 -> 8511.1584 | D53: =+D47 -> 8646.9395 | E53: =+E47 -> 8792.2253 | F53: =+F47 -> 8947.681 | G53: =+G47 -> 4514.0187 | H53: =+H34*H85 -> 17842.274 | I53: =+I34*I85 -> 18861.424 | J53: =+J34*J85 -> 19993.11
B54: BV E boy | C54: =+C51+C52-C53 -> 11718.842 | D54: =+D51+D52-D53 -> 13383.061 | E54: =+E51+E52-E53 -> 15188.975 | F54: =+F51+F52-F53 -> 19436.913 | G54: =+G51+G52-G53 -> 26010.413 | H54: =+H51+H52-H53 -> 12670.815 | I54: =+I51+I52-I53 -> 14199.541 | J54: =+J51+J52-J53 -> 15897.069
B57: EBIT | C57: =+C70/(1-C36) -> 3776.4004 | D57: =+D70/(1-D36) -> 4091.1013 | E57: =+E70/(1-E36) -> 4407.9191 | F57: =+F70/(1-F36) -> 4723.2149 | G57: =+G70/(1-G36) -> 5019.702 | H57: =+H70/(1-H36) -> 5308.0764 | I57: =+I70/(1-I36) -> 5611.2737 | J57: =+J70/(1-J36) -> 5947.9502
B58: Interest payment | C58: =+C43 -> 460 | D58: =+D43 -> 460 | E58: =+E43 -> 460 | F58: =+F43 -> 460 | G58: =+G43 -> 230 | H58: =+H53*H35 -> 1070.5364 | I58: =+I53*I35 -> 1131.6855 | J58: =+J53*J35 -> 1199.5866
B59: Tax deductible interest | C59: =+C58*C39 -> 368 | D59: =+D58*D39 -> 368 | E59: =+E58*E39 -> 368 | F59: =+F58*F39 -> 368 | G59: =+G58*G39 -> 184 | H59: =+H58*H39 -> 1070.5364 | I59: =+I58*I39 -> 1131.6855 | J59: =+J58*J39 -> 1199.5866
B60: PBT | C60: =+C57-C58 -> 3316.4004 | D60: =+D57-D58 -> 3631.1013 | E60: =+E57-E58 -> 3947.9191 | F60: =+F57-F58 -> 4263.2149 | G60: =+G57-G58 -> 4789.702 | H60: =+H57-H58 -> 4237.54 | I60: =+I57-I58 -> 4479.5883 | J60: =+J57-J58 -> 4748.3636
B61: Tax base | C61: =+C57-C59 -> 3408.4004 | D61: =+D57-D59 -> 3723.1013 | E61: =+E57-E59 -> 4039.9191 | F61: =+F57-F59 -> 4355.2149 | G61: =+G57-G59 -> 4835.702 | H61: =+H57-H59 -> 4237.54 | I61: =+I57-I59 -> 4479.5883 | J61: =+J57-J59 -> 4748.3636
B62: Tax | C62: =+IF(C61<0,0,C61*C33) -> 681.68007 | D62: =+IF(D61<0,0,D61*D33) -> 744.62027 | E62: =+IF(E61<0,0,E61*E33) -> 807.98383 | F62: =+IF(F61<0,0,F61*F33) -> 871.04298 | G62: =+IF(G61<0,0,G61*G33) -> 967.14039 | H62: =+IF(H61<0,0,H61*H33) -> 847.508 | I62: =+IF(I61<0,0,I61*I33) -> 895.91766 | J62: =+IF(J61<0,0,J61*J33) -> 949.67271
B63: PAT | C63: =+C60-C62 -> 2634.7203 | D63: =+D60-D62 -> 2886.4811 | E63: =+E60-E62 -> 3139.9353 | F63: =+F60-F62 -> 3392.1719 | G63: =+G60-G62 -> 3822.5616 | H63: =+H60-H62 -> 3390.032 | I63: =+I60-I62 -> 3583.6706 | J63: =+J60-J62 -> 3798.6909
B64: Dividend | C64: =+C63-C65 -> 970.50138 | D64: =+D63-D65 -> 1080.5668 | E64: =+E63-E65 -> 0 | F64: =+F63-F65 -> 0 | G64: =+G63-G65 -> 3822.5616 | H64: =+H63-H65 -> 1861.306 | I64: =+I63-I65 -> 1886.1424 | J64: =+J63-J65 -> 0
B65: Retained Earnings | C65: =+IF(C63<0,C63,MAX(0,MIN(C63,C67))) -> 1664.2189 | D65: =+IF(D63<0,D63,MAX(0,MIN(D63,D67))) -> 1805.9142 | E65: =+IF(E63<0,E63,MAX(0,MIN(E63,E67))) -> 3139.9353 | F65: =+IF(F63<0,F63,MAX(0,MIN(F63,F67))) -> 3392.1719 | G65: =+IF(G63<0,G63,MAX(0,MIN(G63,G67))) -> 0 | H65: =+IF(H63<0,H63,MAX(0,MIN(H63,H67))) -> 1528.726 | I65: =+IF(I63<0,I63,MAX(0,MIN(I63,I67))) -> 1697.5282 | J65: =+IF(J63<0,J63,MAX(0,MIN(J63,J67))) -> 3798.6909
B67: dBVEquity needed | C67: =+D54-C54 -> 1664.2189 | D67: =+E54-D54 -> 1805.9142 | E67: =+F54-E54 -> 4247.9378 | F67: =+G54-F54 -> 6573.5003 | G67: =+H54-G54 -> -13339.598 | H67: =+I54-H54 -> 1528.726 | I67: =+J54-I54 -> 1697.5282
B68: Share issue/buyback | C68: =+C67-C65 -> 0 | D68: =+D67-D65 -> 0 | E68: =+E67-E65 -> 1108.0025 | F68: =+F67-F65 -> 3181.3284 | G68: =+G67-G65 -> -13339.598 | H68: =+H67-H65 -> 0 | I68: =+I67-I65 -> 0
B70: Noplat | C70: =+C52*C28 -> 3000 | D70: =+C70+C71*D29 -> 3252 | E70: =+D70+D71*E29 -> 3505.656 | F70: =+E70+E71*F29 -> 3758.0632 | G70: =+F70+F71*G29 -> 4006.0954 | H70: =+G70+G71*H29 -> 4246.4611 | I70: =+H70+H71*I29 -> 4489.019 | J70: =+I70+I71*J29 -> 4758.3601
B71: dIC | C71: =+C70*C30 -> 1800 | D71: =+D70*D30 -> 1951.2 | E71: =+E70*E30 -> 2103.3936 | F71: =+F70*F30 -> 2254.8379 | G71: =+G70*G30 -> 2403.6572 | H71: =+H70*H30 -> 2547.8767 | I71: =+I70*I30 -> 2829.2136 | J71: =+J70*J30 -> 2998.9665
...
